Workbook
Name SegmentaçãodeDados_CLUBE: #REF!
Name SegmentaçãodeDados_Visitante: #REF!

Sheet CAL
A1: DATAA | B1: IDCLUBE | C1: GM | D1: GV | E1: pc | F1: vitc | G1: empc | H1: derc | I1: csc | J1: IDCLUBE | K1: gc | L1: gf | M1: pf | N1: vit | O1: empf | P1: derf | Q1: csf | R1: CAMP | S1: Coluna1 | T1: Coluna2 | U1: 1 | V1: 2 | W1: 3 | X1: 4 | Y1: 5 | Z1: 6 | AA1: 7 | AB1: 8 | AC1: 9 | AD1: 10 | AE1: 11 | AF1: 12
A2: 46028 | B2: maracanace | C2: 0 | D2: 1 | E2: =IF(C2="","",IF(C2>D2,3,IF(C2=D2,1,0))) -> 0 | F2: =IF(C2="","",IF(C2>D2,1,0)) -> 0 | G2: =IF(C2="","",IF(C2=D2,1,0)) -> 0 | H2: =IF(C2="","",IF(C2<D2,1,0)) -> 1 | I2: =IF(D2=0,1,0) -> 0 | J2: ferroviarioce | K2: =C2 -> 0 | L2: =D2 -> 1 | M2: =IF(D2="","",IF(D2>C2,3,IF(D2=C2,1,0))) -> 3 | N2: =IF(D2="","",IF(D2>C2,1,0)) -> 1 | O2: =IF(D2="","",IF(D2=C2,1,0)) -> 0 | P2: =IF(D2="","",IF(D2<C2,1,0)) -> 0 | Q2: =IF(K2=0,1,0) -> 1 | R2: ce1 | S2: =C2 -> 0 | T2: =D2 -> 1 | U2: 1003
A3: 46028 | B3: saojoseensepr | C3: 2 | D3: 0 | E3: =IF(C3="","",IF(C3>D3,3,0)) -> 3 | F3: =IF(C3="","",IF(C3>D3,1,0)) -> 1 | G3: =IF(C3="","",IF(C3=D3,1,0)) -> 0 | H3: =IF(C3="","",IF(C3<D3,1,0)) -> 0 | I3: =IF(D3=0,1,0) -> 1 | J3: galomaringapr | K3: =C3 -> 2 | L3: =D3 -> 0 | M3: =IF(D3="","",IF(D3>C3,3,IF(D3=C3,1,0))) -> 0 | N3: =IF(D3="","",IF(D3>C3,1,0)) -> 0 | O3: =IF(D3="","",IF(D3=C3,1,0)) -> 0 | P3: =IF(D3="","",IF(D3<C3,1,0)) -> 1 | Q3: =IF(K3=0,1,0) -> 0 | R3: pr1 | S3: =C3 -> 2 | T3: =D3 -> 0 | U3: 1001 | V3: 1002
A4: 46028 | B4: chapecoensesc | C4: 1 | D4: 1 | E4: =IF(C4="","",IF(C4>D4,3,IF(C4=D4,1,0))) -> 1 | F4: =IF(C4="","",IF(C4>D4,1,0)) -> 0 | G4: =IF(C4="","",IF(C4=D4,1,0)) -> 1 | H4: =IF(C4="","",IF(C4<D4,1,0)) -> 0 | I4: =IF(D4=0,1,0) -> 0 | J4: brusquesc | K4: =C4 -> 1 | L4: =D4 -> 1 | M4: =IF(D4="","",IF(D4>C4,3,IF(D4=C4,1,0))) -> 1 | N4: =IF(D4="","",IF(D4>C4,1,0)) -> 0 | O4: =IF(D4="","",IF(D4=C4,1,0)) -> 1 | P4: =IF(D4="","",IF(D4<C4,1,0)) -> 0 | Q4: =IF(K4=0,1,0) -> 0 | R4: sc1 | S4: =C4 -> 1 | T4: =D4 -> 1 | U4: 1004 | V4: 1005
A5: 46028 | B5: santacatarinasc | C5: 2 | D5: 2 | E5: =IF(C5="","",IF(C5>D5,3,IF(C5=D5,1,0))) -> 1 | F5: =IF(C5="","",IF(C5>D5,1,0)) -> 0 | G5: =IF(C5="","",IF(C5=D5,1,0)) -> 1 | H5: =IF(C5="","",IF(C5<D5,1,0)) -> 0 | I5: =IF(D5=0,1,0) -> 0 | J5: camboriusc | K5: =C5 -> 2 | L5: =D5 -> 2 | M5: =IF(D5="","",IF(D5>C5,3,IF(D5=C5,1,0))) -> 1 | N5: =IF(D5="","",IF(D5>C5,1,0)) -> 0 | O5: =IF(D5="","",IF(D5=C5,1,0)) -> 1 | P5: =IF(D5="","",IF(D5<C5,1,0)) -> 0 | Q5: =IF(K5=0,1,0) -> 0 | R5: sc1 | S5: =C5 -> 2 | T5: =D5 -> 2 | U5: 1006 | V5: 1006 | W5: 1007 | X5: 1008
A6: 46029 | B6: tirolce | C6: 0 | D6: 2 | E6: =IF(C6="","",IF(C6>D6,3,IF(C6=D6,1,0))) -> 0 | F6: =IF(C6="","",IF(C6>D6,1,0)) -> 0 | G6: =IF(C6="","",IF(C6=D6,1,0)) -> 0 | H6: =IF(C6="","",IF(C6<D6,1,0)) -> 1 | I6: =IF(D6=0,1,0) -> 0 | J6: florestace | K6: =C6 -> 0 | L6: =D6 -> 2 | M6: =IF(D6="","",IF(D6>C6,3,IF(D6=C6,1,0))) -> 3 | N6: =IF(D6="","",IF(D6>C6,1,0)) -> 1 | O6: =IF(D6="","",IF(D6=C6,1,0)) -> 0 | P6: =IF(D6="","",IF(D6<C6,1,0)) -> 0 | Q6: =IF(K6=0,1,0) -> 1 | R6: ce1 | S6: =C6 -> 0 | T6: =D6 -> 2 | U6: 1022 | V6: 1023
A7: 46029 | B7: horizontece | C7: 0 | D7: 0 | E7: =IF(C7="","",IF(C7>D7,3,IF(C7=D7,1,0))) -> 1 | F7: =IF(C7="","",IF(C7>D7,1,0)) -> 0 | G7: =IF(C7="","",IF(C7=D7,1,0)) -> 1 | H7: =IF(C7="","",IF(C7<D7,1,0)) -> 0 | I7: =IF(D7=0,1,0) -> 1 | J7: quixadace | K7: =C7 -> 0 | L7: =D7 -> 0 | M7: =IF(D7="","",IF(D7>C7,3,IF(D7=C7,1,0))) -> 1 | N7: =IF(D7="","",IF(D7>C7,1,0)) -> 0 | O7: =IF(D7="","",IF(D7=C7,1,0)) -> 1 | P7: =IF(D7="","",IF(D7<C7,1,0)) -> 0 | Q7: =IF(K7=0,1,0) -> 1 | R7: ce1 | S7: =C7 -> 0 | T7: =D7 -> 0
A8: 46029 | B8: londrinapr | C8: 2 | D8: 0 | E8: =IF(C8="","",IF(C8>D8,3,IF(C8=D8,1,0))) -> 3 | F8: =IF(C8="","",IF(C8>D8,1,0)) -> 1 | G8: =IF(C8="","",IF(C8=D8,1,0)) -> 0 | H8: =IF(C8="","",IF(C8<D8,1,0)) -> 0 | I8: =IF(D8=0,1,0) -> 1 | J8: operariopr | K8: =C8 -> 2 | L8: =D8 -> 0 | M8: =IF(D8="","",IF(D8>C8,3,IF(D8=C8,1,0))) -> 0 | N8: =IF(D8="","",IF(D8>C8,1,0)) -> 0 | O8: =IF(D8="","",IF(D8=C8,1,0)) -> 0 | P8: =IF(D8="","",IF(D8<C8,1,0)) -> 1 | Q8: =IF(K8=0,1,0) -> 0 | R8: pr1 | S8: =C8 -> 2 | T8: =D8 -> 0 | U8: 1009 | V8: 1010
A9: 46029 | B9: cianortepr | C9: 3 | D9: 3 | E9: =IF(C9="","",IF(C9>D9,3,IF(C9=D9,1,0))) -> 1 | F9: =IF(C9="","",IF(C9>D9,1,0)) -> 0 | G9: =IF(C9="","",IF(C9=D9,1,0)) -> 1 | H9: =IF(C9="","",IF(C9<D9,1,0)) -> 0 | I9: =IF(D9=0,1,0) -> 0 | J9: maringapr | K9: =C9 -> 3 | L9: =D9 -> 3 | M9: =IF(D9="","",IF(D9>C9,3,IF(D9=C9,1,0))) -> 1 | N9: =IF(D9="","",IF(D9>C9,1,0)) -> 0 | O9: =IF(D9="","",IF(D9=C9,1,0)) -> 1 | P9: =IF(D9="","",IF(D9<C9,1,0)) -> 0 | Q9: =IF(K9=0,1,0) -> 0 | R9: pr1 | S9: =C9 -> 3 | T9: =D9 -> 3 | U9: 1011 | V9: 1012 | W9: 1013 | X9: 1014 | Y9: 1015 | Z9: 1016
A10: 46029 | B10: coritibapr | C10: 2 | D10: 3 | E10: =IF(C10="","",IF(C10>D10,3,IF(C10=D10,1,0))) -> 0 | F10: =IF(C10="","",IF(C10>D10,1,0)) -> 0 | G10: =IF(C10="","",IF(C10=D10,1,0)) -> 0 | H10: =IF(C10="","",IF(C10<D10,1,0)) -> 1 | I10: =IF(D10=0,1,0) -> 0 | J10: fozdoiguacupr | K10: =C10 -> 2 | L10: =D10 -> 3 | M10: =IF(D10="","",IF(D10>C10,3,IF(D10=C10,1,0))) -> 3 | N10: =IF(D10="","",IF(D10>C10,1,0)) -> 1 | O10: =IF(D10="","",IF(D10=C10,1,0)) -> 0 | P10: =IF(D10="","",IF(D10<C10,1,0)) -> 0 | Q10: =IF(K10=0,1,0) -> 0 | R10: pr1 | S10: =C10 -> 2 | T10: =D10 -> 3 | U10: 1017 | V10: 1018 | W10: 1019 | X10: 1020 | Y10: 1021
A11: 46029 | B11: marciliodiassc | C11: 2 | D11: 0 | E11: =IF(C11="","",IF(C11>D11,3,IF(C11=D11,1,0))) -> 3 | F11: =IF(C11="","",IF(C11>D11,1,0)) -> 1 | G11: =IF(C11="","",IF(C11=D11,1,0)) -> 0 | H11: =IF(C11="","",IF(C11<D11,1,0)) -> 0 | I11: =IF(D11=0,1,0) -> 1 | J11: criciumasc | K11: =C11 -> 2 | L11: =D11 -> 0 | M11: =IF(D11="","",IF(D11>C11,3,IF(D11=C11,1,0))) -> 0 | N11: =IF(D11="","",IF(D11>C11,1,0)) -> 0 | O11: =IF(D11="","",IF(D11=C11,1,0)) -> 0 | P11: =IF(D11="","",IF(D11<C11,1,0)) -> 1 | Q11: =IF(K11=0,1,0) -> 0 | R11: sc1 | S11: =C11 -> 2 | T11: =D11 -> 0 | U11: 1024 | V11: 1025
A12: 46029 | B12: joinvillesc | C12: 2 | D12: 3 | E12: =IF(C12="","",IF(C12>D12,3,IF(C12=D12,1,0))) -> 0 | F12: =IF(C12="","",IF(C12>D12,1,0)) -> 0 | G12: =IF(C12="","",IF(C12=D12,1,0)) -> 0 | H12: =IF(C12="","",IF(C12<D12,1,0)) -> 1 | I12: =IF(D12=0,1,0) -> 0 | J12: figueirensesc | K12: =C12 -> 2 | L12: =D12 -> 3 | M12: =IF(D12="","",IF(D12>C12,3,IF(D12=C12,1,0))) -> 3 | N12: =IF(D12="","",IF(D12>C12,1,0)) -> 1 | O12: =IF(D12="","",IF(D12=C12,1,0)) -> 0 | P12: =IF(D12="","",IF(D12<C12,1,0)) -> 0 | Q12: =IF(K12=0,1,0) -> 0 | R12: sc1 | S12: =C12 -> 2 | T12: =D12 -> 3 | U12: 1026 | V12: 1027 | W12: 1028 | X12: 1029 | Y12: 1030
A13: 46029 | B13: avaisc | C13: 2 | D13: 1 | E13: =IF(C13="","",IF(C13>D13,3,IF(C13=D13,1,0))) -> 3 | F13: =IF(C13="","",IF(C13>D13,1,0)) -> 1 | G13: =IF(C13="","",IF(C13=D13,1,0)) -> 0 | H13: =IF(C13="","",IF(C13<D13,1,0)) -> 0 | I13: =IF(D13=0,1,0) -> 0 | J13: barrasc | K13: =C13 -> 2 | L13: =D13 -> 1 | M13: =IF(D13="","",IF(D13>C13,3,IF(D13=C13,1,0))) -> 0 | N13: =IF(D13="","",IF(D13>C13,1,0)) -> 0 | O13: =IF(D13="","",IF(D13=C13,1,0)) -> 0 | P13: =IF(D13="","",IF(D13<C13,1,0)) -> 1 | Q13: =IF(K13=0,1,0) -> 0 | R13: sc1 | S13: =C13 -> 2 | T13: =D13 -> 1 | U13: 1031 | V13: 1032 | W13: 1033
A14: 46029 | B14: vitoriaes | C14: 5 | D14: 1 | E14: =IF(C14="","",IF(C14>D14,3,IF(C14=D14,1,0))) -> 3 | F14: =IF(C14="","",IF(C14>D14,1,0)) -> 1 | G14: =IF(C14="","",IF(C14=D14,1,0)) -> 0 | H14: =IF(C14="","",IF(C14<D14,1,0)) -> 0 | I14: =IF(D14=0,1,0) -> 0 | J14: riobrancoes | K14: =C14 -> 5 | L14: =D14 -> 1 | M14: =IF(D14="","",IF(D14>C14,3,IF(D14=C14,1,0))) -> 0 | N14: =IF(D14="","",IF(D14>C14,1,0)) -> 0 | O14: =IF(D14="","",IF(D14=C14,1,0)) -> 0 | P14: =IF(D14="","",IF(D14<C14,1,0)) -> 1 | Q14: =IF(K14=0,1,0) -> 0 | R14: sces | S14: =C14 -> 5 | T14: =D14 -> 1 | U14: 1034 | V14: 1034 | W14: 1035 | X14: 1036 | Y14: 1036 | Z14: 1037
A15: 46030 | B15: iguatuce | C15: 2 | D15: 0 | E15: =IF(C15="","",IF(C15>D15,3,IF(C15=D15,1,0))) -> 3 | F15: =IF(C15="","",IF(C15>D15,1,0)) -> 1 | G15: =IF(C15="","",IF(C15=D15,1,0)) -> 0 | H15: =IF(C15="","",IF(C15<D15,1,0)) -> 0 | I15: =IF(D15=0,1,0) -> 1 | J15: maranguapece | K15: =C15 -> 2 | L15: =D15 -> 0 | M15: =IF(D15="","",IF(D15>C15,3,IF(D15=C15,1,0))) -> 0 | N15: =IF(D15="","",IF(D15>C15,1,0)) -> 0 | O15: =IF(D15="","",IF(D15=C15,1,0)) -> 0 | P15: =IF(D15="","",IF(D15<C15,1,0)) -> 1 | Q15: =IF(K15=0,1,0) -> 0 | R15: ce1 | S15: =C15 -> 2 | T15: =D15 -> 0 | U15: 1041 | V15: 1042
A16: 46030 | B16: cascavelpr | C16: 0 | D16: 0 | E16: =IF(C16="","",IF(C16>D16,3,IF(C16=D16,1,0))) -> 1 | F16: =IF(C16="","",IF(C16>D16,1,0)) -> 0 | G16: =IF(C16="","",IF(C16=D16,1,0)) -> 1 | H16: =IF(C16="","",IF(C16<D16,1,0)) -> 0 | I16: =IF(D16=0,1,0) -> 1 | J16: azurizpr | K16: =C16 -> 0 | L16: =D16 -> 0 | M16: =IF(D16="","",IF(D16>C16,3,IF(D16=C16,1,0))) -> 1 | N16: =IF(D16="","",IF(D16>C16,1,0)) -> 0 | O16: =IF(D16="","",IF(D16=C16,1,0)) -> 1 | P16: =IF(D16="","",IF(D16<C16,1,0)) -> 0 | Q16: =IF(K16=0,1,0) -> 1 | R16: pr1 | S16: =C16 -> 0 | T16: =D16 -> 0
A17: 46030 | B17: andrauspr | C17: 1 | D17: 2 | E17: =IF(C17="","",IF(C17>D17,3,IF(C17=D17,1,0))) -> 0 | F17: =IF(C17="","",IF(C17>D17,1,0)) -> 0 | G17: =IF(C17="","",IF(C17=D17,1,0)) -> 0 | H17: =IF(C17="","",IF(C17<D17,1,0)) -> 1 | I17: =IF(D17=0,1,0) -> 0 | J17: athleticopr | K17: =C17 -> 1 | L17: =D17 -> 2 | M17: =IF(D17="","",IF(D17>C17,3,IF(D17=C17,1,0))) -> 3 | N17: =IF(D17="","",IF(D17>C17,1,0)) -> 1 | O17: =IF(D17="","",IF(D17=C17,1,0)) -> 0 | P17: =IF(D17="","",IF(D17<C17,1,0)) -> 0 | Q17: =IF(K17=0,1,0) -> 0 | R17: pr1 | S17: =C17 -> 1 | T17: =D17 -> 2 | U17: 1038 | V17: 1039 | W17: 1040
A18: 46030 | B18: carlosrenauxsc | C18: 0 | D18: 1 | E18: =IF(C18="","",IF(C18>D18,3,IF(C18=D18,1,0))) -> 0 | F18: =IF(C18="","",IF(C18>D18,1,0)) -> 0 | G18: =IF(C18="","",IF(C18=D18,1,0)) -> 0 | H18: =IF(C18="","",IF(C18<D18,1,0)) -> 1 | I18: =IF(D18=0,1,0) -> 0 | J18: concordiasc | K18: =C18 -> 0 | L18: =D18 -> 1 | M18: =IF(D18="","",IF(D18>C18,3,IF(D18=C18,1,0))) -> 3 | N18: =IF(D18="","",IF(D18>C18,1,0)) -> 1 | O18: =IF(D18="","",IF(D18=C18,1,0)) -> 0 | P18: =IF(D18="","",IF(D18<C18,1,0)) -> 0 | Q18: =IF(K18=0,1,0) -> 1 | R18: sc1 | S18: =C18 -> 0 | T18: =D18 -> 1 | U18: 1043
A19: 46031 | B19: retrope | C19: 4 | D19: 0 | E19: =IF(C19="","",IF(C19>D19,3,IF(C19=D19,1,0))) -> 3 | F19: =IF(C19="","",IF(C19>D19,1,0)) -> 1 | G19: =IF(C19="","",IF(C19=D19,1,0)) -> 0 | H19: =IF(C19="","",IF(C19<D19,1,0)) -> 0 | I19: =IF(D19=0,1,0) -> 1 | J19: vitoriape | K19: =C19 -> 4 | L19: =D19 -> 0 | M19: =IF(D19="","",IF(D19>C19,3,IF(D19=C19,1,0))) -> 0 | N19: =IF(D19="","",IF(D19>C19,1,0)) -> 0 | O19: =IF(D19="","",IF(D19=C19,1,0)) -> 0 | P19: =IF(D19="","",IF(D19<C19,1,0)) -> 1 | Q19: =IF(K19=0,1,0) -> 0 | R19: pe1 | S19: =C19 -> 4 | T19: =D19 -> 0 | U19: 1044 | V19: 1045 | W19: 1046 | X19: 1047
A20: 46031 | B20: nauticope | C20: 2 | D20: 0 | E20: =IF(C20="","",IF(C20>D20,3,IF(C20=D20,1,0))) -> 3 | F20: =IF(C20="","",IF(C20>D20,1,0)) -> 1 | G20: =IF(C20="","",IF(C20=D20,1,0)) -> 0 | H20: =IF(C20="","",IF(C20<D20,1,0)) -> 0 | I20: =IF(D20=0,1,0) -> 1 | J20: maguarype | K20: =C20 -> 2 | L20: =D20 -> 0 | M20: =IF(D20="","",IF(D20>C20,3,IF(D20=C20,1,0))) -> 0 | N20: =IF(D20="","",IF(D20>C20,1,0)) -> 0 | O20: =IF(D20="","",IF(D20=C20,1,0)) -> 0 | P20: =IF(D20="","",IF(D20<C20,1,0)) -> 1 | Q20: =IF(K20=0,1,0) -> 0 | R20: pe1 | S20: =C20 -> 2 | T20: =D20 -> 0 | U20: 1048 | V20: 1048
A21: 46031 | B21: osascosp | C21: 0 | D21: 0 | E21: =IF(C21="","",IF(C21>D21,3,IF(C21=D21,1,0))) -> 1 | F21: =IF(C21="","",IF(C21>D21,1,0)) -> 0 | G21: =IF(C21="","",IF(C21=D21,1,0)) -> 1 | H21: =IF(C21="","",IF(C21<D21,1,0)) -> 0 | I21: =IF(D21=0,1,0) -> 1 | J21: ferroviariasp | K21: =C21 -> 0 | L21: =D21 -> 0 | M21: =IF(D21="","",IF(D21>C21,3,IF(D21=C21,1,0))) -> 1 | N21: =IF(D21="","",IF(D21>C21,1,0)) -> 0 | O21: =IF(D21="","",IF(D21=C21,1,0)) -> 1 | P21: =IF(D21="","",IF(D21<C21,1,0)) -> 0 | Q21: =IF(K21=0,1,0) -> 1 | R21: sp2 | S21: =C21 -> 0 | T21: =D21 -> 0
A22: 46032 | B22: crbal | C22: 1 | D22: 0 | E22: =IF(C22="","",IF(C22>D22,3,IF(C22=D22,1,0))) -> 3 | F22: =IF(C22="","",IF(C22>D22,1,0)) -> 1 | G22: =IF(C22="","",IF(C22=D22,1,0)) -> 0 | H22: =IF(C22="","",IF(C22<D22,1,0)) -> 0 | I22: =IF(D22=0,1,0) -> 1 | J22: cseal | K22: =C22 -> 1 | L22: =D22 -> 0 | M22: =IF(D22="","",IF(D22>C22,3,IF(D22=C22,1,0))) -> 0 | N22: =IF(D22="","",IF(D22>C22,1,0)) -> 0 | O22: =IF(D22="","",IF(D22=C22,1,0)) -> 0 | P22: =IF(D22="","",IF(D22<C22,1,0)) -> 1 | Q22: =IF(K22=0,1,0) -> 0 | R22: al1 | S22: =C22 -> 1 | T22: =D22 -> 0 | U22: 1093
A23: 46032 | B23: penedenseal | C23: 1 | D23: 0 | E23: =IF(C23="","",IF(C23>D23,3,IF(C23=D23,1,0))) -> 3 | F23: =IF(C23="","",IF(C23>D23,1,0)) -> 1 | G23: =IF(C23="","",IF(C23=D23,1,0)) -> 0 | H23: =IF(C23="","",IF(C23<D23,1,0)) -> 0 | I23: =IF(D23=0,1,0) -> 1 | J23: cruzeiroal | K23: =C23 -> 1 | L23: =D23 -> 0 | M23: =IF(D23="","",IF(D23>C23,3,IF(D23=C23,1,0))) -> 0 | N23: =IF(D23="","",IF(D23>C23,1,0)) -> 0 | O23: =IF(D23="","",IF(D23=C23,1,0)) -> 0 | P23: =IF(D23="","",IF(D23<C23,1,0)) -> 1 | Q23: =IF(K23=0,1,0) -> 0 | R23: al1 | S23: =C23 -> 1 | T23: =D23 -> 0 | U23: 1094
A24: 46032 | B24: asaal | C24: 0 | D24: 0 | E24: =IF(C24="","",IF(C24>D24,3,IF(C24=D24,1,0))) -> 1 | F24: =IF(C24="","",IF(C24>D24,1,0)) -> 0 | G24: =IF(C24="","",IF(C24=D24,1,0)) -> 1 | H24: =IF(C24="","",IF(C24<D24,1,0)) -> 0 | I24: =IF(D24=0,1,0) -> 1 | J24: muricial | K24: =C24 -> 0 | L24: =D24 -> 0 | M24: =IF(D24="","",IF(D24>C24,3,IF(D24=C24,1,0))) -> 1 | N24: =IF(D24="","",IF(D24>C24,1,0)) -> 0 | O24: =IF(D24="","",IF(D24=C24,1,0)) -> 1 | P24: =IF(D24="","",IF(D24<C24,1,0)) -> 0 | Q24: =IF(K24=0,1,0) -> 1 | R24: al1 | S24: =C24 -> 0 | T24: =D24 -> 0
A25: 46032 | B25: amazonasam | C25: 3 | D25: 0 | E25: =IF(C25="","",IF(C25>D25,3,IF(C25=D25,1,0))) -> 3 | F25: =IF(C25="","",IF(C25>D25,1,0)) -> 1 | G25: =IF(C25="","",IF(C25=D25,1,0)) -> 0 | H25: =IF(C25="","",IF(C25<D25,1,0)) -> 0 | I25: =IF(D25=0,1,0) -> 1 | J25: saoraimundoam | K25: =C25 -> 3 | L25: =D25 -> 0 | M25: =IF(D25="","",IF(D25>C25,3,IF(D25=C25,1,0))) -> 0 | N25: =IF(D25="","",IF(D25>C25,1,0)) -> 0 | O25: =IF(D25="","",IF(D25=C25,1,0)) -> 0 | P25: =IF(D25="","",IF(D25<C25,1,0)) -> 1 | Q25: =IF(K25=0,1,0) -> 0 | R25: am1 | S25: =C25 -> 3 | T25: =D25 -> 0 | U25: 1107 | V25: 1108 | W25: 1109
A26: 46032 | B26: vitoriaba | C26: 0 | D26: 0 | E26: =IF(C26="","",IF(C26>D26,3,IF(C26=D26,1,0))) -> 1 | F26: =IF(C26="","",IF(C26>D26,1,0)) -> 0 | G26: =IF(C26="","",IF(C26=D26,1,0)) -> 1 | H26: =IF(C26="","",IF(C26<D26,1,0)) -> 0 | I26: =IF(D26=0,1,0) -> 1 | J26: atleticoba | K26: =C26 -> 0 | L26: =D26 -> 0 | M26: =IF(D26="","",IF(D26>C26,3,IF(D26=C26,1,0))) -> 1 | N26: =IF(D26="","",IF(D26>C26,1,0)) -> 0 | O26: =IF(D26="","",IF(D26=C26,1,0)) -> 1 | P26: =IF(D26="","",IF(D26<C26,1,0)) -> 0 | Q26: =IF(K26=0,1,0) -> 1 | R26: ba1 | S26: =C26 -> 0 | T26: =D26 -> 0
A27: 46032 | B27: portoba | C27: 3 | D27: 2 | E27: =IF(C27="","",IF(C27>D27,3,IF(C27=D27,1,0))) -> 3 | F27: =IF(C27="","",IF(C27>D27,1,0)) -> 1 | G27: =IF(C27="","",IF(C27=D27,1,0)) -> 0 | H27: =IF(C27="","",IF(C27<D27,1,0)) -> 0 | I27: =IF(D27=0,1,0) -> 0 | J27: jacuipenseba | K27: =C27 -> 3 | L27: =D27 -> 2 | M27: =IF(D27="","",IF(D27>C27,3,IF(D27=C27,1,0))) -> 0 | N27: =IF(D27="","",IF(D27>C27,1,0)) -> 0 | O27: =IF(D27="","",IF(D27=C27,1,0)) -> 0 | P27: =IF(D27="","",IF(D27<C27,1,0)) -> 1 | Q27: =IF(K27=0,1,0) -> 0 | R27: ba1 | S27: =C27 -> 3 | T27: =D27 -> 2 | U27: 1084 | V27: 1085 | W27: 1086 | X27: 1087 | Y27: 1088
A28: 46032 | B28: florestace | C28: 0 | D28: 1 | E28: =IF(C28="","",IF(C28>D28,3,IF(C28=D28,1,0))) -> 0 | F28: =IF(C28="","",IF(C28>D28,1,0)) -> 0 | G28: =IF(C28="","",IF(C28=D28,1,0)) -> 0 | H28: =IF(C28="","",IF(C28<D28,1,0)) -> 1 | I28: =IF(D28=0,1,0) -> 0 | J28: cearace | K28: =C28 -> 0 | L28: =D28 -> 1 | M28: =IF(D28="","",IF(D28>C28,3,IF(D28=C28,1,0))) -> 3 | N28: =IF(D28="","",IF(D28>C28,1,0)) -> 1 | O28: =IF(D28="","",IF(D28=C28,1,0)) -> 0 | P28: =IF(D28="","",IF(D28<C28,1,0)) -> 0 | Q28: =IF(K28=0,1,0) -> 1 | R28: ce1 | S28: =C28 -> 0 | T28: =D28 -> 1 | U28: 1075
A29: 46032 | B29: quixadace | C29: 1 | D29: 0 | E29: =IF(C29="","",IF(C29>D29,3,IF(C29=D29,1,0))) -> 3 | F29: =IF(C29="","",IF(C29>D29,1,0)) -> 1 | G29: =IF(C29="","",IF(C29=D29,1,0)) -> 0 | H29: =IF(C29="","",IF(C29<D29,1,0)) -> 0 | I29: =IF(D29=0,1,0) -> 1 | J29: maracanace | K29: =C29 -> 1 | L29: =D29 -> 0 | M29: =IF(D29="","",IF(D29>C29,3,IF(D29=C29,1,0))) -> 0 | N29: =IF(D29="","",IF(D29>C29,1,0)) -> 0 | O29: =IF(D29="","",IF(D29=C29,1,0)) -> 0 | P29: =IF(D29="","",IF(D29<C29,1,0)) -> 1 | Q29: =IF(K29=0,1,0) -> 0 | R29: ce1 | S29: =C29 -> 1 | T29: =D29 -> 0 | U29: 9999
A30: 46032 | B30: paranoadf | C30: 0 | D30: 1 | E30: =IF(C30="","",IF(C30>D30,3,IF(C30=D30,1,0))) -> 0 | F30: =IF(C30="","",IF(C30>D30,1,0)) -> 0 | G30: =IF(C30="","",IF(C30=D30,1,0)) -> 0 | H30: =IF(C30="","",IF(C30<D30,1,0)) -> 1 | I30: =IF(D30=0,1,0) -> 0 | J30: arucdf | K30: =C30 -> 0 | L30: =D30 -> 1 | M30: =IF(D30="","",IF(D30>C30,3,IF(D30=C30,1,0))) -> 3 | N30: =IF(D30="","",IF(D30>C30,1,0)) -> 1 | O30: =IF(D30="","",IF(D30=C30,1,0)) -> 0 | P30: =IF(D30="","",IF(D30<C30,1,0)) -> 0 | Q30: =IF(K30=0,1,0) -> 1 | R30: df1 | S30: =C30 -> 0 | T30: =D30 -> 1 | U30: 1121
A31: 46032 | B31: brasiliensedf | C31: 4 | D31: 0 | E31: =IF(C31="","",IF(C31>D31,3,IF(C31=D31,1,0))) -> 3 | F31: =IF(C31="","",IF(C31>D31,1,0)) -> 1 | G31: =IF(C31="","",IF(C31=D31,1,0)) -> 0 | H31: =IF(C31="","",IF(C31<D31,1,0)) -> 0 | I31: =IF(D31=0,1,0) -> 1 | J31: brasiliadf | K31: =C31 -> 4 | L31: =D31 -> 0 | M31: =IF(D31="","",IF(D31>C31,3,IF(D31=C31,1,0))) -> 0 | N31: =IF(D31="","",IF(D31>C31,1,0)) -> 0 | O31: =IF(D31="","",IF(D31=C31,1,0)) -> 0 | P31: =IF(D31="","",IF(D31<C31,1,0)) -> 1 | Q31: =IF(K31=0,1,0) -> 0 | R31: df1 | S31: =C31 -> 4 | T31: =D31 -> 0 | U31: 1122 | V31: 1123 | W31: 1124 | X31: 1125
A32: 46032 | B32: ceilandiadf | C32: 1 | D32: 1 | E32: =IF(C32="","",IF(C32>D32,3,IF(C32=D32,1,0))) -> 1 | F32: =IF(C32="","",IF(C32>D32,1,0)) -> 0 | G32: =IF(C32="","",IF(C32=D32,1,0)) -> 1 | H32: =IF(C32="","",IF(C32<D32,1,0)) -> 0 | I32: =IF(D32=0,1,0) -> 0 | J32: sobradinhodf | K32: =C32 -> 1 | L32: =D32 -> 1 | M32: =IF(D32="","",IF(D32>C32,3,IF(D32=C32,1,0))) -> 1 | N32: =IF(D32="","",IF(D32>C32,1,0)) -> 0 | O32: =IF(D32="","",IF(D32=C32,1,0)) -> 1 | P32: =IF(D32="","",IF(D32<C32,1,0)) -> 0 | Q32: =IF(K32=0,1,0) -> 0 | R32: df1 | S32: =C32 -> 1 | T32: =D32 -> 1 | U32: 1126 | V32: 1127
A33: 46032 | B33: gamadf | C33: 1 | D33: 0 | E33: =IF(C33="","",IF(C33>D33,3,IF(C33=D33,1,0))) -> 3 | F33: =IF(C33="","",IF(C33>D33,1,0)) -> 1 | G33: =IF(C33="","",IF(C33=D33,1,0)) -> 0 | H33: =IF(C33="","",IF(C33<D33,1,0)) -> 0 | I33: =IF(D33=0,1,0) -> 1 | J33: realbrasiliadf | K33: =C33 -> 1 | L33: =D33 -> 0 | M33: =IF(D33="","",IF(D33>C33,3,IF(D33=C33,1,0))) -> 0 | N33: =IF(D33="","",IF(D33>C33,1,0)) -> 0 | O33: =IF(D33="","",IF(D33=C33,1,0)) -> 0 | P33: =IF(D33="","",IF(D33<C33,1,0)) -> 1 | Q33: =IF(K33=0,1,0) -> 0 | R33: df1 | S33: =C33 -> 1 | T33: =D33 -> 0 | U33: 1128
A34: 46032 | B34: jataiensego | C34: 1 | D34: 1 | E34: =IF(C34="","",IF(C34>D34,3,IF(C34=D34,1,0))) -> 1 | F34: =IF(C34="","",IF(C34>D34,1,0)) -> 0 | G34: =IF(C34="","",IF(C34=D34,1,0)) -> 1 | H34: =IF(C34="","",IF(C34<D34,1,0)) -> 0 | I34: =IF(D34=0,1,0) -> 0 | J34: cracgo | K34: =C34 -> 1 | L34: =D34 -> 1 | M34: =IF(D34="","",IF(D34>C34,3,IF(D34=C34,1,0))) -> 1 | N34: =IF(D34="","",IF(D34>C34,1,0)) -> 0 | O34: =IF(D34="","",IF(D34=C34,1,0)) -> 1 | P34: =IF(D34="","",IF(D34<C34,1,0)) -> 0 | Q34: =IF(K34=0,1,0) -> 0 | R34: go1 | S34: =C34 -> 1 | T34: =D34 -> 1 | U34: 1076 | V34: 1077
A35: 46032 | B35: atleticogo | C35: 2 | D35: 0 | E35: =IF(C35="","",IF(C35>D35,3,IF(C35=D35,1,0))) -> 3 | F35: =IF(C35="","",IF(C35>D35,1,0)) -> 1 | G35: =IF(C35="","",IF(C35=D35,1,0)) -> 0 | H35: =IF(C35="","",IF(C35<D35,1,0)) -> 0 | I35: =IF(D35=0,1,0) -> 1 | J35: anapolisgo | K35: =C35 -> 2 | L35: =D35 -> 0 | M35: =IF(D35="","",IF(D35>C35,3,IF(D35=C35,1,0))) -> 0 | N35: =IF(D35="","",IF(D35>C35,1,0)) -> 0 | O35: =IF(D35="","",IF(D35=C35,1,0)) -> 0 | P35: =IF(D35="","",IF(D35<C35,1,0)) -> 1 | Q35: =IF(K35=0,1,0) -> 0 | R35: go1 | S35: =C35 -> 2 | T35: =D35 -> 0 | U35: 1078 | V35: 1079 | W35: 1080
A36: 46032 | B36: abecatgo | C36: 1 | D36: 2 | E36: =IF(C36="","",IF(C36>D36,3,IF(C36=D36,1,0))) -> 0 | F36: =IF(C36="","",IF(C36>D36,1,0)) -> 0 | G36: =IF(C36="","",IF(C36=D36,1,0)) -> 0 | H36: =IF(C36="","",IF(C36<D36,1,0)) -> 1 | I36: =IF(D36=0,1,0) -> 0 | J36: vilanovago | K36: =C36 -> 1 | L36: =D36 -> 2 | M36: =IF(D36="","",IF(D36>C36,3,IF(D36=C36,1,0))) -> 3 | N36: =IF(D36="","",IF(D36>C36,1,0)) -> 1 | O36: =IF(D36="","",IF(D36=C36,1,0)) -> 0 | P36: =IF(D36="","",IF(D36<C36,1,0)) -> 0 | Q36: =IF(K36=0,1,0) -> 0 | R36: go1 | S36: =C36 -> 1 | T36: =D36 -> 2 | U36: 1081 | V36: 1082
A37: 46032 | B37: imperatrizma | C37: 1 | D37: 1 | E37: =IF(C37="","",IF(C37>D37,3,IF(C37=D37,1,0))) -> 1 | F37: =IF(C37="","",IF(C37>D37,1,0)) -> 0 | G37: =IF(C37="","",IF(C37=D37,1,0)) -> 1 | H37: =IF(C37="","",IF(C37<D37,1,0)) -> 0 | I37: =IF(D37=0,1,0) -> 0 | J37: sampaiocorreama | K37: =C37 -> 1 | L37: =D37 -> 1 | M37: =IF(D37="","",IF(D37>C37,3,IF(D37=C37,1,0))) -> 1 | N37: =IF(D37="","",IF(D37>C37,1,0)) -> 0 | O37: =IF(D37="","",IF(D37=C37,1,0)) -> 1 | P37: =IF(D37="","",IF(D37<C37,1,0)) -> 0 | Q37: =IF(K37=0,1,0) -> 0 | R37: ma1 | S37: =C37 -> 1 | T37: =D37 -> 1 | U37: 1105 | V37: 1106
A38: 46032 | B38: uberlandiamg | C38: 0 | D38: 0 | E38: =IF(C38="","",IF(C38>D38,3,IF(C38=D38,1,0))) -> 1 | F38: =IF(C38="","",IF(C38>D38,1,0)) -> 0 | G38: =IF(C38="","",IF(C38=D38,1,0)) -> 1 | H38: =IF(C38="","",IF(C38<D38,1,0)) -> 0 | I38: =IF(D38=0,1,0) -> 1 | J38: tombensemg | K38: =C38 -> 0 | L38: =D38 -> 0 | M38: =IF(D38="","",IF(D38>C38,3,IF(D38=C38,1,0))) -> 1 | N38: =IF(D38="","",IF(D38>C38,1,0)) -> 0 | O38: =IF(D38="","",IF(D38=C38,1,0)) -> 1 | P38: =IF(D38="","",IF(D38<C38,1,0)) -> 0 | Q38: =IF(K38=0,1,0) -> 1 | R38: mg1 | S38: =C38 -> 0 | T38: =D38 -> 0
A39: 46032 | B39: cruzeiromg | C39: 1 | D39: 2 | E39: =IF(C39="","",IF(C39>D39,3,IF(C39=D39,1,0))) -> 0 | F39: =IF(C39="","",IF(C39>D39,1,0)) -> 0 | G39: =IF(C39="","",IF(C39=D39,1,0)) -> 0 | H39: =IF(C39="","",IF(C39<D39,1,0)) -> 1 | I39: =IF(D39=0,1,0) -> 0 | J39: pousoalegremg | K39: =C39 -> 1 | L39: =D39 -> 2 | M39: =IF(D39="","",IF(D39>C39,3,IF(D39=C39,1,0))) -> 3 | N39: =IF(D39="","",IF(D39>C39,1,0)) -> 1 | O39: =IF(D39="","",IF(D39=C39,1,0)) -> 0 | P39: =IF(D39="","",IF(D39<C39,1,0)) -> 0 | Q39: =IF(K39=0,1,0) -> 0 | R39: mg1 | S39: =C39 -> 1 | T39: =D39 -> 2 | U39: 1066 | V39: 1067 | W39: 1068
A40: 46032 | B40: itabiritomg | C40: 0 | D40: 1 | E40: =IF(C40="","",IF(C40>D40,3,IF(C40=D40,1,0))) -> 0 | F40: =IF(C40="","",IF(C40>D40,1,0)) -> 0 | G40: =IF(C40="","",IF(C40=D40,1,0)) -> 0 | H40: =IF(C40="","",IF(C40<D40,1,0)) -> 1 | I40: =IF(D40=0,1,0) -> 0 | J40: democratagvmg | K40: =C40 -> 0 | L40: =D40 -> 1 | M40: =IF(D40="","",IF(D40>C40,3,IF(D40=C40,1,0))) -> 3 | N40: =IF(D40="","",IF(D40>C40,1,0)) -> 1 | O40: =IF(D40="","",IF(D40=C40,1,0)) -> 0 | P40: =IF(D40="","",IF(D40<C40,1,0)) -> 0 | Q40: =IF(K40=0,1,0) -> 1 | R40: mg1 | S40: =C40 -> 0 | T40: =D40 -> 1 | U40: 1069
...

Sheet ART
A1: POS | B1: COD | C1: JOGADOR | D1: CLUBE | E1: NOME_COMPLETO | F1: NASCIMENTO | G1: PAIS | H1: GOLS | I1: JOGOS | J1: OBSERVAÇÕES
A2: 1º | B2: 5081 | C2: John | D2: 1992-RS | E2: John de Aquino Nunes | F2: 38478 | G2: Brasil | H2: =COUNTIF(CAL!U:AN,B2) -> 2 | I2: 8 | J2: 1 jaraguars | K2: =MONTH(F2) -> 5 | L2: =YEAR(F2) -> 2005
A3: 2º | B3: 5507 | C3: Luan | D3: 4 de julho-PI | H3: =COUNTIF(CAL!U:AN,B3) -> 1 | K3: =MONTH(F3) -> 1 | L3: =YEAR(F3) -> 1900
A4: 3º | B4: 5508 | C4: Wendel | D4: 4 de julho-PI | H4: =COUNTIF(CAL!U:AN,B4) -> 1 | K4: =MONTH(F4) -> 1 | L4: =YEAR(F4) -> 1900
A5: 4º | B5: 1715 | C5: Brunão | D5: ABC-RN | E5: Bruno Vitor Ribeiro Rodrigues | F5: 35970 | G5: Brasil | H5: =COUNTIF(CAL!U:AN,B5) -> 4 | I5: 8 | J5: 2 boavistarj | K5: =MONTH(F5) -> 6 | L5: =YEAR(F5) -> 1998
A6: 5º | B6: 3417 | C6: Bruno Leite | D6: ABC-RN | E6: Bruno da Silva Costa Leite | F6: 36623 | G6: Brasil | H6: =COUNTIF(CAL!U:AN,B6) -> 5 | I6: 15 | K6: =MONTH(F6) -> 4 | L6: =YEAR(F6) -> 2000
A7: 6º | B7: 2117 | C7: Cayo Tenorio | D7: ABC-RN | E7: Cayo Henrique Nascimento Ferreira | F7: 36213 | G7: Brasil | H7: =COUNTIF(CAL!U:AN,B7) -> 1 | I7: 5 | K7: =MONTH(F7) -> 2 | L7: =YEAR(F7) -> 1999
A8: 7º | B8: 1183 | C8: Edson | D8: ABC-RN | E8: Edson Felipe da Cruz | F8: 33420 | G8: Brasil | H8: =COUNTIF(CAL!U:AN,B8) -> 5 | I8: 15 | K8: =MONTH(F8) -> 7 | L8: =YEAR(F8) -> 1991
A9: 8º | B9: 4178 | C9: Emanuel | D9: ABC-RN | E9: Emanuel Junio da Silva Peixoto | F9: 38641 | G9: Brasil | H9: =COUNTIF(CAL!U:AN,B9) -> 1 | I9: 4 | K9: =MONTH(F9) -> 10 | L9: =YEAR(F9) -> 2005
A10: 9º | B10: 1450 | C10: Geilson | D10: ABC-RN | E10: Geilson Cequeira Almeida | F10: 37057 | G10: Brasil | H10: =COUNTIF(CAL!U:AN,B10) -> 1 | I10: 11 | K10: =MONTH(F10) -> 6 | L10: =YEAR(F10) -> 2001
A11: 10º | B11: 1453 | C11: Igor Bahia | D11: ABC-RN | E11: Igor Ruan Sousa dos Santos | F11: 34025 | G11: Brasil | H11: =COUNTIF(CAL!U:AN,B11) -> 13 | I11: 29 | K11: =MONTH(F11) -> 2 | L11: =YEAR(F11) -> 1993
A12: 11º | B12: 3603 | C12: Jhosefer | D12: ABC-RN | E12: Jhosefer Raphael Januario | F12: 38055 | G12: Brasil | H12: =COUNTIF(CAL!U:AN,B12) -> 4 | I12: 6 | K12: =MONTH(F12) -> 3 | L12: =YEAR(F12) -> 2004
A13: 12º | B13: 3878 | C13: João Pedro | D13: ABC-RN | E13: João Pedro Florencio Barbosa | F13: 36070 | G13: Brasil | H13: =COUNTIF(CAL!U:AN,B13) -> 2 | I13: 17 | K13: =MONTH(F13) -> 10 | L13: =YEAR(F13) -> 1998
A14: 13º | B14: 3418 | C14: Lima | D14: ABC-RN | E14: Guilherme Natan de Lima | F14: 36289 | G14: Brasil | H14: =COUNTIF(CAL!U:AN,B14) -> 2 | I14: 13 | K14: =MONTH(F14) -> 5 | L14: =YEAR(F14) -> 1999
A15: 14º | B15: 1452 | C15: Lucas Marques | D15: ABC-RN | E15: Lucas Alexandre Marques Otaviano | F15: 35956 | G15: Brasil | H15: =COUNTIF(CAL!U:AN,B15) -> 2 | I15: 14 | K15: =MONTH(F15) -> 6 | L15: =YEAR(F15) -> 1998
A16: 15º | B16: 1321 | C16: Lucas Souza | D16: ABC-RN | E16: Lucas do Carmo Souza | F16: 35801 | G16: Brasil | H16: =COUNTIF(CAL!U:AN,B16) -> 1 | I16: 14 | K16: =MONTH(F16) -> 1 | L16: =YEAR(F16) -> 1998
A17: 16º | B17: 2043 | C17: Luiz Fernando | D17: ABC-RN | E17: Luiz Fernando Ferreira de Souza | F17: 36352 | G17: Brasil | H17: =COUNTIF(CAL!U:AN,B17) -> 9 | I17: 11 | J17: 1 primaverasp | K17: =MONTH(F17) -> 7 | L17: =YEAR(F17) -> 1999
A18: 17º | B18: 2037 | C18: Rikelmi | D18: ABC-RN | E18: Rikelmi Valentim dos Santos | F18: 37117 | G18: Brasil | H18: =COUNTIF(CAL!U:AN,B18) -> 4 | I18: 23 | J18: 3 saojosesp | K18: =MONTH(F18) -> 8 | L18: =YEAR(F18) -> 2001
A19: 18º | B19: 2311 | C19: Thalissinho | D19: ABC-RN | E19: Thalisson de Sousa Oliveira | F19: 38690 | G19: Brasil | H19: =COUNTIF(CAL!U:AN,B19) -> 1 | I19: 5 | K19: =MONTH(F19) -> 12 | L19: =YEAR(F19) -> 2005
A20: 19º | B20: 2116 | C20: Wallyson | D20: ABC-RN | E20: Wallyson Ricardo Maciel Monteiro | F20: 32433 | G20: Brasil | H20: =COUNTIF(CAL!U:AN,B20) -> 13 | I20: 30 | K20: =MONTH(F20) -> 10 | L20: =YEAR(F20) -> 1988
A21: 20º | B21: 3760 | C21: Welligton Carvalho | D21: ABC-RN | E21: Wellington Carvalho dos Santos | F21: 34015 | G21: Brasil | H21: =COUNTIF(CAL!U:AN,B21) -> 3 | I21: 20 | K21: =MONTH(F21) -> 2 | L21: =YEAR(F21) -> 1993
A22: 21º | B22: 3194 | C22: Wellington Reis | D22: ABC-RN | E22: Wellington Rodrigues dos Reis | F22: 33587 | G22: Brasil | H22: =COUNTIF(CAL!U:AN,B22) -> 2 | I22: 9 | J22: 1 qfcrn | K22: =MONTH(F22) -> 12 | L22: =YEAR(F22) -> 1991
A23: 22º | B23: 1078 | C23: Alan Bald | D23: Abecat-GO | E23: Alan Henrique Bald | F23: 34636 | G23: Brasil | H23: =COUNTIF(CAL!U:AN,B23) -> 1 | I23: 3 | K23: =MONTH(F23) -> 10 | L23: =YEAR(F23) -> 1994
A24: 23º | B24: 2404 | C24: Alan Junior | D24: Abecat-GO | E24: Alan Junior Martins Oliveira | F24: 34069 | G24: Brasil | H24: =COUNTIF(CAL!U:AN,B24) -> 2 | I24: 13 | K24: =MONTH(F24) -> 4 | L24: =YEAR(F24) -> 1993
A25: 24º | B25: 4384 | C25: Kadu | D25: Abecat-GO | E25: Carlos Eduardo Antonio dos Santos | F25: 35316 | G25: Brasil | H25: =COUNTIF(CAL!U:AN,B25) -> 1 | I25: 15 | K25: =MONTH(F25) -> 9 | L25: =YEAR(F25) -> 1996
A26: 25º | B26: 4529 | C26: Marcos Moser | D26: Abecat-GO | E26: Marcos Moser Preto | F26: 35932 | G26: Brasil | H26: =COUNTIF(CAL!U:AN,B26) -> 1 | I26: 11 | K26: =MONTH(F26) -> 5 | L26: =YEAR(F26) -> 1998
A27: 26º | B27: 2403 | C27: Rafael Dumas | D27: Abecat-GO | E27: Rafael Dumas Ribeiro | F27: 34771 | G27: Brasil | H27: =COUNTIF(CAL!U:AN,B27) -> 1 | I27: 19 | K27: =MONTH(F27) -> 3 | L27: =YEAR(F27) -> 1995
A28: 27º | B28: 2763 | C28: Uesley Gaucho | D28: Abecat-GO | E28: Uesley Moura Heinemann | F28: 36992 | G28: Brasil | H28: =COUNTIF(CAL!U:AN,B28) -> 1 | I28: 16 | K28: =MONTH(F28) -> 4 | L28: =YEAR(F28) -> 2001
A29: 28º | B29: 3705 | C29: Adrianinho | D29: Ação-MT | E29: Adriano Alencar de Barros | F29: 37277 | G29: Brasil | H29: =COUNTIF(CAL!U:AN,B29) -> 2 | I29: 2 | K29: =MONTH(F29) -> 1 | L29: =YEAR(F29) -> 2002
A30: 29º | B30: 3742 | C30: Albino | D30: Ação-MT | E30: Arthur Albino da Silva | F30: 39058 | G30: Brasil | H30: =COUNTIF(CAL!U:AN,B30) -> 1 | I30: 2 | K30: =MONTH(F30) -> 12 | L30: =YEAR(F30) -> 2006
A31: 30º | B31: 4377 | C31: Daniel Lucas | D31: Ação-MT | E31: Daniel Lucas Duarte Batista | F31: 38225 | G31: Brasil | H31: =COUNTIF(CAL!U:AN,B31) -> 1 | I31: 5 | K31: =MONTH(F31) -> 8 | L31: =YEAR(F31) -> 2004
A32: 31º | B32: 4158 | C32: Diego | D32: Ação-MT | E32: Diego do Nascimento Estrela | F32: 37879 | G32: Brasil | H32: =COUNTIF(CAL!U:AN,B32) -> 1 | I32: 15 | K32: =MONTH(F32) -> 9 | L32: =YEAR(F32) -> 2003
A33: 32º | B33: 2308 | C33: Euller | D33: Ação-MT | E33: Euller da Silva Rodrigues | F33: 34729 | G33: Brasil | H33: =COUNTIF(CAL!U:AN,B33) -> 3 | I33: 12 | J33: 2 lagunarn | K33: =MONTH(F33) -> 1 | L33: =YEAR(F33) -> 1995
A34: 33º | B34: 4346 | C34: Ryan | D34: Ação-MT | E34: Ryan Fellipe da Silva Viana | F34: 38909 | G34: Brasil | H34: =COUNTIF(CAL!U:AN,B34) -> 2 | I34: 4 | K34: =MONTH(F34) -> 7 | L34: =YEAR(F34) -> 2006
A35: 34º | B35: 4157 | C35: Samuca | D35: Ação-MT | E35: Sameul Gomes Salles dos Santos | F35: 37533 | G35: Brasil | H35: =COUNTIF(CAL!U:AN,B35) -> 1 | I35: 4 | K35: =MONTH(F35) -> 10 | L35: =YEAR(F35) -> 2002
A36: 35º | B36: 5278 | C36: Bruno | D36: Acopiara-CE | E36: Bruno Rafael da Silva | F36: 36957 | G36: Brasil | H36: =COUNTIF(CAL!U:AN,B36) -> 3 | I36: 14 | K36: =MONTH(F36) -> 3 | L36: =YEAR(F36) -> 2001
A37: 36º | B37: 3732 | C37: Davi | D37: Acopiara-CE | E37: Davi Tibúrcio da Silva | F37: 36477 | G37: Brasil | H37: =COUNTIF(CAL!U:AN,B37) -> 7 | I37: 11 | J37: 1 guaranice | K37: =MONTH(F37) -> 11 | L37: =YEAR(F37) -> 1999
A38: 37º | B38: 1197 | C38: Kaio | D38: Acopiara-CE | E38: Kaio Henrique Oliveira das Chagas | F38: 38259 | G38: Brasil | H38: =COUNTIF(CAL!U:AN,B38) -> 2 | I38: 15 | J38: 2 guaranyse | K38: =MONTH(F38) -> 9 | L38: =YEAR(F38) -> 2004
A39: 38º | B39: 5500 | C39: Kauan | D39: Acopiara-CE | H39: =COUNTIF(CAL!U:AN,B39) -> 1 | K39: =MONTH(F39) -> 1 | L39: =YEAR(F39) -> 1900
A40: 39º | B40: 5226 | C40: Leandrinho | D40: Acopiara-CE | E40: José Leandro Cândido de Paula | F40: 36867 | G40: Brasil | H40: =COUNTIF(CAL!U:AN,B40) -> 1 | I40: 14 | K40: =MONTH(F40) -> 12 | L40: =YEAR(F40) -> 2000
...

Sheet CLA
A1: POS | B1: IDCLUBE | C1: CLUBE | D1: PTS | E1: J | F1: V | G1: E | H1: D | I1: APROVEITAMENTO | J1: GOLS | K1: GL | L1: SALDO | M1: MG | N1: MD | O1: CL_SH | P1: CIDADE | Q1: UF
A2: 1º | B2: palmeirassp | C2: Palmeiras-SP | D2: =SUMIF(CAL!B:E,B2,CAL!E:E)+SUMIF(CAL!J:M,B2,CAL!M:M) -> 109 | E2: =COUNTIF(CAL!B:J,B2) -> 52 | F2: =SUMIF(CAL!B:F,B2,CAL!F:F)+SUMIF(CAL!J:N,B2,CAL!N:N) -> 32 | G2: =SUMIF(CAL!B:F,B2,CAL!G:G)+SUMIF(CAL!J:N,B2,CAL!O:O) -> 13 | H2: =SUMIF(CAL!B:F,B2,CAL!H:H)+SUMIF(CAL!J:N,B2,CAL!P:P) -> 7 | I2: =IF(E2=0,0,(D2/(E2*3))) -> 0.69871795 | J2: =SUMIF(CAL!B:C,B2,CAL!C:C)+SUMIF(CAL!J:J,B2,CAL!D:D) -> 89 | K2: =SUMIF(CAL!B:D,B2,CAL!D:D)+SUMIF(CAL!J:L,B2,CAL!K:K) -> 40 | L2: =J2-K2 -> 49 | M2: =IF(E2=0,0,(J2/E2)) -> 1.7115385 | N2: =IF(E2=0,0,(K2/E2)) -> 0.76923077 | O2: =SUMIF(CAL!B:I,B2,CAL!I:I)+SUMIF(CAL!J:Q,B2,CAL!Q:Q) -> 22 | P2: São Paulo | Q2: SP
A3: 2º | B3: fortalezace | C3: Fortaleza-CE | D3: =SUMIF(CAL!B:E,B3,CAL!E:E)+SUMIF(CAL!J:M,B3,CAL!M:M) -> 99 | E3: =COUNTIF(CAL!B:J,B3) -> 54 | F3: =SUMIF(CAL!B:F,B3,CAL!F:F)+SUMIF(CAL!J:N,B3,CAL!N:N) -> 28 | G3: =SUMIF(CAL!B:F,B3,CAL!G:G)+SUMIF(CAL!J:N,B3,CAL!O:O) -> 15 | H3: =SUMIF(CAL!B:F,B3,CAL!H:H)+SUMIF(CAL!J:N,B3,CAL!P:P) -> 11 | I3: =IF(E3=0,0,(D3/(E3*3))) -> 0.61111111 | J3: =SUMIF(CAL!B:C,B3,CAL!C:C)+SUMIF(CAL!J:J,B3,CAL!D:D) -> 67 | K3: =SUMIF(CAL!B:D,B3,CAL!D:D)+SUMIF(CAL!J:L,B3,CAL!K:K) -> 45 | L3: =J3-K3 -> 22 | M3: =IF(E3=0,0,(J3/E3)) -> 1.2407407 | N3: =IF(E3=0,0,(K3/E3)) -> 0.83333333 | O3: =SUMIF(CAL!B:I,B3,CAL!I:I)+SUMIF(CAL!J:Q,B3,CAL!Q:Q) -> 26 | P3: Fortaleza | Q3: CE
A4: 3º | B4: flamengorj | C4: Flamengo-RJ | D4: =SUMIF(CAL!B:E,B4,CAL!E:E)+SUMIF(CAL!J:M,B4,CAL!M:M) -> 94 | E4: =COUNTIF(CAL!B:J,B4) -> 49 | F4: =SUMIF(CAL!B:F,B4,CAL!F:F)+SUMIF(CAL!J:N,B4,CAL!N:N) -> 28 | G4: =SUMIF(CAL!B:F,B4,CAL!G:G)+SUMIF(CAL!J:N,B4,CAL!O:O) -> 10 | H4: =SUMIF(CAL!B:F,B4,CAL!H:H)+SUMIF(CAL!J:N,B4,CAL!P:P) -> 11 | I4: =IF(E4=0,0,(D4/(E4*3))) -> 0.63945578 | J4: =SUMIF(CAL!B:C,B4,CAL!C:C)+SUMIF(CAL!J:J,B4,CAL!D:D) -> 96 | K4: =SUMIF(CAL!B:D,B4,CAL!D:D)+SUMIF(CAL!J:L,B4,CAL!K:K) -> 44 | L4: =J4-K4 -> 52 | M4: =IF(E4=0,0,(J4/E4)) -> 1.9591837 | N4: =IF(E4=0,0,(K4/E4)) -> 0.89795918 | O4: =SUMIF(CAL!B:I,B4,CAL!I:I)+SUMIF(CAL!J:Q,B4,CAL!Q:Q) -> 20 | P4: Rio de Janeiro | Q4: RJ
A5: 4º | B5: gamadf | C5: Gama-DF | D5: =SUMIF(CAL!B:E,B5,CAL!E:E)+SUMIF(CAL!J:M,B5,CAL!M:M) -> 90 | E5: =COUNTIF(CAL!B:J,B5) -> 40 | F5: =SUMIF(CAL!B:F,B5,CAL!F:F)+SUMIF(CAL!J:N,B5,CAL!N:N) -> 27 | G5: =SUMIF(CAL!B:F,B5,CAL!G:G)+SUMIF(CAL!J:N,B5,CAL!O:O) -> 9 | H5: =SUMIF(CAL!B:F,B5,CAL!H:H)+SUMIF(CAL!J:N,B5,CAL!P:P) -> 4 | I5: =IF(E5=0,0,(D5/(E5*3))) -> 0.75 | J5: =SUMIF(CAL!B:C,B5,CAL!C:C)+SUMIF(CAL!J:J,B5,CAL!D:D) -> 66 | K5: =SUMIF(CAL!B:D,B5,CAL!D:D)+SUMIF(CAL!J:L,B5,CAL!K:K) -> 27 | L5: =J5-K5 -> 39 | M5: =IF(E5=0,0,(J5/E5)) -> 1.65 | N5: =IF(E5=0,0,(K5/E5)) -> 0.675 | O5: =SUMIF(CAL!B:I,B5,CAL!I:I)+SUMIF(CAL!J:Q,B5,CAL!Q:Q) -> 19 | P5: Gama | Q5: DF
A6: 5º | B6: asaal | C6: ASA-AL | D6: =SUMIF(CAL!B:E,B6,CAL!E:E)+SUMIF(CAL!J:M,B6,CAL!M:M) -> 85 | E6: =COUNTIF(CAL!B:J,B6) -> 46 | F6: =SUMIF(CAL!B:F,B6,CAL!F:F)+SUMIF(CAL!J:N,B6,CAL!N:N) -> 23 | G6: =SUMIF(CAL!B:F,B6,CAL!G:G)+SUMIF(CAL!J:N,B6,CAL!O:O) -> 16 | H6: =SUMIF(CAL!B:F,B6,CAL!H:H)+SUMIF(CAL!J:N,B6,CAL!P:P) -> 7 | I6: =IF(E6=0,0,(D6/(E6*3))) -> 0.61594203 | J6: =SUMIF(CAL!B:C,B6,CAL!C:C)+SUMIF(CAL!J:J,B6,CAL!D:D) -> 68 | K6: =SUMIF(CAL!B:D,B6,CAL!D:D)+SUMIF(CAL!J:L,B6,CAL!K:K) -> 31 | L6: =J6-K6 -> 37 | M6: =IF(E6=0,0,(J6/E6)) -> 1.4782609 | N6: =IF(E6=0,0,(K6/E6)) -> 0.67391304 | O6: =SUMIF(CAL!B:I,B6,CAL!I:I)+SUMIF(CAL!J:Q,B6,CAL!Q:Q) -> 24 | P6: Arapiraca | Q6: AL
A7: 6º | B7: novorizontinosp | C7: Novorizontino-SP | D7: =SUMIF(CAL!B:E,B7,CAL!E:E)+SUMIF(CAL!J:M,B7,CAL!M:M) -> 87 | E7: =COUNTIF(CAL!B:J,B7) -> 49 | F7: =SUMIF(CAL!B:F,B7,CAL!F:F)+SUMIF(CAL!J:N,B7,CAL!N:N) -> 25 | G7: =SUMIF(CAL!B:F,B7,CAL!G:G)+SUMIF(CAL!J:N,B7,CAL!O:O) -> 12 | H7: =SUMIF(CAL!B:F,B7,CAL!H:H)+SUMIF(CAL!J:N,B7,CAL!P:P) -> 12 | I7: =IF(E7=0,0,(D7/(E7*3))) -> 0.59183673 | J7: =SUMIF(CAL!B:C,B7,CAL!C:C)+SUMIF(CAL!J:J,B7,CAL!D:D) -> 81 | K7: =SUMIF(CAL!B:D,B7,CAL!D:D)+SUMIF(CAL!J:L,B7,CAL!K:K) -> 46 | L7: =J7-K7 -> 35 | M7: =IF(E7=0,0,(J7/E7)) -> 1.6530612 | N7: =IF(E7=0,0,(K7/E7)) -> 0.93877551 | O7: =SUMIF(CAL!B:I,B7,CAL!I:I)+SUMIF(CAL!J:Q,B7,CAL!Q:Q) -> 18 | P7: Novo Horizonte | Q7: SP
A8: 7º | B8: cruzeiromg | C8: Cruzeiro-MG | D8: =SUMIF(CAL!B:E,B8,CAL!E:E)+SUMIF(CAL!J:M,B8,CAL!M:M) -> 87 | E8: =COUNTIF(CAL!B:J,B8) -> 51 | F8: =SUMIF(CAL!B:F,B8,CAL!F:F)+SUMIF(CAL!J:N,B8,CAL!N:N) -> 25 | G8: =SUMIF(CAL!B:F,B8,CAL!G:G)+SUMIF(CAL!J:N,B8,CAL!O:O) -> 12 | H8: =SUMIF(CAL!B:F,B8,CAL!H:H)+SUMIF(CAL!J:N,B8,CAL!P:P) -> 14 | I8: =IF(E8=0,0,(D8/(E8*3))) -> 0.56862745 | J8: =SUMIF(CAL!B:C,B8,CAL!C:C)+SUMIF(CAL!J:J,B8,CAL!D:D) -> 73 | K8: =SUMIF(CAL!B:D,B8,CAL!D:D)+SUMIF(CAL!J:L,B8,CAL!K:K) -> 56 | L8: =J8-K8 -> 17 | M8: =IF(E8=0,0,(J8/E8)) -> 1.4313725 | N8: =IF(E8=0,0,(K8/E8)) -> 1.0980392 | O8: =SUMIF(CAL!B:I,B8,CAL!I:I)+SUMIF(CAL!J:Q,B8,CAL!Q:Q) -> 17 | P8: Belo Horizonte | Q8: MG
A9: 8º | B9: sportpe | C9: Sport-PE | D9: =SUMIF(CAL!B:E,B9,CAL!E:E)+SUMIF(CAL!J:M,B9,CAL!M:M) -> 82 | E9: =COUNTIF(CAL!B:J,B9) -> 48 | F9: =SUMIF(CAL!B:F,B9,CAL!F:F)+SUMIF(CAL!J:N,B9,CAL!N:N) -> 22 | G9: =SUMIF(CAL!B:F,B9,CAL!G:G)+SUMIF(CAL!J:N,B9,CAL!O:O) -> 16 | H9: =SUMIF(CAL!B:F,B9,CAL!H:H)+SUMIF(CAL!J:N,B9,CAL!P:P) -> 10 | I9: =IF(E9=0,0,(D9/(E9*3))) -> 0.56944444 | J9: =SUMIF(CAL!B:C,B9,CAL!C:C)+SUMIF(CAL!J:J,B9,CAL!D:D) -> 75 | K9: =SUMIF(CAL!B:D,B9,CAL!D:D)+SUMIF(CAL!J:L,B9,CAL!K:K) -> 49 | L9: =J9-K9 -> 26 | M9: =IF(E9=0,0,(J9/E9)) -> 1.5625 | N9: =IF(E9=0,0,(K9/E9)) -> 1.0208333 | O9: =SUMIF(CAL!B:I,B9,CAL!I:I)+SUMIF(CAL!J:Q,B9,CAL!Q:Q) -> 19 | P9: Recife | Q9: PE
A10: 9º | B10: atleticogo | C10: Atlético-GO | D10: =SUMIF(CAL!B:E,B10,CAL!E:E)+SUMIF(CAL!J:M,B10,CAL!M:M) -> 81 | E10: =COUNTIF(CAL!B:J,B10) -> 50 | F10: =SUMIF(CAL!B:F,B10,CAL!F:F)+SUMIF(CAL!J:N,B10,CAL!N:N) -> 21 | G10: =SUMIF(CAL!B:F,B10,CAL!G:G)+SUMIF(CAL!J:N,B10,CAL!O:O) -> 18 | H10: =SUMIF(CAL!B:F,B10,CAL!H:H)+SUMIF(CAL!J:N,B10,CAL!P:P) -> 11 | I10: =IF(E10=0,0,(D10/(E10*3))) -> 0.54 | J10: =SUMIF(CAL!B:C,B10,CAL!C:C)+SUMIF(CAL!J:J,B10,CAL!D:D) -> 55 | K10: =SUMIF(CAL!B:D,B10,CAL!D:D)+SUMIF(CAL!J:L,B10,CAL!K:K) -> 41 | L10: =J10-K10 -> 14 | M10: =IF(E10=0,0,(J10/E10)) -> 1.1 | N10: =IF(E10=0,0,(K10/E10)) -> 0.82 | O10: =SUMIF(CAL!B:I,B10,CAL!I:I)+SUMIF(CAL!J:Q,B10,CAL!Q:Q) -> 24 | P10: Goiânia | Q10: GO
A11: 10º | B11: fluminenserj | C11: Fluminense-RJ | D11: =SUMIF(CAL!B:E,B11,CAL!E:E)+SUMIF(CAL!J:M,B11,CAL!M:M) -> 86 | E11: =COUNTIF(CAL!B:J,B11) -> 49 | F11: =SUMIF(CAL!B:F,B11,CAL!F:F)+SUMIF(CAL!J:N,B11,CAL!N:N) -> 23 | G11: =SUMIF(CAL!B:F,B11,CAL!G:G)+SUMIF(CAL!J:N,B11,CAL!O:O) -> 17 | H11: =SUMIF(CAL!B:F,B11,CAL!H:H)+SUMIF(CAL!J:N,B11,CAL!P:P) -> 9 | I11: =IF(E11=0,0,(D11/(E11*3))) -> 0.58503401 | J11: =SUMIF(CAL!B:C,B11,CAL!C:C)+SUMIF(CAL!J:J,B11,CAL!D:D) -> 67 | K11: =SUMIF(CAL!B:D,B11,CAL!D:D)+SUMIF(CAL!J:L,B11,CAL!K:K) -> 51 | L11: =J11-K11 -> 16 | M11: =IF(E11=0,0,(J11/E11)) -> 1.3673469 | N11: =IF(E11=0,0,(K11/E11)) -> 1.0408163 | O11: =SUMIF(CAL!B:I,B11,CAL!I:I)+SUMIF(CAL!J:Q,B11,CAL!Q:Q) -> 14 | P11: Rio de Janeiro | Q11: RJ
A12: 11º | B12: vilanovago | C12: Vila Nova-GO | D12: =SUMIF(CAL!B:E,B12,CAL!E:E)+SUMIF(CAL!J:M,B12,CAL!M:M) -> 79 | E12: =COUNTIF(CAL!B:J,B12) -> 47 | F12: =SUMIF(CAL!B:F,B12,CAL!F:F)+SUMIF(CAL!J:N,B12,CAL!N:N) -> 22 | G12: =SUMIF(CAL!B:F,B12,CAL!G:G)+SUMIF(CAL!J:N,B12,CAL!O:O) -> 13 | H12: =SUMIF(CAL!B:F,B12,CAL!H:H)+SUMIF(CAL!J:N,B12,CAL!P:P) -> 12 | I12: =IF(E12=0,0,(D12/(E12*3))) -> 0.56028369 | J12: =SUMIF(CAL!B:C,B12,CAL!C:C)+SUMIF(CAL!J:J,B12,CAL!D:D) -> 71 | K12: =SUMIF(CAL!B:D,B12,CAL!D:D)+SUMIF(CAL!J:L,B12,CAL!K:K) -> 48 | L12: =J12-K12 -> 23 | M12: =IF(E12=0,0,(J12/E12)) -> 1.5106383 | N12: =IF(E12=0,0,(K12/E12)) -> 1.0212766 | O12: =SUMIF(CAL!B:I,B12,CAL!I:I)+SUMIF(CAL!J:Q,B12,CAL!Q:Q) -> 16 | P12: Goiânia | Q12: GO
A13: 12º | B13: juventuders | C13: Juventude-RS | D13: =SUMIF(CAL!B:E,B13,CAL!E:E)+SUMIF(CAL!J:M,B13,CAL!M:M) -> 82 | E13: =COUNTIF(CAL!B:J,B13) -> 49 | F13: =SUMIF(CAL!B:F,B13,CAL!F:F)+SUMIF(CAL!J:N,B13,CAL!N:N) -> 22 | G13: =SUMIF(CAL!B:F,B13,CAL!G:G)+SUMIF(CAL!J:N,B13,CAL!O:O) -> 16 | H13: =SUMIF(CAL!B:F,B13,CAL!H:H)+SUMIF(CAL!J:N,B13,CAL!P:P) -> 11 | I13: =IF(E13=0,0,(D13/(E13*3))) -> 0.55782313 | J13: =SUMIF(CAL!B:C,B13,CAL!C:C)+SUMIF(CAL!J:J,B13,CAL!D:D) -> 59 | K13: =SUMIF(CAL!B:D,B13,CAL!D:D)+SUMIF(CAL!J:L,B13,CAL!K:K) -> 35 | L13: =J13-K13 -> 24 | M13: =IF(E13=0,0,(J13/E13)) -> 1.2040816 | N13: =IF(E13=0,0,(K13/E13)) -> 0.71428571 | O13: =SUMIF(CAL!B:I,B13,CAL!I:I)+SUMIF(CAL!J:Q,B13,CAL!Q:Q) -> 26 | P13: Caxias do Sul | Q13: RS
... A295: 294º | B295: saocarlossp | C295: São Carlos-SP | D295: =SUMIF(CAL!B:E,B295,CAL!E:E)+SUMIF(CAL!J:M,B295,CAL!M:M) -> 15 | E295: =COUNTIF(CAL!B:J,B295) -> 12 | F295: =SUMIF(CAL!B:F,B295,CAL!F:F)+SUMIF(CAL!J:N,B295,CAL!N:N) -> 4 | G295: =SUMIF(CAL!B:F,B295,CAL!G:G)+SUMIF(CAL!J:N,B295,CAL!O:O) -> 3 | H295: =SUMIF(CAL!B:F,B295,CAL!H:H)+SUMIF(CAL!J:N,B295,CAL!P:P) -> 5 | I295: =IF(E295=0,0,(D295/(E295*3))) -> 0.41666667 | J295: =SUMIF(CAL!B:C,B295,CAL!C:C)+SUMIF(CAL!J:J,B295,CAL!D:D) -> 19 | K295: =SUMIF(CAL!B:D,B295,CAL!D:D)+SUMIF(CAL!J:L,B295,CAL!K:K) -> 14 | L295: =J295-K295 -> 5 | M295: =IF(E295=0,0,(J295/E295)) -> 1.5833333 | N295: =IF(E295=0,0,(K295/E295)) -> 1.1666667 | O295: =SUMIF(CAL!B:I,B295,CAL!I:I)+SUMIF(CAL!J:Q,B295,CAL!Q:Q) -> 3 | P295: São Carlos | Q295: SP
A296: 295º | B296: crateusce | C296: Crateús-CE | D296: =SUMIF(CAL!B:E,B296,CAL!E:E)+SUMIF(CAL!J:M,B296,CAL!M:M) -> 15 | E296: =COUNTIF(CAL!B:J,B296) -> 11 | F296: =SUMIF(CAL!B:F,B296,CAL!F:F)+SUMIF(CAL!J:N,B296,CAL!N:N) -> 4 | G296: =SUMIF(CAL!B:F,B296,CAL!G:G)+SUMIF(CAL!J:N,B296,CAL!O:O) -> 3 | H296: =SUMIF(CAL!B:F,B296,CAL!H:H)+SUMIF(CAL!J:N,B296,CAL!P:P) -> 4 | I296: =IF(E296=0,0,(D296/(E296*3))) -> 0.45454545 | J296: =SUMIF(CAL!B:C,B296,CAL!C:C)+SUMIF(CAL!J:J,B296,CAL!D:D) -> 10 | K296: =SUMIF(CAL!B:D,B296,CAL!D:D)+SUMIF(CAL!J:L,B296,CAL!K:K) -> 7 | L296: =J296-K296 -> 3 | M296: =IF(E296=0,0,(J296/E296)) -> 0.90909091 | N296: =IF(E296=0,0,(K296/E296)) -> 0.63636364 | O296: =SUMIF(CAL!B:I,B296,CAL!I:I)+SUMIF(CAL!J:Q,B296,CAL!Q:Q) -> 6
A297: 296º | B297: santacruzensesp | C297: Santacruzense-SP | D297: =SUMIF(CAL!B:E,B297,CAL!E:E)+SUMIF(CAL!J:M,B297,CAL!M:M) -> 15 | E297: =COUNTIF(CAL!B:J,B297) -> 12 | F297: =SUMIF(CAL!B:F,B297,CAL!F:F)+SUMIF(CAL!J:N,B297,CAL!N:N) -> 4 | G297: =SUMIF(CAL!B:F,B297,CAL!G:G)+SUMIF(CAL!J:N,B297,CAL!O:O) -> 3 | H297: =SUMIF(CAL!B:F,B297,CAL!H:H)+SUMIF(CAL!J:N,B297,CAL!P:P) -> 5 | I297: =IF(E297=0,0,(D297/(E297*3))) -> 0.41666667 | J297: =SUMIF(CAL!B:C,B297,CAL!C:C)+SUMIF(CAL!J:J,B297,CAL!D:D) -> 19 | K297: =SUMIF(CAL!B:D,B297,CAL!D:D)+SUMIF(CAL!J:L,B297,CAL!K:K) -> 16 | L297: =J297-K297 -> 3 | M297: =IF(E297=0,0,(J297/E297)) -> 1.5833333 | N297: =IF(E297=0,0,(K297/E297)) -> 1.3333333 | O297: =SUMIF(CAL!B:I,B297,CAL!I:I)+SUMIF(CAL!J:Q,B297,CAL!Q:Q) -> 4 | P297: Santa Cruz do Rio Pardo | Q297: SP
A298: 297º | B298: izabelensepa | C298: Izabelense-PA | D298: =SUMIF(CAL!B:E,B298,CAL!E:E)+SUMIF(CAL!J:M,B298,CAL!M:M) -> 15 | E298: =COUNTIF(CAL!B:J,B298) -> 9 | F298: =SUMIF(CAL!B:F,B298,CAL!F:F)+SUMIF(CAL!J:N,B298,CAL!N:N) -> 4 | G298: =SUMIF(CAL!B:F,B298,CAL!G:G)+SUMIF(CAL!J:N,B298,CAL!O:O) -> 3 | H298: =SUMIF(CAL!B:F,B298,CAL!H:H)+SUMIF(CAL!J:N,B298,CAL!P:P) -> 2 | I298: =IF(E298=0,0,(D298/(E298*3))) -> 0.55555556 | J298: =SUMIF(CAL!B:C,B298,CAL!C:C)+SUMIF(CAL!J:J,B298,CAL!D:D) -> 12 | K298: =SUMIF(CAL!B:D,B298,CAL!D:D)+SUMIF(CAL!J:L,B298,CAL!K:K) -> 10 | L298: =J298-K298 -> 2 | M298: =IF(E298=0,0,(J298/E298)) -> 1.3333333 | N298: =IF(E298=0,0,(K298/E298)) -> 1.1111111 | O298: =SUMIF(CAL!B:I,B298,CAL!I:I)+SUMIF(CAL!J:Q,B298,CAL!Q:Q) -> 2
A299: 298º | B299: tupygo | C299: Tupy-GO | D299: =SUMIF(CAL!B:E,B299,CAL!E:E)+SUMIF(CAL!J:M,B299,CAL!M:M) -> 16 | E299: =COUNTIF(CAL!B:J,B299) -> 11 | F299: =SUMIF(CAL!B:F,B299,CAL!F:F)+SUMIF(CAL!J:N,B299,CAL!N:N) -> 4 | G299: =SUMIF(CAL!B:F,B299,CAL!G:G)+SUMIF(CAL!J:N,B299,CAL!O:O) -> 4 | H299: =SUMIF(CAL!B:F,B299,CAL!H:H)+SUMIF(CAL!J:N,B299,CAL!P:P) -> 3 | I299: =IF(E299=0,0,(D299/(E299*3))) -> 0.48484848 | J299: =SUMIF(CAL!B:C,B299,CAL!C:C)+SUMIF(CAL!J:J,B299,CAL!D:D) -> 10 | K299: =SUMIF(CAL!B:D,B299,CAL!D:D)+SUMIF(CAL!J:L,B299,CAL!K:K) -> 8 | L299: =J299-K299 -> 2 | M299: =IF(E299=0,0,(J299/E299)) -> 0.90909091 | N299: =IF(E299=0,0,(K299/E299)) -> 0.72727273 | O299: =SUMIF(CAL!B:I,B299,CAL!I:I)+SUMIF(CAL!J:Q,B299,CAL!Q:Q) -> 3 | P299: Jussara | Q299: GO
A300: 299º | B300: laranjamecanicapr | C300: Laranja Mecânica-PR | D300: =SUMIF(CAL!B:E,B300,CAL!E:E)+SUMIF(CAL!J:M,B300,CAL!M:M) -> 15 | E300: =COUNTIF(CAL!B:J,B300) -> 11 | F300: =SUMIF(CAL!B:F,B300,CAL!F:F)+SUMIF(CAL!J:N,B300,CAL!N:N) -> 4 | G300: =SUMIF(CAL!B:F,B300,CAL!G:G)+SUMIF(CAL!J:N,B300,CAL!O:O) -> 3 | H300: =SUMIF(CAL!B:F,B300,CAL!H:H)+SUMIF(CAL!J:N,B300,CAL!P:P) -> 4 | I300: =IF(E300=0,0,(D300/(E300*3))) -> 0.45454545 | J300: =SUMIF(CAL!B:C,B300,CAL!C:C)+SUMIF(CAL!J:J,B300,CAL!D:D) -> 8 | K300: =SUMIF(CAL!B:D,B300,CAL!D:D)+SUMIF(CAL!J:L,B300,CAL!K:K) -> 11 | L300: =J300-K300 -> -3 | M300: =IF(E300=0,0,(J300/E300)) -> 0.72727273 | N300: =IF(E300=0,0,(K300/E300)) -> 1 | O300: =SUMIF(CAL!B:I,B300,CAL!I:I)+SUMIF(CAL!J:Q,B300,CAL!Q:Q) -> 5
A301: 300º | B301: bangurj | C301: Bangu-RJ | D301: =SUMIF(CAL!B:E,B301,CAL!E:E)+SUMIF(CAL!J:M,B301,CAL!M:M) -> 15 | E301: =COUNTIF(CAL!B:J,B301) -> 12 | F301: =SUMIF(CAL!B:F,B301,CAL!F:F)+SUMIF(CAL!J:N,B301,CAL!N:N) -> 4 | G301: =SUMIF(CAL!B:F,B301,CAL!G:G)+SUMIF(CAL!J:N,B301,CAL!O:O) -> 3 | H301: =SUMIF(CAL!B:F,B301,CAL!H:H)+SUMIF(CAL!J:N,B301,CAL!P:P) -> 5 | I301: =IF(E301=0,0,(D301/(E301*3))) -> 0.41666667 | J301: =SUMIF(CAL!B:C,B301,CAL!C:C)+SUMIF(CAL!J:J,B301,CAL!D:D) -> 12 | K301: =SUMIF(CAL!B:D,B301,CAL!D:D)+SUMIF(CAL!J:L,B301,CAL!K:K) -> 17 | L301: =J301-K301 -> -5 | M301: =IF(E301=0,0,(J301/E301)) -> 1 | N301: =IF(E301=0,0,(K301/E301)) -> 1.4166667 | O301: =SUMIF(CAL!B:I,B301,CAL!I:I)+SUMIF(CAL!J:Q,B301,CAL!Q:Q) -> 1 | P301: Rio de Janeiro | Q301: RJ
A302: 301º | B302: assisensesp | C302: Assisense-SP | D302: =SUMIF(CAL!B:E,B302,CAL!E:E)+SUMIF(CAL!J:M,B302,CAL!M:M) -> 15 | E302: =COUNTIF(CAL!B:J,B302) -> 12 | F302: =SUMIF(CAL!B:F,B302,CAL!F:F)+SUMIF(CAL!J:N,B302,CAL!N:N) -> 3 | G302: =SUMIF(CAL!B:F,B302,CAL!G:G)+SUMIF(CAL!J:N,B302,CAL!O:O) -> 6 | H302: =SUMIF(CAL!B:F,B302,CAL!H:H)+SUMIF(CAL!J:N,B302,CAL!P:P) -> 3 | I302: =IF(E302=0,0,(D302/(E302*3))) -> 0.41666667 | J302: =SUMIF(CAL!B:C,B302,CAL!C:C)+SUMIF(CAL!J:J,B302,CAL!D:D) -> 17 | K302: =SUMIF(CAL!B:D,B302,CAL!D:D)+SUMIF(CAL!J:L,B302,CAL!K:K) -> 16 | L302: =J302-K302 -> 1 | M302: =IF(E302=0,0,(J302/E302)) -> 1.4166667 | N302: =IF(E302=0,0,(K302/E302)) -> 1.3333333 | O302: =SUMIF(CAL!B:I,B302,CAL!I:I)+SUMIF(CAL!J:Q,B302,CAL!Q:Q) -> 2 | P302: Assis | Q302: SP
A303: 302º | B303: desportivaes | C303: Desportiva-ES | D303: =SUMIF(CAL!B:E,B303,CAL!E:E)+SUMIF(CAL!J:M,B303,CAL!M:M) -> 15 | E303: =COUNTIF(CAL!B:J,B303) -> 13 | F303: =SUMIF(CAL!B:F,B303,CAL!F:F)+SUMIF(CAL!J:N,B303,CAL!N:N) -> 3 | G303: =SUMIF(CAL!B:F,B303,CAL!G:G)+SUMIF(CAL!J:N,B303,CAL!O:O) -> 6 | H303: =SUMIF(CAL!B:F,B303,CAL!H:H)+SUMIF(CAL!J:N,B303,CAL!P:P) -> 4 | I303: =IF(E303=0,0,(D303/(E303*3))) -> 0.38461538 | J303: =SUMIF(CAL!B:C,B303,CAL!C:C)+SUMIF(CAL!J:J,B303,CAL!D:D) -> 13 | K303: =SUMIF(CAL!B:D,B303,CAL!D:D)+SUMIF(CAL!J:L,B303,CAL!K:K) -> 14 | L303: =J303-K303 -> -1 | M303: =IF(E303=0,0,(J303/E303)) -> 1 | N303: =IF(E303=0,0,(K303/E303)) -> 1.0769231 | O303: =SUMIF(CAL!B:I,B303,CAL!I:I)+SUMIF(CAL!J:Q,B303,CAL!Q:Q) -> 4
A304: 303º | B304: vocemsp | C304: VOCEM-SP | D304: =SUMIF(CAL!B:E,B304,CAL!E:E)+SUMIF(CAL!J:M,B304,CAL!M:M) -> 15 | E304: =COUNTIF(CAL!B:J,B304) -> 15 | F304: =SUMIF(CAL!B:F,B304,CAL!F:F)+SUMIF(CAL!J:N,B304,CAL!N:N) -> 3 | G304: =SUMIF(CAL!B:F,B304,CAL!G:G)+SUMIF(CAL!J:N,B304,CAL!O:O) -> 6 | H304: =SUMIF(CAL!B:F,B304,CAL!H:H)+SUMIF(CAL!J:N,B304,CAL!P:P) -> 6 | I304: =IF(E304=0,0,(D304/(E304*3))) -> 0.33333333 | J304: =SUMIF(CAL!B:C,B304,CAL!C:C)+SUMIF(CAL!J:J,B304,CAL!D:D) -> 12 | K304: =SUMIF(CAL!B:D,B304,CAL!D:D)+SUMIF(CAL!J:L,B304,CAL!K:K) -> 13 | L304: =J304-K304 -> -1 | M304: =IF(E304=0,0,(J304/E304)) -> 0.8 | N304: =IF(E304=0,0,(K304/E304)) -> 0.86666667 | O304: =SUMIF(CAL!B:I,B304,CAL!I:I)+SUMIF(CAL!J:Q,B304,CAL!Q:Q) -> 7 | P304: Rio Claro | Q304: Sp
A305: 304º | B305: brasilfarrs | C305: Brasil de Farroupilha-RS | D305: =SUMIF(CAL!B:E,B305,CAL!E:E)+SUMIF(CAL!J:M,B305,CAL!M:M) -> 18 | E305: =COUNTIF(CAL!B:J,B305) -> 15 | F305: =SUMIF(CAL!B:F,B305,CAL!F:F)+SUMIF(CAL!J:N,B305,CAL!N:N) -> 3 | G305: =SUMIF(CAL!B:F,B305,CAL!G:G)+SUMIF(CAL!J:N,B305,CAL!O:O) -> 9 | H305: =SUMIF(CAL!B:F,B305,CAL!H:H)+SUMIF(CAL!J:N,B305,CAL!P:P) -> 3 | I305: =IF(E305=0,0,(D305/(E305*3))) -> 0.4 | J305: =SUMIF(CAL!B:C,B305,CAL!C:C)+SUMIF(CAL!J:J,B305,CAL!D:D) -> 16 | K305: =SUMIF(CAL!B:D,B305,CAL!D:D)+SUMIF(CAL!J:L,B305,CAL!K:K) -> 15 | L305: =J305-K305 -> 1 | M305: =IF(E305=0,0,(J305/E305)) -> 1.0666667 | N305: =IF(E305=0,0,(K305/E305)) -> 1 | O305: =SUMIF(CAL!B:I,B305,CAL!I:I)+SUMIF(CAL!J:Q,B305,CAL!Q:Q) -> 5 | P305: Farroupilha | Q305: RS
A306: 305º | B306: fastam | C306: Fast-AM | D306: =SUMIF(CAL!B:E,B306,CAL!E:E)+SUMIF(CAL!J:M,B306,CAL!M:M) -> 20 | E306: =COUNTIF(CAL!B:J,B306) -> 8 | F306: =SUMIF(CAL!B:F,B306,CAL!F:F)+SUMIF(CAL!J:N,B306,CAL!N:N) -> 6 | G306: =SUMIF(CAL!B:F,B306,CAL!G:G)+SUMIF(CAL!J:N,B306,CAL!O:O) -> 2 | H306: =SUMIF(CAL!B:F,B306,CAL!H:H)+SUMIF(CAL!J:N,B306,CAL!P:P) -> 0 | I306: =IF(E306=0,0,(D306/(E306*3))) -> 0.83333333 | J306: =SUMIF(CAL!B:C,B306,CAL!C:C)+SUMIF(CAL!J:J,B306,CAL!D:D) -> 19 | K306: =SUMIF(CAL!B:D,B306,CAL!D:D)+SUMIF(CAL!J:L,B306,CAL!K:K) -> 5 | L306: =J306-K306 -> 14 | M306: =IF(E306=0,0,(J306/E306)) -> 2.375 | N306: =IF(E306=0,0,(K306/E306)) -> 0.625 | O306: =SUMIF(CAL!B:I,B306,CAL!I:I)+SUMIF(CAL!J:Q,B306,CAL!Q:Q) -> 3 | P306: Manaus | Q306: AM
A307: 306º | B307: portuguesaap | C307: Portuguesa-AP | D307: =SUMIF(CAL!B:E,B307,CAL!E:E)+SUMIF(CAL!J:M,B307,CAL!M:M) -> 14 | E307: =COUNTIF(CAL!B:J,B307) -> 8 | F307: =SUMIF(CAL!B:F,B307,CAL!F:F)+SUMIF(CAL!J:N,B307,CAL!N:N) -> 4 | G307: =SUMIF(CAL!B:F,B307,CAL!G:G)+SUMIF(CAL!J:N,B307,CAL!O:O) -> 2 | H307: =SUMIF(CAL!B:F,B307,CAL!H:H)+SUMIF(CAL!J:N,B307,CAL!P:P) -> 2 | I307: =IF(E307=0,0,(D307/(E307*3))) -> 0.58333333 | J307: =SUMIF(CAL!B:C,B307,CAL!C:C)+SUMIF(CAL!J:J,B307,CAL!D:D) -> 15 | K307: =SUMIF(CAL!B:D,B307,CAL!D:D)+SUMIF(CAL!J:L,B307,CAL!K:K) -> 8 | L307: =J307-K307 -> 7 | M307: =IF(E307=0,0,(J307/E307)) -> 1.875 | N307: =IF(E307=0,0,(K307/E307)) -> 1 | O307: =SUMIF(CAL!B:I,B307,CAL!I:I)+SUMIF(CAL!J:Q,B307,CAL!Q:Q) -> 3 | P307: Macapá | Q307: AP
A308: 307º | B308: cruzeiroap | C308: Cruzeiro-AP | D308: =SUMIF(CAL!B:E,B308,CAL!E:E)+SUMIF(CAL!J:M,B308,CAL!M:M) -> 14 | E308: =COUNTIF(CAL!B:J,B308) -> 7 | F308: =SUMIF(CAL!B:F,B308,CAL!F:F)+SUMIF(CAL!J:N,B308,CAL!N:N) -> 4 | G308: =SUMIF(CAL!B:F,B308,CAL!G:G)+SUMIF(CAL!J:N,B308,CAL!O:O) -> 2 | H308: =SUMIF(CAL!B:F,B308,CAL!H:H)+SUMIF(CAL!J:N,B308,CAL!P:P) -> 1 | I308: =IF(E308=0,0,(D308/(E308*3))) -> 0.66666667 | J308: =SUMIF(CAL!B:C,B308,CAL!C:C)+SUMIF(CAL!J:J,B308,CAL!D:D) -> 13 | K308: =SUMIF(CAL!B:D,B308,CAL!D:D)+SUMIF(CAL!J:L,B308,CAL!K:K) -> 7 | L308: =J308-K308 -> 6 | M308: =IF(E308=0,0,(J308/E308)) -> 1.8571429 | N308: =IF(E308=0,0,(K308/E308)) -> 1 | O308: =SUMIF(CAL!B:I,B308,CAL!I:I)+SUMIF(CAL!J:Q,B308,CAL!Q:Q) -> 2 | P308: Macapá | Q308: AP
A309: 308º | B309: redencaoba | C309: Redenção-BA | D309: =SUMIF(CAL!B:E,B309,CAL!E:E)+SUMIF(CAL!J:M,B309,CAL!M:M) -> 14 | E309: =COUNTIF(CAL!B:J,B309) -> 9 | F309: =SUMIF(CAL!B:F,B309,CAL!F:F)+SUMIF(CAL!J:N,B309,CAL!N:N) -> 4 | G309: =SUMIF(CAL!B:F,B309,CAL!G:G)+SUMIF(CAL!J:N,B309,CAL!O:O) -> 2 | H309: =SUMIF(CAL!B:F,B309,CAL!H:H)+SUMIF(CAL!J:N,B309,CAL!P:P) -> 3 | I309: =IF(E309=0,0,(D309/(E309*3))) -> 0.51851852 | J309: =SUMIF(CAL!B:C,B309,CAL!C:C)+SUMIF(CAL!J:J,B309,CAL!D:D) -> 16 | K309: =SUMIF(CAL!B:D,B309,CAL!D:D)+SUMIF(CAL!J:L,B309,CAL!K:K) -> 11 | L309: =J309-K309 -> 5 | M309: =IF(E309=0,0,(J309/E309)) -> 1.7777778 | N309: =IF(E309=0,0,(K309/E309)) -> 1.2222222 | O309: =SUMIF(CAL!B:I,B309,CAL!I:I)+SUMIF(CAL!J:Q,B309,CAL!Q:Q) -> 4 | P309: Salvador | Q309: BA
A310: 309º | B310: mistoms | C310: Misto-MS | D310: =SUMIF(CAL!B:E,B310,CAL!E:E)+SUMIF(CAL!J:M,B310,CAL!M:M) -> 14 | E310: =COUNTIF(CAL!B:J,B310) -> 7 | F310: =SUMIF(CAL!B:F,B310,CAL!F:F)+SUMIF(CAL!J:N,B310,CAL!N:N) -> 4 | G310: =SUMIF(CAL!B:F,B310,CAL!G:G)+SUMIF(CAL!J:N,B310,CAL!O:O) -> 2 | H310: =SUMIF(CAL!B:F,B310,CAL!H:H)+SUMIF(CAL!J:N,B310,CAL!P:P) -> 1 | I310: =IF(E310=0,0,(D310/(E310*3))) -> 0.66666667 | J310: =SUMIF(CAL!B:C,B310,CAL!C:C)+SUMIF(CAL!J:J,B310,CAL!D:D) -> 9 | K310: =SUMIF(CAL!B:D,B310,CAL!D:D)+SUMIF(CAL!J:L,B310,CAL!K:K) -> 5 | L310: =J310-K310 -> 4 | M310: =IF(E310=0,0,(J310/E310)) -> 1.2857143 | N310: =IF(E310=0,0,(K310/E310)) -> 0.71428571 | O310: =SUMIF(CAL!B:I,B310,CAL!I:I)+SUMIF(CAL!J:Q,B310,CAL!Q:Q) -> 4 | P310: Três Lagoas | Q310: MS
A311: 310º | B311: Uniaofrederiquensers | C311: União Frederiquense-RS | D311: =SUMIF(CAL!B:E,B311,CAL!E:E)+SUMIF(CAL!J:M,B311,CAL!M:M) -> 15 | E311: =COUNTIF(CAL!B:J,B311) -> 9 | F311: =SUMIF(CAL!B:F,B311,CAL!F:F)+SUMIF(CAL!J:N,B311,CAL!N:N) -> 4 | G311: =SUMIF(CAL!B:F,B311,CAL!G:G)+SUMIF(CAL!J:N,B311,CAL!O:O) -> 3 | H311: =SUMIF(CAL!B:F,B311,CAL!H:H)+SUMIF(CAL!J:N,B311,CAL!P:P) -> 2 | I311: =IF(E311=0,0,(D311/(E311*3))) -> 0.55555556 | J311: =SUMIF(CAL!B:C,B311,CAL!C:C)+SUMIF(CAL!J:J,B311,CAL!D:D) -> 8 | K311: =SUMIF(CAL!B:D,B311,CAL!D:D)+SUMIF(CAL!J:L,B311,CAL!K:K) -> 4 | L311: =J311-K311 -> 4 | M311: =IF(E311=0,0,(J311/E311)) -> 0.88888889 | N311: =IF(E311=0,0,(K311/E311)) -> 0.44444444 | O311: =SUMIF(CAL!B:I,B311,CAL!I:I)+SUMIF(CAL!J:Q,B311,CAL!Q:Q) -> 6 | P311: Frederico Westfalen | Q311: RS
A312: 311º | B312: veranopolisrs | C312: Veranópolis-RS | D312: =SUMIF(CAL!B:E,B312,CAL!E:E)+SUMIF(CAL!J:M,B312,CAL!M:M) -> 17 | E312: =COUNTIF(CAL!B:J,B312) -> 9 | F312: =SUMIF(CAL!B:F,B312,CAL!F:F)+SUMIF(CAL!J:N,B312,CAL!N:N) -> 5 | G312: =SUMIF(CAL!B:F,B312,CAL!G:G)+SUMIF(CAL!J:N,B312,CAL!O:O) -> 2 | H312: =SUMIF(CAL!B:F,B312,CAL!H:H)+SUMIF(CAL!J:N,B312,CAL!P:P) -> 2 | I312: =IF(E312=0,0,(D312/(E312*3))) -> 0.62962963 | J312: =SUMIF(CAL!B:C,B312,CAL!C:C)+SUMIF(CAL!J:J,B312,CAL!D:D) -> 10 | K312: =SUMIF(CAL!B:D,B312,CAL!D:D)+SUMIF(CAL!J:L,B312,CAL!K:K) -> 5 | L312: =J312-K312 -> 5 | M312: =IF(E312=0,0,(J312/E312)) -> 1.1111111 | N312: =IF(E312=0,0,(K312/E312)) -> 0.55555556 | O312: =SUMIF(CAL!B:I,B312,CAL!I:I)+SUMIF(CAL!J:Q,B312,CAL!Q:Q) -> 6 | P312: Veranópolis | Q312: RS
A313: 312º | B313: morrinhosgo | C313: Morrinhos-GO | D313: =SUMIF(CAL!B:E,B313,CAL!E:E)+SUMIF(CAL!J:M,B313,CAL!M:M) -> 15 | E313: =COUNTIF(CAL!B:J,B313) -> 10 | F313: =SUMIF(CAL!B:F,B313,CAL!F:F)+SUMIF(CAL!J:N,B313,CAL!N:N) -> 4 | G313: =SUMIF(CAL!B:F,B313,CAL!G:G)+SUMIF(CAL!J:N,B313,CAL!O:O) -> 3 | H313: =SUMIF(CAL!B:F,B313,CAL!H:H)+SUMIF(CAL!J:N,B313,CAL!P:P) -> 3 | I313: =IF(E313=0,0,(D313/(E313*3))) -> 0.5 | J313: =SUMIF(CAL!B:C,B313,CAL!C:C)+SUMIF(CAL!J:J,B313,CAL!D:D) -> 16 | K313: =SUMIF(CAL!B:D,B313,CAL!D:D)+SUMIF(CAL!J:L,B313,CAL!K:K) -> 14 | L313: =J313-K313 -> 2 | M313: =IF(E313=0,0,(J313/E313)) -> 1.6 | N313: =IF(E313=0,0,(K313/E313)) -> 1.4 | O313: =SUMIF(CAL!B:I,B313,CAL!I:I)+SUMIF(CAL!J:Q,B313,CAL!Q:Q) -> 3 | P313: Morrinhos | Q313: GO
A314: 313º | B314: riobarrarj | C314: Rio Barra-RJ | D314: =SUMIF(CAL!B:E,B314,CAL!E:E)+SUMIF(CAL!J:M,B314,CAL!M:M) -> 14 | E314: =COUNTIF(CAL!B:J,B314) -> 10 | F314: =SUMIF(CAL!B:F,B314,CAL!F:F)+SUMIF(CAL!J:N,B314,CAL!N:N) -> 4 | G314: =SUMIF(CAL!B:F,B314,CAL!G:G)+SUMIF(CAL!J:N,B314,CAL!O:O) -> 2 | H314: =SUMIF(CAL!B:F,B314,CAL!H:H)+SUMIF(CAL!J:N,B314,CAL!P:P) -> 4 | I314: =IF(E314=0,0,(D314/(E314*3))) -> 0.46666667 | J314: =SUMIF(CAL!B:C,B314,CAL!C:C)+SUMIF(CAL!J:J,B314,CAL!D:D) -> 14 | K314: =SUMIF(CAL!B:D,B314,CAL!D:D)+SUMIF(CAL!J:L,B314,CAL!K:K) -> 12 | L314: =J314-K314 -> 2 | M314: =IF(E314=0,0,(J314/E314)) -> 1.4 | N314: =IF(E314=0,0,(K314/E314)) -> 1.2 | O314: =SUMIF(CAL!B:I,B314,CAL!I:I)+SUMIF(CAL!J:Q,B314,CAL!Q:Q) -> 3
A315: 314º | B315: aimorers | C315: Aimoré-RS | D315: =SUMIF(CAL!B:E,B315,CAL!E:E)+SUMIF(CAL!J:M,B315,CAL!M:M) -> 14 | E315: =COUNTIF(CAL!B:J,B315) -> 9 | F315: =SUMIF(CAL!B:F,B315,CAL!F:F)+SUMIF(CAL!J:N,B315,CAL!N:N) -> 4 | G315: =SUMIF(CAL!B:F,B315,CAL!G:G)+SUMIF(CAL!J:N,B315,CAL!O:O) -> 2 | H315: =SUMIF(CAL!B:F,B315,CAL!H:H)+SUMIF(CAL!J:N,B315,CAL!P:P) -> 3 | I315: =IF(E315=0,0,(D315/(E315*3))) -> 0.51851852 | J315: =SUMIF(CAL!B:C,B315,CAL!C:C)+SUMIF(CAL!J:J,B315,CAL!D:D) -> 9 | K315: =SUMIF(CAL!B:D,B315,CAL!D:D)+SUMIF(CAL!J:L,B315,CAL!K:K) -> 9 | L315: =J315-K315 -> 0 | M315: =IF(E315=0,0,(J315/E315)) -> 1 | N315: =IF(E315=0,0,(K315/E315)) -> 1 | O315: =SUMIF(CAL!B:I,B315,CAL!I:I)+SUMIF(CAL!J:Q,B315,CAL!Q:Q) -> 4 | P315: São Leopoldo | Q315: RS
A316: 315º | B316: uniaocentralrj | C316: União Central-RJ | D316: =SUMIF(CAL!B:E,B316,CAL!E:E)+SUMIF(CAL!J:M,B316,CAL!M:M) -> 14 | E316: =COUNTIF(CAL!B:J,B316) -> 10 | F316: =SUMIF(CAL!B:F,B316,CAL!F:F)+SUMIF(CAL!J:N,B316,CAL!N:N) -> 4 | G316: =SUMIF(CAL!B:F,B316,CAL!G:G)+SUMIF(CAL!J:N,B316,CAL!O:O) -> 2 | H316: =SUMIF(CAL!B:F,B316,CAL!H:H)+SUMIF(CAL!J:N,B316,CAL!P:P) -> 4 | I316: =IF(E316=0,0,(D316/(E316*3))) -> 0.46666667 | J316: =SUMIF(CAL!B:C,B316,CAL!C:C)+SUMIF(CAL!J:J,B316,CAL!D:D) -> 16 | K316: =SUMIF(CAL!B:D,B316,CAL!D:D)+SUMIF(CAL!J:L,B316,CAL!K:K) -> 18 | L316: =J316-K316 -> -2 | M316: =IF(E316=0,0,(J316/E316)) -> 1.6 | N316: =IF(E316=0,0,(K316/E316)) -> 1.8 | O316: =SUMIF(CAL!B:I,B316,CAL!I:I)+SUMIF(CAL!J:Q,B316,CAL!Q:Q) -> 1
A317: 316º | B317: manthiqueirasp | C317: Manthiqueira-SP | D317: =SUMIF(CAL!B:E,B317,CAL!E:E)+SUMIF(CAL!J:M,B317,CAL!M:M) -> 14 | E317: =COUNTIF(CAL!B:J,B317) -> 12 | F317: =SUMIF(CAL!B:F,B317,CAL!F:F)+SUMIF(CAL!J:N,B317,CAL!N:N) -> 4 | G317: =SUMIF(CAL!B:F,B317,CAL!G:G)+SUMIF(CAL!J:N,B317,CAL!O:O) -> 2 | H317: =SUMIF(CAL!B:F,B317,CAL!H:H)+SUMIF(CAL!J:N,B317,CAL!P:P) -> 6 | I317: =IF(E317=0,0,(D317/(E317*3))) -> 0.38888889 | J317: =SUMIF(CAL!B:C,B317,CAL!C:C)+SUMIF(CAL!J:J,B317,CAL!D:D) -> 18 | K317: =SUMIF(CAL!B:D,B317,CAL!D:D)+SUMIF(CAL!J:L,B317,CAL!K:K) -> 21 | L317: =J317-K317 -> -3 | M317: =IF(E317=0,0,(J317/E317)) -> 1.5 | N317: =IF(E317=0,0,(K317/E317)) -> 1.75 | O317: =SUMIF(CAL!B:I,B317,CAL!I:I)+SUMIF(CAL!J:Q,B317,CAL!Q:Q) -> 0
A318: 317º | B318: fozdoiguacupr | C318: Foz do Iguaçu-PR | D318: =SUMIF(CAL!B:E,B318,CAL!E:E)+SUMIF(CAL!J:M,B318,CAL!M:M) -> 14 | E318: =COUNTIF(CAL!B:J,B318) -> 10 | F318: =SUMIF(CAL!B:F,B318,CAL!F:F)+SUMIF(CAL!J:N,B318,CAL!N:N) -> 4 | G318: =SUMIF(CAL!B:F,B318,CAL!G:G)+SUMIF(CAL!J:N,B318,CAL!O:O) -> 2 | H318: =SUMIF(CAL!B:F,B318,CAL!H:H)+SUMIF(CAL!J:N,B318,CAL!P:P) -> 4 | I318: =IF(E318=0,0,(D318/(E318*3))) -> 0.46666667 | J318: =SUMIF(CAL!B:C,B318,CAL!C:C)+SUMIF(CAL!J:J,B318,CAL!D:D) -> 15 | K318: =SUMIF(CAL!B:D,B318,CAL!D:D)+SUMIF(CAL!J:L,B318,CAL!K:K) -> 21 | L318: =J318-K318 -> -6 | M318: =IF(E318=0,0,(J318/E318)) -> 1.5 | N318: =IF(E318=0,0,(K318/E318)) -> 2.1 | O318: =SUMIF(CAL!B:I,B318,CAL!I:I)+SUMIF(CAL!J:Q,B318,CAL!Q:Q) -> 0 | P318: Foz do Iguaçu | Q318: PR
A319: 318º | B319: independenteap | C319: Indepentende-AP | D319: =SUMIF(CAL!B:E,B319,CAL!E:E)+SUMIF(CAL!J:M,B319,CAL!M:M) -> 14 | E319: =COUNTIF(CAL!B:J,B319) -> 10 | F319: =SUMIF(CAL!B:F,B319,CAL!F:F)+SUMIF(CAL!J:N,B319,CAL!N:N) -> 3 | G319: =SUMIF(CAL!B:F,B319,CAL!G:G)+SUMIF(CAL!J:N,B319,CAL!O:O) -> 5 | H319: =SUMIF(CAL!B:F,B319,CAL!H:H)+SUMIF(CAL!J:N,B319,CAL!P:P) -> 2 | I319: =IF(E319=0,0,(D319/(E319*3))) -> 0.46666667 | J319: =SUMIF(CAL!B:C,B319,CAL!C:C)+SUMIF(CAL!J:J,B319,CAL!D:D) -> 18 | K319: =SUMIF(CAL!B:D,B319,CAL!D:D)+SUMIF(CAL!J:L,B319,CAL!K:K) -> 12 | L319: =J319-K319 -> 6 | M319: =IF(E319=0,0,(J319/E319)) -> 1.8 | N319: =IF(E319=0,0,(K319/E319)) -> 1.2 | O319: =SUMIF(CAL!B:I,B319,CAL!I:I)+SUMIF(CAL!J:Q,B319,CAL!Q:Q) -> 2 | P319: Santana | Q319: AP
