Workbook

Sheet CAL
A1: Data | B1: Mandante | C1: GM | D1: GV | E1: pc | F1: vitc | G1: empc | H1: derc | I1: csc | J1: Visitante | K1: gc | L1: gf | M1: pf | N1: vit | O1: empf | P1: derf | Q1: csf | R1: Camp | S1: Coluna1 | T1: Coluna2 | U1: 1 | V1: 2 | W1: 3 | X1: 4 | Y1: 5 | Z1: 6 | AA1: 7 | AB1: 8 | AC1: 9 | AD1: 10 | AE1: 11 | AF1: 12
A2: 46028 | B2: maracanace | C2: 0 | D2: 1 | E2: =IF(C2="","",IF(C2>D2,3,IF(C2=D2,1,0))) -> 0 | F2: =IF(C2="","",IF(C2>D2,1,0)) -> 0 | G2: =IF(C2="","",IF(C2=D2,1,0)) -> 0 | H2: =IF(C2="","",IF(C2<D2,1,0)) -> 1 | I2: =IF(D2=0,1,0) -> 0 | J2: ferroviarioce | K2: =C2 -> 0 | L2: =D2 -> 1 | M2: =IF(D2="","",IF(D2>C2,3,IF(D2=C2,1,0))) -> 3 | N2: =IF(D2="","",IF(D2>C2,1,0)) -> 1 | O2: =IF(D2="","",IF(D2=C2,1,0)) -> 0 | P2: =IF(D2="","",IF(D2<C2,1,0)) -> 0 | Q2: =IF(K2=0,1,0) -> 1 | R2: ce1 | S2: =C2 -> 0 | T2: =D2 -> 1 | U2: 1003
A3: 46028 | B3: saojoseensepr | C3: 2 | D3: 0 | E3: =IF(C3="","",IF(C3>D3,3,0)) -> 3 | F3: =IF(C3="","",IF(C3>D3,1,0)) -> 1 | G3: =IF(C3="","",IF(C3=D3,1,0)) -> 0 | H3: =IF(C3="","",IF(C3<D3,1,0)) -> 0 | I3: =IF(D3=0,1,0) -> 1 | J3: galomaringapr | K3: =C3 -> 2 | L3: =D3 -> 0 | M3: =IF(D3="","",IF(D3>C3,3,IF(D3=C3,1,0))) -> 0 | N3: =IF(D3="","",IF(D3>C3,1,0)) -> 0 | O3: =IF(D3="","",IF(D3=C3,1,0)) -> 0 | P3: =IF(D3="","",IF(D3<C3,1,0)) -> 1 | Q3: =IF(K3=0,1,0) -> 0 | R3: pr1 | S3: =C3 -> 2 | T3: =D3 -> 0 | U3: 1001 | V3: 1002
A4: 46028 | B4: chapecoensesc | C4: 1 | D4: 1 | E4: =IF(C4="","",IF(C4>D4,3,IF(C4=D4,1,0))) -> 1 | F4: =IF(C4="","",IF(C4>D4,1,0)) -> 0 | G4: =IF(C4="","",IF(C4=D4,1,0)) -> 1 | H4: =IF(C4="","",IF(C4<D4,1,0)) -> 0 | I4: =IF(D4=0,1,0) -> 0 | J4: brusquesc | K4: =C4 -> 1 | L4: =D4 -> 1 | M4: =IF(D4="","",IF(D4>C4,3,IF(D4=C4,1,0))) -> 1 | N4: =IF(D4="","",IF(D4>C4,1,0)) -> 0 | O4: =IF(D4="","",IF(D4=C4,1,0)) -> 1 | P4: =IF(D4="","",IF(D4<C4,1,0)) -> 0 | Q4: =IF(K4=0,1,0) -> 0 | R4: sc1 | S4: =C4 -> 1 | T4: =D4 -> 1 | U4: 1004 | V4: 1005
A5: 46028 | B5: santacatarinasc | C5: 2 | D5: 2 | E5: =IF(C5="","",IF(C5>D5,3,IF(C5=D5,1,0))) -> 1 | F5: =IF(C5="","",IF(C5>D5,1,0)) -> 0 | G5: =IF(C5="","",IF(C5=D5,1,0)) -> 1 | H5: =IF(C5="","",IF(C5<D5,1,0)) -> 0 | I5: =IF(D5=0,1,0) -> 0 | J5: camboriusc | K5: =C5 -> 2 | L5: =D5 -> 2 | M5: =IF(D5="","",IF(D5>C5,3,IF(D5=C5,1,0))) -> 1 | N5: =IF(D5="","",IF(D5>C5,1,0)) -> 0 | O5: =IF(D5="","",IF(D5=C5,1,0)) -> 1 | P5: =IF(D5="","",IF(D5<C5,1,0)) -> 0 | Q5: =IF(K5=0,1,0) -> 0 | R5: sc1 | S5: =C5 -> 2 | T5: =D5 -> 2 | U5: 1006 | V5: 1006 | W5: 1007 | X5: 1008
A6: 46029 | B6: tirolce | C6: 0 | D6: 2 | E6: =IF(C6="","",IF(C6>D6,3,IF(C6=D6,1,0))) -> 0 | F6: =IF(C6="","",IF(C6>D6,1,0)) -> 0 | G6: =IF(C6="","",IF(C6=D6,1,0)) -> 0 | H6: =IF(C6="","",IF(C6<D6,1,0)) -> 1 | I6: =IF(D6=0,1,0) -> 0 | J6: florestace | K6: =C6 -> 0 | L6: =D6 -> 2 | M6: =IF(D6="","",IF(D6>C6,3,IF(D6=C6,1,0))) -> 3 | N6: =IF(D6="","",IF(D6>C6,1,0)) -> 1 | O6: =IF(D6="","",IF(D6=C6,1,0)) -> 0 | P6: =IF(D6="","",IF(D6<C6,1,0)) -> 0 | Q6: =IF(K6=0,1,0) -> 1 | R6: ce1 | S6: =C6 -> 0 | T6: =D6 -> 2 | U6: 1022 | V6: 1023
A7: 46029 | B7: horizontece | C7: 0 | D7: 0 | E7: =IF(C7="","",IF(C7>D7,3,IF(C7=D7,1,0))) -> 1 | F7: =IF(C7="","",IF(C7>D7,1,0)) -> 0 | G7: =IF(C7="","",IF(C7=D7,1,0)) -> 1 | H7: =IF(C7="","",IF(C7<D7,1,0)) -> 0 | I7: =IF(D7=0,1,0) -> 1 | J7: quixadace | K7: =C7 -> 0 | L7: =D7 -> 0 | M7: =IF(D7="","",IF(D7>C7,3,IF(D7=C7,1,0))) -> 1 | N7: =IF(D7="","",IF(D7>C7,1,0)) -> 0 | O7: =IF(D7="","",IF(D7=C7,1,0)) -> 1 | P7: =IF(D7="","",IF(D7<C7,1,0)) -> 0 | Q7: =IF(K7=0,1,0) -> 1 | R7: ce1 | S7: =C7 -> 0 | T7: =D7 -> 0
A8: 46029 | B8: londrinapr | C8: 2 | D8: 0 | E8: =IF(C8="","",IF(C8>D8,3,IF(C8=D8,1,0))) -> 3 | F8: =IF(C8="","",IF(C8>D8,1,0)) -> 1 | G8: =IF(C8="","",IF(C8=D8,1,0)) -> 0 | H8: =IF(C8="","",IF(C8<D8,1,0)) -> 0 | I8: =IF(D8=0,1,0) -> 1 | J8: operariopr | K8: =C8 -> 2 | L8: =D8 -> 0 | M8: =IF(D8="","",IF(D8>C8,3,IF(D8=C8,1,0))) -> 0 | N8: =IF(D8="","",IF(D8>C8,1,0)) -> 0 | O8: =IF(D8="","",IF(D8=C8,1,0)) -> 0 | P8: =IF(D8="","",IF(D8<C8,1,0)) -> 1 | Q8: =IF(K8=0,1,0) -> 0 | R8: pr1 | S8: =C8 -> 2 | T8: =D8 -> 0 | U8: 1009 | V8: 1010
A9: 46029 | B9: cianortepr | C9: 3 | D9: 3 | E9: =IF(C9="","",IF(C9>D9,3,IF(C9=D9,1,0))) -> 1 | F9: =IF(C9="","",IF(C9>D9,1,0)) -> 0 | G9: =IF(C9="","",IF(C9=D9,1,0)) -> 1 | H9: =IF(C9="","",IF(C9<D9,1,0)) -> 0 | I9: =IF(D9=0,1,0) -> 0 | J9: maringapr | K9: =C9 -> 3 | L9: =D9 -> 3 | M9: =IF(D9="","",IF(D9>C9,3,IF(D9=C9,1,0))) -> 1 | N9: =IF(D9="","",IF(D9>C9,1,0)) -> 0 | O9: =IF(D9="","",IF(D9=C9,1,0)) -> 1 | P9: =IF(D9="","",IF(D9<C9,1,0)) -> 0 | Q9: =IF(K9=0,1,0) -> 0 | R9: pr1 | S9: =C9 -> 3 | T9: =D9 -> 3 | U9: 1011 | V9: 1012 | W9: 1013 | X9: 1014 | Y9: 1015 | Z9: 1016
A10: 46029 | B10: coritibapr | C10: 2 | D10: 3 | E10: =IF(C10="","",IF(C10>D10,3,IF(C10=D10,1,0))) -> 0 | F10: =IF(C10="","",IF(C10>D10,1,0)) -> 0 | G10: =IF(C10="","",IF(C10=D10,1,0)) -> 0 | H10: =IF(C10="","",IF(C10<D10,1,0)) -> 1 | I10: =IF(D10=0,1,0) -> 0 | J10: fozdoiguacupr | K10: =C10 -> 2 | L10: =D10 -> 3 | M10: =IF(D10="","",IF(D10>C10,3,IF(D10=C10,1,0))) -> 3 | N10: =IF(D10="","",IF(D10>C10,1,0)) -> 1 | O10: =IF(D10="","",IF(D10=C10,1,0)) -> 0 | P10: =IF(D10="","",IF(D10<C10,1,0)) -> 0 | Q10: =IF(K10=0,1,0) -> 0 | R10: pr1 | S10: =C10 -> 2 | T10: =D10 -> 3 | U10: 1017 | V10: 1018 | W10: 1019 | X10: 1020 | Y10: 1021
A11: 46029 | B11: marciliodiassc | C11: 2 | D11: 0 | E11: =IF(C11="","",IF(C11>D11,3,IF(C11=D11,1,0))) -> 3 | F11: =IF(C11="","",IF(C11>D11,1,0)) -> 1 | G11: =IF(C11="","",IF(C11=D11,1,0)) -> 0 | H11: =IF(C11="","",IF(C11<D11,1,0)) -> 0 | I11: =IF(D11=0,1,0) -> 1 | J11: criciumasc | K11: =C11 -> 2 | L11: =D11 -> 0 | M11: =IF(D11="","",IF(D11>C11,3,IF(D11=C11,1,0))) -> 0 | N11: =IF(D11="","",IF(D11>C11,1,0)) -> 0 | O11: =IF(D11="","",IF(D11=C11,1,0)) -> 0 | P11: =IF(D11="","",IF(D11<C11,1,0)) -> 1 | Q11: =IF(K11=0,1,0) -> 0 | R11: sc1 | S11: =C11 -> 2 | T11: =D11 -> 0 | U11: 1024 | V11: 1025
A12: 46029 | B12: joinvillesc | C12: 2 | D12: 3 | E12: =IF(C12="","",IF(C12>D12,3,IF(C12=D12,1,0))) -> 0 | F12: =IF(C12="","",IF(C12>D12,1,0)) -> 0 | G12: =IF(C12="","",IF(C12=D12,1,0)) -> 0 | H12: =IF(C12="","",IF(C12<D12,1,0)) -> 1 | I12: =IF(D12=0,1,0) -> 0 | J12: figueirensesc | K12: =C12 -> 2 | L12: =D12 -> 3 | M12: =IF(D12="","",IF(D12>C12,3,IF(D12=C12,1,0))) -> 3 | N12: =IF(D12="","",IF(D12>C12,1,0)) -> 1 | O12: =IF(D12="","",IF(D12=C12,1,0)) -> 0 | P12: =IF(D12="","",IF(D12<C12,1,0)) -> 0 | Q12: =IF(K12=0,1,0) -> 0 | R12: sc1 | S12: =C12 -> 2 | T12: =D12 -> 3 | U12: 1026 | V12: 1027 | W12: 1028 | X12: 1029 | Y12: 1030
A13: 46029 | B13: avaisc | C13: 2 | D13: 1 | E13: =IF(C13="","",IF(C13>D13,3,IF(C13=D13,1,0))) -> 3 | F13: =IF(C13="","",IF(C13>D13,1,0)) -> 1 | G13: =IF(C13="","",IF(C13=D13,1,0)) -> 0 | H13: =IF(C13="","",IF(C13<D13,1,0)) -> 0 | I13: =IF(D13=0,1,0) -> 0 | J13: barrasc | K13: =C13 -> 2 | L13: =D13 -> 1 | M13: =IF(D13="","",IF(D13>C13,3,IF(D13=C13,1,0))) -> 0 | N13: =IF(D13="","",IF(D13>C13,1,0)) -> 0 | O13: =IF(D13="","",IF(D13=C13,1,0)) -> 0 | P13: =IF(D13="","",IF(D13<C13,1,0)) -> 1 | Q13: =IF(K13=0,1,0) -> 0 | R13: sc1 | S13: =C13 -> 2 | T13: =D13 -> 1 | U13: 1031 | V13: 1032 | W13: 1033
A14: 46029 | B14: vitoriaes | C14: 5 | D14: 1 | E14: =IF(C14="","",IF(C14>D14,3,IF(C14=D14,1,0))) -> 3 | F14: =IF(C14="","",IF(C14>D14,1,0)) -> 1 | G14: =IF(C14="","",IF(C14=D14,1,0)) -> 0 | H14: =IF(C14="","",IF(C14<D14,1,0)) -> 0 | I14: =IF(D14=0,1,0) -> 0 | J14: riobrancoes | K14: =C14 -> 5 | L14: =D14 -> 1 | M14: =IF(D14="","",IF(D14>C14,3,IF(D14=C14,1,0))) -> 0 | N14: =IF(D14="","",IF(D14>C14,1,0)) -> 0 | O14: =IF(D14="","",IF(D14=C14,1,0)) -> 0 | P14: =IF(D14="","",IF(D14<C14,1,0)) -> 1 | Q14: =IF(K14=0,1,0) -> 0 | R14: sces | S14: =C14 -> 5 | T14: =D14 -> 1 | U14: 1034 | V14: 1034 | W14: 1035 | X14: 1036 | Y14: 1036 | Z14: 1037
A15: 46030 | B15: iguatuce | C15: 2 | D15: 0 | E15: =IF(C15="","",IF(C15>D15,3,IF(C15=D15,1,0))) -> 3 | F15: =IF(C15="","",IF(C15>D15,1,0)) -> 1 | G15: =IF(C15="","",IF(C15=D15,1,0)) -> 0 | H15: =IF(C15="","",IF(C15<D15,1,0)) -> 0 | I15: =IF(D15=0,1,0) -> 1 | J15: maranguapece | K15: =C15 -> 2 | L15: =D15 -> 0 | M15: =IF(D15="","",IF(D15>C15,3,IF(D15=C15,1,0))) -> 0 | N15: =IF(D15="","",IF(D15>C15,1,0)) -> 0 | O15: =IF(D15="","",IF(D15=C15,1,0)) -> 0 | P15: =IF(D15="","",IF(D15<C15,1,0)) -> 1 | Q15: =IF(K15=0,1,0) -> 0 | R15: ce1 | S15: =C15 -> 2 | T15: =D15 -> 0 | U15: 1041 | V15: 1042
A16: 46030 | B16: cascavelpr | C16: 0 | D16: 0 | E16: =IF(C16="","",IF(C16>D16,3,IF(C16=D16,1,0))) -> 1 | F16: =IF(C16="","",IF(C16>D16,1,0)) -> 0 | G16: =IF(C16="","",IF(C16=D16,1,0)) -> 1 | H16: =IF(C16="","",IF(C16<D16,1,0)) -> 0 | I16: =IF(D16=0,1,0) -> 1 | J16: azurizpr | K16: =C16 -> 0 | L16: =D16 -> 0 | M16: =IF(D16="","",IF(D16>C16,3,IF(D16=C16,1,0))) -> 1 | N16: =IF(D16="","",IF(D16>C16,1,0)) -> 0 | O16: =IF(D16="","",IF(D16=C16,1,0)) -> 1 | P16: =IF(D16="","",IF(D16<C16,1,0)) -> 0 | Q16: =IF(K16=0,1,0) -> 1 | R16: pr1 | S16: =C16 -> 0 | T16: =D16 -> 0
A17: 46030 | B17: andrauspr | C17: 1 | D17: 2 | E17: =IF(C17="","",IF(C17>D17,3,IF(C17=D17,1,0))) -> 0 | F17: =IF(C17="","",IF(C17>D17,1,0)) -> 0 | G17: =IF(C17="","",IF(C17=D17,1,0)) -> 0 | H17: =IF(C17="","",IF(C17<D17,1,0)) -> 1 | I17: =IF(D17=0,1,0) -> 0 | J17: athleticopr | K17: =C17 -> 1 | L17: =D17 -> 2 | M17: =IF(D17="","",IF(D17>C17,3,IF(D17=C17,1,0))) -> 3 | N17: =IF(D17="","",IF(D17>C17,1,0)) -> 1 | O17: =IF(D17="","",IF(D17=C17,1,0)) -> 0 | P17: =IF(D17="","",IF(D17<C17,1,0)) -> 0 | Q17: =IF(K17=0,1,0) -> 0 | R17: pr1 | S17: =C17 -> 1 | T17: =D17 -> 2 | U17: 1038 | V17: 1039 | W17: 1040
A18: 46030 | B18: carlosrenauxsc | C18: 0 | D18: 1 | E18: =IF(C18="","",IF(C18>D18,3,IF(C18=D18,1,0))) -> 0 | F18: =IF(C18="","",IF(C18>D18,1,0)) -> 0 | G18: =IF(C18="","",IF(C18=D18,1,0)) -> 0 | H18: =IF(C18="","",IF(C18<D18,1,0)) -> 1 | I18: =IF(D18=0,1,0) -> 0 | J18: concordiasc | K18: =C18 -> 0 | L18: =D18 -> 1 | M18: =IF(D18="","",IF(D18>C18,3,IF(D18=C18,1,0))) -> 3 | N18: =IF(D18="","",IF(D18>C18,1,0)) -> 1 | O18: =IF(D18="","",IF(D18=C18,1,0)) -> 0 | P18: =IF(D18="","",IF(D18<C18,1,0)) -> 0 | Q18: =IF(K18=0,1,0) -> 1 | R18: sc1 | S18: =C18 -> 0 | T18: =D18 -> 1 | U18: 1043
A19: 46031 | B19: retrope | C19: 4 | D19: 0 | E19: =IF(C19="","",IF(C19>D19,3,IF(C19=D19,1,0))) -> 3 | F19: =IF(C19="","",IF(C19>D19,1,0)) -> 1 | G19: =IF(C19="","",IF(C19=D19,1,0)) -> 0 | H19: =IF(C19="","",IF(C19<D19,1,0)) -> 0 | I19: =IF(D19=0,1,0) -> 1 | J19: vitoriape | K19: =C19 -> 4 | L19: =D19 -> 0 | M19: =IF(D19="","",IF(D19>C19,3,IF(D19=C19,1,0))) -> 0 | N19: =IF(D19="","",IF(D19>C19,1,0)) -> 0 | O19: =IF(D19="","",IF(D19=C19,1,0)) -> 0 | P19: =IF(D19="","",IF(D19<C19,1,0)) -> 1 | Q19: =IF(K19=0,1,0) -> 0 | R19: pe1 | S19: =C19 -> 4 | T19: =D19 -> 0 | U19: 1044 | V19: 1045 | W19: 1046 | X19: 1047
A20: 46031 | B20: nauticope | C20: 2 | D20: 0 | E20: =IF(C20="","",IF(C20>D20,3,IF(C20=D20,1,0))) -> 3 | F20: =IF(C20="","",IF(C20>D20,1,0)) -> 1 | G20: =IF(C20="","",IF(C20=D20,1,0)) -> 0 | H20: =IF(C20="","",IF(C20<D20,1,0)) -> 0 | I20: =IF(D20=0,1,0) -> 1 | J20: maguarype | K20: =C20 -> 2 | L20: =D20 -> 0 | M20: =IF(D20="","",IF(D20>C20,3,IF(D20=C20,1,0))) -> 0 | N20: =IF(D20="","",IF(D20>C20,1,0)) -> 0 | O20: =IF(D20="","",IF(D20=C20,1,0)) -> 0 | P20: =IF(D20="","",IF(D20<C20,1,0)) -> 1 | Q20: =IF(K20=0,1,0) -> 0 | R20: pe1 | S20: =C20 -> 2 | T20: =D20 -> 0 | U20: 1048 | V20: 1048
A21: 46031 | B21: osascosp | C21: 0 | D21: 0 | E21: =IF(C21="","",IF(C21>D21,3,IF(C21=D21,1,0))) -> 1 | F21: =IF(C21="","",IF(C21>D21,1,0)) -> 0 | G21: =IF(C21="","",IF(C21=D21,1,0)) -> 1 | H21: =IF(C21="","",IF(C21<D21,1,0)) -> 0 | I21: =IF(D21=0,1,0) -> 1 | J21: ferroviariasp | K21: =C21 -> 0 | L21: =D21 -> 0 | M21: =IF(D21="","",IF(D21>C21,3,IF(D21=C21,1,0))) -> 1 | N21: =IF(D21="","",IF(D21>C21,1,0)) -> 0 | O21: =IF(D21="","",IF(D21=C21,1,0)) -> 1 | P21: =IF(D21="","",IF(D21<C21,1,0)) -> 0 | Q21: =IF(K21=0,1,0) -> 1 | R21: sp2 | S21: =C21 -> 0 | T21: =D21 -> 0
A22: 46032 | B22: crbal | C22: 1 | D22: 0 | E22: =IF(C22="","",IF(C22>D22,3,IF(C22=D22,1,0))) -> 3 | F22: =IF(C22="","",IF(C22>D22,1,0)) -> 1 | G22: =IF(C22="","",IF(C22=D22,1,0)) -> 0 | H22: =IF(C22="","",IF(C22<D22,1,0)) -> 0 | I22: =IF(D22=0,1,0) -> 1 | J22: cseal | K22: =C22 -> 1 | L22: =D22 -> 0 | M22: =IF(D22="","",IF(D22>C22,3,IF(D22=C22,1,0))) -> 0 | N22: =IF(D22="","",IF(D22>C22,1,0)) -> 0 | O22: =IF(D22="","",IF(D22=C22,1,0)) -> 0 | P22: =IF(D22="","",IF(D22<C22,1,0)) -> 1 | Q22: =IF(K22=0,1,0) -> 0 | R22: al1 | S22: =C22 -> 1 | T22: =D22 -> 0 | U22: 1093
A23: 46032 | B23: penedenseal | C23: 1 | D23: 0 | E23: =IF(C23="","",IF(C23>D23,3,IF(C23=D23,1,0))) -> 3 | F23: =IF(C23="","",IF(C23>D23,1,0)) -> 1 | G23: =IF(C23="","",IF(C23=D23,1,0)) -> 0 | H23: =IF(C23="","",IF(C23<D23,1,0)) -> 0 | I23: =IF(D23=0,1,0) -> 1 | J23: cruzeiroal | K23: =C23 -> 1 | L23: =D23 -> 0 | M23: =IF(D23="","",IF(D23>C23,3,IF(D23=C23,1,0))) -> 0 | N23: =IF(D23="","",IF(D23>C23,1,0)) -> 0 | O23: =IF(D23="","",IF(D23=C23,1,0)) -> 0 | P23: =IF(D23="","",IF(D23<C23,1,0)) -> 1 | Q23: =IF(K23=0,1,0) -> 0 | R23: al1 | S23: =C23 -> 1 | T23: =D23 -> 0 | U23: 1094
A24: 46032 | B24: asaal | C24: 0 | D24: 0 | E24: =IF(C24="","",IF(C24>D24,3,IF(C24=D24,1,0))) -> 1 | F24: =IF(C24="","",IF(C24>D24,1,0)) -> 0 | G24: =IF(C24="","",IF(C24=D24,1,0)) -> 1 | H24: =IF(C24="","",IF(C24<D24,1,0)) -> 0 | I24: =IF(D24=0,1,0) -> 1 | J24: muricial | K24: =C24 -> 0 | L24: =D24 -> 0 | M24: =IF(D24="","",IF(D24>C24,3,IF(D24=C24,1,0))) -> 1 | N24: =IF(D24="","",IF(D24>C24,1,0)) -> 0 | O24: =IF(D24="","",IF(D24=C24,1,0)) -> 1 | P24: =IF(D24="","",IF(D24<C24,1,0)) -> 0 | Q24: =IF(K24=0,1,0) -> 1 | R24: al1 | S24: =C24 -> 0 | T24: =D24 -> 0
A25: 46032 | B25: amazonasam | C25: 3 | D25: 0 | E25: =IF(C25="","",IF(C25>D25,3,IF(C25=D25,1,0))) -> 3 | F25: =IF(C25="","",IF(C25>D25,1,0)) -> 1 | G25: =IF(C25="","",IF(C25=D25,1,0)) -> 0 | H25: =IF(C25="","",IF(C25<D25,1,0)) -> 0 | I25: =IF(D25=0,1,0) -> 1 | J25: saoraimundoam | K25: =C25 -> 3 | L25: =D25 -> 0 | M25: =IF(D25="","",IF(D25>C25,3,IF(D25=C25,1,0))) -> 0 | N25: =IF(D25="","",IF(D25>C25,1,0)) -> 0 | O25: =IF(D25="","",IF(D25=C25,1,0)) -> 0 | P25: =IF(D25="","",IF(D25<C25,1,0)) -> 1 | Q25: =IF(K25=0,1,0) -> 0 | R25: am1 | S25: =C25 -> 3 | T25: =D25 -> 0 | U25: 1107 | V25: 1108 | W25: 1109
A26: 46032 | B26: vitoriaba | C26: 0 | D26: 0 | E26: =IF(C26="","",IF(C26>D26,3,IF(C26=D26,1,0))) -> 1 | F26: =IF(C26="","",IF(C26>D26,1,0)) -> 0 | G26: =IF(C26="","",IF(C26=D26,1,0)) -> 1 | H26: =IF(C26="","",IF(C26<D26,1,0)) -> 0 | I26: =IF(D26=0,1,0) -> 1 | J26: atleticoba | K26: =C26 -> 0 | L26: =D26 -> 0 | M26: =IF(D26="","",IF(D26>C26,3,IF(D26=C26,1,0))) -> 1 | N26: =IF(D26="","",IF(D26>C26,1,0)) -> 0 | O26: =IF(D26="","",IF(D26=C26,1,0)) -> 1 | P26: =IF(D26="","",IF(D26<C26,1,0)) -> 0 | Q26: =IF(K26=0,1,0) -> 1 | R26: ba1 | S26: =C26 -> 0 | T26: =D26 -> 0
A27: 46032 | B27: portoba | C27: 3 | D27: 2 | E27: =IF(C27="","",IF(C27>D27,3,IF(C27=D27,1,0))) -> 3 | F27: =IF(C27="","",IF(C27>D27,1,0)) -> 1 | G27: =IF(C27="","",IF(C27=D27,1,0)) -> 0 | H27: =IF(C27="","",IF(C27<D27,1,0)) -> 0 | I27: =IF(D27=0,1,0) -> 0 | J27: jacuipenseba | K27: =C27 -> 3 | L27: =D27 -> 2 | M27: =IF(D27="","",IF(D27>C27,3,IF(D27=C27,1,0))) -> 0 | N27: =IF(D27="","",IF(D27>C27,1,0)) -> 0 | O27: =IF(D27="","",IF(D27=C27,1,0)) -> 0 | P27: =IF(D27="","",IF(D27<C27,1,0)) -> 1 | Q27: =IF(K27=0,1,0) -> 0 | R27: ba1 | S27: =C27 -> 3 | T27: =D27 -> 2 | U27: 1084 | V27: 1085 | W27: 1086 | X27: 1087 | Y27: 1088
A28: 46032 | B28: florestace | C28: 0 | D28: 1 | E28: =IF(C28="","",IF(C28>D28,3,IF(C28=D28,1,0))) -> 0 | F28: =IF(C28="","",IF(C28>D28,1,0)) -> 0 | G28: =IF(C28="","",IF(C28=D28,1,0)) -> 0 | H28: =IF(C28="","",IF(C28<D28,1,0)) -> 1 | I28: =IF(D28=0,1,0) -> 0 | J28: cearace | K28: =C28 -> 0 | L28: =D28 -> 1 | M28: =IF(D28="","",IF(D28>C28,3,IF(D28=C28,1,0))) -> 3 | N28: =IF(D28="","",IF(D28>C28,1,0)) -> 1 | O28: =IF(D28="","",IF(D28=C28,1,0)) -> 0 | P28: =IF(D28="","",IF(D28<C28,1,0)) -> 0 | Q28: =IF(K28=0,1,0) -> 1 | R28: ce1 | S28: =C28 -> 0 | T28: =D28 -> 1 | U28: 1075
A29: 46032 | B29: quixadace | C29: 1 | D29: 0 | E29: =IF(C29="","",IF(C29>D29,3,IF(C29=D29,1,0))) -> 3 | F29: =IF(C29="","",IF(C29>D29,1,0)) -> 1 | G29: =IF(C29="","",IF(C29=D29,1,0)) -> 0 | H29: =IF(C29="","",IF(C29<D29,1,0)) -> 0 | I29: =IF(D29=0,1,0) -> 1 | J29: maracanace | K29: =C29 -> 1 | L29: =D29 -> 0 | M29: =IF(D29="","",IF(D29>C29,3,IF(D29=C29,1,0))) -> 0 | N29: =IF(D29="","",IF(D29>C29,1,0)) -> 0 | O29: =IF(D29="","",IF(D29=C29,1,0)) -> 0 | P29: =IF(D29="","",IF(D29<C29,1,0)) -> 1 | Q29: =IF(K29=0,1,0) -> 0 | R29: ce1 | S29: =C29 -> 1 | T29: =D29 -> 0 | U29: 9999
A30: 46032 | B30: paranoadf | C30: 0 | D30: 1 | E30: =IF(C30="","",IF(C30>D30,3,IF(C30=D30,1,0))) -> 0 | F30: =IF(C30="","",IF(C30>D30,1,0)) -> 0 | G30: =IF(C30="","",IF(C30=D30,1,0)) -> 0 | H30: =IF(C30="","",IF(C30<D30,1,0)) -> 1 | I30: =IF(D30=0,1,0) -> 0 | J30: arucdf | K30: =C30 -> 0 | L30: =D30 -> 1 | M30: =IF(D30="","",IF(D30>C30,3,IF(D30=C30,1,0))) -> 3 | N30: =IF(D30="","",IF(D30>C30,1,0)) -> 1 | O30: =IF(D30="","",IF(D30=C30,1,0)) -> 0 | P30: =IF(D30="","",IF(D30<C30,1,0)) -> 0 | Q30: =IF(K30=0,1,0) -> 1 | R30: df1 | S30: =C30 -> 0 | T30: =D30 -> 1 | U30: 1121
A31: 46032 | B31: brasiiliensedf | C31: 4 | D31: 0 | E31: =IF(C31="","",IF(C31>D31,3,IF(C31=D31,1,0))) -> 3 | F31: =IF(C31="","",IF(C31>D31,1,0)) -> 1 | G31: =IF(C31="","",IF(C31=D31,1,0)) -> 0 | H31: =IF(C31="","",IF(C31<D31,1,0)) -> 0 | I31: =IF(D31=0,1,0) -> 1 | J31: brasiliadf | K31: =C31 -> 4 | L31: =D31 -> 0 | M31: =IF(D31="","",IF(D31>C31,3,IF(D31=C31,1,0))) -> 0 | N31: =IF(D31="","",IF(D31>C31,1,0)) -> 0 | O31: =IF(D31="","",IF(D31=C31,1,0)) -> 0 | P31: =IF(D31="","",IF(D31<C31,1,0)) -> 1 | Q31: =IF(K31=0,1,0) -> 0 | R31: df1 | S31: =C31 -> 4 | T31: =D31 -> 0 | U31: 1122 | V31: 1123 | W31: 1124 | X31: 1125
A32: 46032 | B32: ceilandiadf | C32: 1 | D32: 1 | E32: =IF(C32="","",IF(C32>D32,3,IF(C32=D32,1,0))) -> 1 | F32: =IF(C32="","",IF(C32>D32,1,0)) -> 0 | G32: =IF(C32="","",IF(C32=D32,1,0)) -> 1 | H32: =IF(C32="","",IF(C32<D32,1,0)) -> 0 | I32: =IF(D32=0,1,0) -> 0 | J32: sobradinhodf | K32: =C32 -> 1 | L32: =D32 -> 1 | M32: =IF(D32="","",IF(D32>C32,3,IF(D32=C32,1,0))) -> 1 | N32: =IF(D32="","",IF(D32>C32,1,0)) -> 0 | O32: =IF(D32="","",IF(D32=C32,1,0)) -> 1 | P32: =IF(D32="","",IF(D32<C32,1,0)) -> 0 | Q32: =IF(K32=0,1,0) -> 0 | R32: df1 | S32: =C32 -> 1 | T32: =D32 -> 1 | U32: 1126 | V32: 1127
A33: 46032 | B33: gamadf | C33: 1 | D33: 0 | E33: =IF(C33="","",IF(C33>D33,3,IF(C33=D33,1,0))) -> 3 | F33: =IF(C33="","",IF(C33>D33,1,0)) -> 1 | G33: =IF(C33="","",IF(C33=D33,1,0)) -> 0 | H33: =IF(C33="","",IF(C33<D33,1,0)) -> 0 | I33: =IF(D33=0,1,0) -> 1 | J33: realbrasiliadf | K33: =C33 -> 1 | L33: =D33 -> 0 | M33: =IF(D33="","",IF(D33>C33,3,IF(D33=C33,1,0))) -> 0 | N33: =IF(D33="","",IF(D33>C33,1,0)) -> 0 | O33: =IF(D33="","",IF(D33=C33,1,0)) -> 0 | P33: =IF(D33="","",IF(D33<C33,1,0)) -> 1 | Q33: =IF(K33=0,1,0) -> 0 | R33: df1 | S33: =C33 -> 1 | T33: =D33 -> 0 | U33: 1128
A34: 46032 | B34: jataiensego | C34: 1 | D34: 1 | E34: =IF(C34="","",IF(C34>D34,3,IF(C34=D34,1,0))) -> 1 | F34: =IF(C34="","",IF(C34>D34,1,0)) -> 0 | G34: =IF(C34="","",IF(C34=D34,1,0)) -> 1 | H34: =IF(C34="","",IF(C34<D34,1,0)) -> 0 | I34: =IF(D34=0,1,0) -> 0 | J34: cracgo | K34: =C34 -> 1 | L34: =D34 -> 1 | M34: =IF(D34="","",IF(D34>C34,3,IF(D34=C34,1,0))) -> 1 | N34: =IF(D34="","",IF(D34>C34,1,0)) -> 0 | O34: =IF(D34="","",IF(D34=C34,1,0)) -> 1 | P34: =IF(D34="","",IF(D34<C34,1,0)) -> 0 | Q34: =IF(K34=0,1,0) -> 0 | R34: go1 | S34: =C34 -> 1 | T34: =D34 -> 1 | U34: 1076 | V34: 1077
A35: 46032 | B35: atleticogo | C35: 2 | D35: 0 | E35: =IF(C35="","",IF(C35>D35,3,IF(C35=D35,1,0))) -> 3 | F35: =IF(C35="","",IF(C35>D35,1,0)) -> 1 | G35: =IF(C35="","",IF(C35=D35,1,0)) -> 0 | H35: =IF(C35="","",IF(C35<D35,1,0)) -> 0 | I35: =IF(D35=0,1,0) -> 1 | J35: anapolisgo | K35: =C35 -> 2 | L35: =D35 -> 0 | M35: =IF(D35="","",IF(D35>C35,3,IF(D35=C35,1,0))) -> 0 | N35: =IF(D35="","",IF(D35>C35,1,0)) -> 0 | O35: =IF(D35="","",IF(D35=C35,1,0)) -> 0 | P35: =IF(D35="","",IF(D35<C35,1,0)) -> 1 | Q35: =IF(K35=0,1,0) -> 0 | R35: go1 | S35: =C35 -> 2 | T35: =D35 -> 0 | U35: 1078 | V35: 1079 | W35: 1080
A36: 46032 | B36: abecatgo | C36: 1 | D36: 2 | E36: =IF(C36="","",IF(C36>D36,3,IF(C36=D36,1,0))) -> 0 | F36: =IF(C36="","",IF(C36>D36,1,0)) -> 0 | G36: =IF(C36="","",IF(C36=D36,1,0)) -> 0 | H36: =IF(C36="","",IF(C36<D36,1,0)) -> 1 | I36: =IF(D36=0,1,0) -> 0 | J36: vilanovago | K36: =C36 -> 1 | L36: =D36 -> 2 | M36: =IF(D36="","",IF(D36>C36,3,IF(D36=C36,1,0))) -> 3 | N36: =IF(D36="","",IF(D36>C36,1,0)) -> 1 | O36: =IF(D36="","",IF(D36=C36,1,0)) -> 0 | P36: =IF(D36="","",IF(D36<C36,1,0)) -> 0 | Q36: =IF(K36=0,1,0) -> 0 | R36: go1 | S36: =C36 -> 1 | T36: =D36 -> 2 | U36: 1081 | V36: 1082
A37: 46032 | B37: imperatrizma | C37: 1 | D37: 1 | E37: =IF(C37="","",IF(C37>D37,3,IF(C37=D37,1,0))) -> 1 | F37: =IF(C37="","",IF(C37>D37,1,0)) -> 0 | G37: =IF(C37="","",IF(C37=D37,1,0)) -> 1 | H37: =IF(C37="","",IF(C37<D37,1,0)) -> 0 | I37: =IF(D37=0,1,0) -> 0 | J37: sampaiocorreama | K37: =C37 -> 1 | L37: =D37 -> 1 | M37: =IF(D37="","",IF(D37>C37,3,IF(D37=C37,1,0))) -> 1 | N37: =IF(D37="","",IF(D37>C37,1,0)) -> 0 | O37: =IF(D37="","",IF(D37=C37,1,0)) -> 1 | P37: =IF(D37="","",IF(D37<C37,1,0)) -> 0 | Q37: =IF(K37=0,1,0) -> 0 | R37: ma1 | S37: =C37 -> 1 | T37: =D37 -> 1 | U37: 1105 | V37: 1106
A38: 46032 | B38: uberlandiamg | C38: 0 | D38: 0 | E38: =IF(C38="","",IF(C38>D38,3,IF(C38=D38,1,0))) -> 1 | F38: =IF(C38="","",IF(C38>D38,1,0)) -> 0 | G38: =IF(C38="","",IF(C38=D38,1,0)) -> 1 | H38: =IF(C38="","",IF(C38<D38,1,0)) -> 0 | I38: =IF(D38=0,1,0) -> 1 | J38: tombensemg | K38: =C38 -> 0 | L38: =D38 -> 0 | M38: =IF(D38="","",IF(D38>C38,3,IF(D38=C38,1,0))) -> 1 | N38: =IF(D38="","",IF(D38>C38,1,0)) -> 0 | O38: =IF(D38="","",IF(D38=C38,1,0)) -> 1 | P38: =IF(D38="","",IF(D38<C38,1,0)) -> 0 | Q38: =IF(K38=0,1,0) -> 1 | R38: mg1 | S38: =C38 -> 0 | T38: =D38 -> 0
A39: 46032 | B39: cruzeiromg | C39: 1 | D39: 2 | E39: =IF(C39="","",IF(C39>D39,3,IF(C39=D39,1,0))) -> 0 | F39: =IF(C39="","",IF(C39>D39,1,0)) -> 0 | G39: =IF(C39="","",IF(C39=D39,1,0)) -> 0 | H39: =IF(C39="","",IF(C39<D39,1,0)) -> 1 | I39: =IF(D39=0,1,0) -> 0 | J39: pousoalegremg | K39: =C39 -> 1 | L39: =D39 -> 2 | M39: =IF(D39="","",IF(D39>C39,3,IF(D39=C39,1,0))) -> 3 | N39: =IF(D39="","",IF(D39>C39,1,0)) -> 1 | O39: =IF(D39="","",IF(D39=C39,1,0)) -> 0 | P39: =IF(D39="","",IF(D39<C39,1,0)) -> 0 | Q39: =IF(K39=0,1,0) -> 0 | R39: mg1 | S39: =C39 -> 1 | T39: =D39 -> 2 | U39: 1066 | V39: 1067 | W39: 1068
A40: 46032 | B40: itabiritomg | C40: 0 | D40: 1 | E40: =IF(C40="","",IF(C40>D40,3,IF(C40=D40,1,0))) -> 0 | F40: =IF(C40="","",IF(C40>D40,1,0)) -> 0 | G40: =IF(C40="","",IF(C40=D40,1,0)) -> 0 | H40: =IF(C40="","",IF(C40<D40,1,0)) -> 1 | I40: =IF(D40=0,1,0) -> 0 | J40: democratagvmg | K40: =C40 -> 0 | L40: =D40 -> 1 | M40: =IF(D40="","",IF(D40>C40,3,IF(D40=C40,1,0))) -> 3 | N40: =IF(D40="","",IF(D40>C40,1,0)) -> 1 | O40: =IF(D40="","",IF(D40=C40,1,0)) -> 0 | P40: =IF(D40="","",IF(D40<C40,1,0)) -> 0 | Q40: =IF(K40=0,1,0) -> 1 | R40: mg1 | S40: =C40 -> 0 | T40: =D40 -> 1 | U40: 1069
...

Sheet ART
A1: POS | B1: COD | C1: JOGADOR | D1: CLUBE | E1: NOME_COMPLETO | F1: NASCIMENTO | G1: NACIONALIDADE | H1: GOLS | I1: JOGOS | J1: OBSERVAÇÕES
A2: 1 | B2: 1837 | C2: Alex Choco | D2: operarioms | E2: Alex Honorio Junior | F2: 37084 | G2: brasil | H2: =COUNTIF(CAL!U:AF,B2) -> 16 | I2: 16 | J2: 15 bataguassums
A3: 2 | B3: 1304 | C3: Alex Bruno | D3: asaal | E3: Alex Bruno da Costa Lima | F3: 36167 | G3: brasil | H3: =COUNTIF(CAL!U:AF,B3) -> 13 | I3: 17
A4: 3 | B4: 1829 | C4: Vanilson | D4: gasrr | E4: Vanilson de Lima Silva | F4: 33111 | G4: brasil | H4: =COUNTIF(CAL!U:AF,B4) -> 12 | I4: 14
A5: 4 | B5: 1418 | C5: Carlos Vinicius | D5: gremiors | E5: Carlos Vinicius Alves Morais | F5: 34783 | G5: brasil | H5: =COUNTIF(CAL!U:AF,B5) -> 12 | I5: 21
A6: 5 | B6: 1623 | C6: Calleri | D6: saopaulosp | E6: Jonathan Calleri | F6: 34235 | G6: argentina | H6: =COUNTIF(CAL!U:AF,B6) -> 11 | I6: 19
A7: 6 | B7: 1733 | C7: Anselmo Ramon | D7: goiasgo | E7: Anselmo Ramon Alves Herculano | F7: 32317 | G7: brasil | H7: =COUNTIF(CAL!U:AF,B7) -> 11 | I7: 20
A8: 7 | B8: 1128 | C8: Felipe Clemente | D8: gamadf | E8: Luiz Felipe Clemente de Almeida | F8: 36328 | G8: brasil | H8: =COUNTIF(CAL!U:AF,B8) -> 10 | I8: 15
A9: 8 | B9: 1382 | C9: Mikael | D9: crbal | E9: Mikael Filipe Viana de Sousa | F9: 36308 | G9: brasil | H9: =COUNTIF(CAL!U:AF,B9) -> 10 | I9: 18
A10: 9 | B10: 1695 | C10: Mano | D10: guaporero | E10: Antonio Luis dos Santos | F10: 32312 | G10: brasil | H10: =COUNTIF(CAL!U:AF,B10) -> 10 | I10: 22
A11: 10 | B11: 1639 | C11: Ronaldo Tavares | D11: athleticmg | E11: Ronaldo Rodrigues Tavares | F11: 35633 | G11: portugal | H11: =COUNTIF(CAL!U:AF,B11) -> 9 | I11: 12
A12: 11 | B12: 1421 | C12: Kaio Jorge | D12: cruzeiromg | E12: Kaio Jorge Pinto Ramos | F12: 37280 | G12: brasil | H12: =COUNTIF(CAL!U:AF,B12) -> 9 | I12: 13
A13: 12 | B13: 1851 | C13: Lucas Lima | D13: mariliasp | E13: Lucas de Lima Maximo | F13: 35439 | G13: brasil | H13: =COUNTIF(CAL!U:AF,B13) -> 9 | I13: 13
A14: 13 | B14: 1249 | C14: Gabriel Taliari | D14: remopa | E14: Gabriel Pereira Taliari | F14: 35533 | G14: brasil | H14: =COUNTIF(CAL!U:AF,B14) -> 9 | I14: 16 | J14: 6 juventuders
A15: 14 | B15: 1079 | C15: Dellatorre | D15: vilanovago | E15: Guilherme Augusto Alves Dellatorre | F15: 33725 | G15: brasil | H15: =COUNTIF(CAL!U:AF,B15) -> 9 | I15: 17
A16: 15 | B16: 2217 | C16: Juan Palacios | D16: nacionalpr | E16: Juan Diego Palacios Ricardo | F16: 35767 | G16: colombia | H16: =COUNTIF(CAL!U:AF,B16) -> 9 | I16: 17 | J16: 8 jiparanaro
A17: 16 | B17: 1268 | C17: Bruno Santos | D17: londrinapr | E17: Bruno Santos de Oliveira | F17: 35387 | G17: brasil | H17: =COUNTIF(CAL!U:AF,B17) -> 9 | I17: 18
A18: 17 | B18: 1345 | C18: Luketa | D18: sertaozinhosp | E18: Lucas Henrique Luciano | F18: 36225 | G18: brasil | H18: =COUNTIF(CAL!U:AF,B18) -> 9 | I18: 18
A19: 18 | B19: 2373 | C19: Pedro | D19: flamengorj | E19: Pedro Guilherme Abreu dos Santos | F19: 35601 | G19: brasil | H19: =COUNTIF(CAL!U:AF,B19) -> 9 | I19: 18
A20: 19 | B20: 1411 | C20: Flaco Lopez | D20: palmeirassp | E20: Jose Manuel Alberto Lopez | F20: 36866 | G20: argentina | H20: =COUNTIF(CAL!U:AF,B20) -> 9 | I20: 20
A21: 20 | B21: 1048 | C21: Paulo Sérgio | D21: nauticope | E21: Paulo Sergio Luiz de Souza | F21: 32670 | G21: brasil | H21: =COUNTIF(CAL!U:AF,B21) -> 8 | I21: 10
A22: 21 | B22: 1909 | C22: Italo | D22: paysandupa | E22: Italo de Carvalho Rocha Lima | F22: 35376 | G22: brasil | H22: =COUNTIF(CAL!U:AF,B22) -> 8 | I22: 13
A23: 22 | B23: 1339 | C23: Macario | D23: brusquesc | E23: Matheus Moraes Macario de Souza | F23: 36967 | G23: brasil | H23: =COUNTIF(CAL!U:AF,B23) -> 8 | I23: 14 | J23: 8 taubatesp
A24: 23 | B24: 2005 | C24: Wanderson Gotinha | D24: tremap | E24: Wanderson Pinheiro Diniz | F24: 35304 | G24: brasil | H24: =COUNTIF(CAL!U:AF,B24) -> 8 | I24: 14 | J24: 2 motoclubma
A25: 24 | B25: 1036 | C25: Gustavo Tonoli | D25: vitoriaes | E25: Gustavo Rodrigues Tonoli | F25: 35690 | G25: brasil | H25: =COUNTIF(CAL!U:AF,B25) -> 8 | I25: 15
A26: 25 | B26: 1341 | C26: Juninho | D26: paysandupa | E26: José Romualdo Pedro Junior | F26: 38153 | G26: brasil | H26: =COUNTIF(CAL!U:AF,B26) -> 8 | I26: 15 | J26: 7 osascosp
A27: 26 | B27: 1182 | C27: Robson | D27: novorizontinosp | E27: Robson dos Santos Fernandes | F27: 33388 | G27: brasil | H27: =COUNTIF(CAL!U:AF,B27) -> 8 | I27: 17
A28: 27 | B28: 1982 | C28: Rafael Carioca | D28: saoraimundorr | E28: Rafael William Ribeiro Mendonça | F28: 36071 | G28: brasil | H28: =COUNTIF(CAL!U:AF,B28) -> 7 | I28: 8
A29: 28 | B29: 1171 | C29: Tiago Recife | D29: jequieba | E29: Tiago Souza de Lima | F29: 33656 | G29: brasil | H29: =COUNTIF(CAL!U:AF,B29) -> 7 | I29: 9
A30: 29 | B30: 1019 | C30: Lucas Alves | D30: figueirensesc | E30: Lucas Alves | F30: 37367 | G30: brasil | H30: =COUNTIF(CAL!U:AF,B30) -> 7 | I30: 11 | J30: 5 fozdoiguacupr
A31: 30 | B31: 2434 | C31: Vitor Xavier | D31: samambaiadf | E31: Vitor Xavier de Campos Humeni | F31: 34420 | G31: brasil | H31: =COUNTIF(CAL!U:AF,B31) -> 7 | I31: 11
A32: 31 | B32: 1014 | C32: Edison Negueba | D32: maringapr | E32: Edson Gustódio dos Santos | F32: 36823 | G32: brasil | H32: =COUNTIF(CAL!U:AF,B32) -> 7 | I32: 12
A33: 32 | B33: 2119 | C33: Everton Heleno | D33: sousapb | E33: Everton Heleno dos Santos | F33: 33202 | G33: brasil | H33: =COUNTIF(CAL!U:AF,B33) -> 7 | I33: 13 | J33: 5 campinensepb
A34: 33 | B34: 1052 | C34: Gabriel Barbosa | D34: santossp | E34: Gabriel Barbosa Almeida | F34: 35307 | G34: brasil | H34: =COUNTIF(CAL!U:AF,B34) -> 7 | I34: 13
A35: 34 | B35: 2736 | C35: Kaua Giancler | D35: taquaritingasp | E35: Kaua Giancler Machado da Silva | F35: 38051 | G35: brasil | H35: =COUNTIF(CAL!U:AF,B35) -> 7 | I35: 13
A36: 35 | B36: 2234 | C36: Matheus Lagoa | D36: anapolisgo | E36: Matheus Vinicius da Silva | F36: 35137 | G36: brasil | H36: =COUNTIF(CAL!U:AF,B36) -> 7 | I36: 13
A37: 36 | B37: 1317 | C37: Paulinho | D37: americarn | E37: Paulo Cesar de Oliveira | F37: 33805 | G37: brasil | H37: =COUNTIF(CAL!U:AF,B37) -> 7 | I37: 13 | J37: 7 qfcrn
A38: 37 | B38: 1408 | C38: Rene | D38: portuguesasp | E38: Carlos Rene de Sousa Ferreira | F38: 37901 | G38: brasil | H38: =COUNTIF(CAL!U:AF,B38) -> 7 | I38: 13
A39: 38 | B39: 1357 | C39: Carlão | D39: novorizontinosp | E39: Carlos Henrique de Moura Brito | F39: 33788 | G39: brasil | H39: =COUNTIF(CAL!U:AF,B39) -> 7 | I39: 14 | J39: 4 noroestesp
A40: 39 | B40: 2055 | C40: Daniel Cruz | D40: uniaobarbarensesp | E40: Daniel Paulo da Cruz | F40: 33027 | G40: brasil | H40: =COUNTIF(CAL!U:AF,B40) -> 7 | I40: 14
...

Sheet CLA
B1: EQUIPE | C1: TIME | D1: PTS | E1: J | F1: V | G1: E | H1: D | I1: APROVEITAMENTO | J1: GOL | K1: GL | L1: SALDO | M1: MG | N1: MD | O1: CL_SH | P1: INV | Q1: VIT | R1: EMP | S1: DIVISÃO NACIONAL | T1: CIDADE | U1: UF
A2: 1 | B2: gamadf | C2: Gama-DF | D2: =SUMIF(CAL!B:E,B2,CAL!E:E)+SUMIF(CAL!J:M,B2,CAL!M:M) -> 44 | E2: =COUNTIF(CAL!B:J,B2) -> 18 | F2: =SUMIF(CAL!B:F,B2,CAL!F:F)+SUMIF(CAL!J:N,B2,CAL!N:N) -> 13 | G2: =SUMIF(CAL!B:F,B2,CAL!G:G)+SUMIF(CAL!J:N,B2,CAL!O:O) -> 5 | H2: =SUMIF(CAL!B:F,B2,CAL!H:H)+SUMIF(CAL!J:N,B2,CAL!P:P) -> 0 | I2: =IF(E2=0,0,(D2/(E2*3))) -> 0.81481481 | J2: =SUMIF(CAL!B:C,B2,CAL!C:C)+SUMIF(CAL!J:J,B2,CAL!D:D) -> 28 | K2: =SUMIF(CAL!B:D,B2,CAL!D:D)+SUMIF(CAL!J:L,B2,CAL!K:K) -> 9 | L2: =J2-K2 -> 19 | M2: =IF(E2=0,0,(J2/E2)) -> 1.5555556 | N2: =IF(E2=0,0,(K2/E2)) -> 0.5 | O2: =SUMIF(CAL!B:I,B2,CAL!I:I)+SUMIF(CAL!J:Q,B2,CAL!Q:Q) -> 10 | P2: =Q2+R2 -> 22 | Q2: 14 | R2: 8 | S2: D | T2: Parnahyba | U2: PI
A3: 2 | B3: goiasgo | C3: Goiás-GO | D3: =SUMIF(CAL!B:E,B3,CAL!E:E)+SUMIF(CAL!J:M,B3,CAL!M:M) -> 44 | E3: =COUNTIF(CAL!B:J,B3) -> 20 | F3: =SUMIF(CAL!B:F,B3,CAL!F:F)+SUMIF(CAL!J:N,B3,CAL!N:N) -> 12 | G3: =SUMIF(CAL!B:F,B3,CAL!G:G)+SUMIF(CAL!J:N,B3,CAL!O:O) -> 8 | H3: =SUMIF(CAL!B:F,B3,CAL!H:H)+SUMIF(CAL!J:N,B3,CAL!P:P) -> 0 | I3: =IF(E3=0,0,(D3/(E3*3))) -> 0.73333333 | J3: =SUMIF(CAL!B:C,B3,CAL!C:C)+SUMIF(CAL!J:J,B3,CAL!D:D) -> 36 | K3: =SUMIF(CAL!B:D,B3,CAL!D:D)+SUMIF(CAL!J:L,B3,CAL!K:K) -> 11 | L3: =J3-K3 -> 25 | M3: =IF(E3=0,0,(J3/E3)) -> 1.8 | N3: =IF(E3=0,0,(K3/E3)) -> 0.55 | O3: =SUMIF(CAL!B:I,B3,CAL!I:I)+SUMIF(CAL!J:Q,B3,CAL!Q:Q) -> 12 | P3: =Q3+R3 -> 20 | Q3: 12 | R3: 8 | S3: D | T3: Natal | U3: RN
A4: 3 | B4: operariopr | C4: Operário-PR | D4: =SUMIF(CAL!B:E,B4,CAL!E:E)+SUMIF(CAL!J:M,B4,CAL!M:M) -> 36 | E4: =COUNTIF(CAL!B:J,B4) -> 21 | F4: =SUMIF(CAL!B:F,B4,CAL!F:F)+SUMIF(CAL!J:N,B4,CAL!N:N) -> 9 | G4: =SUMIF(CAL!B:F,B4,CAL!G:G)+SUMIF(CAL!J:N,B4,CAL!O:O) -> 9 | H4: =SUMIF(CAL!B:F,B4,CAL!H:H)+SUMIF(CAL!J:N,B4,CAL!P:P) -> 3 | I4: =IF(E4=0,0,(D4/(E4*3))) -> 0.57142857 | J4: =SUMIF(CAL!B:C,B4,CAL!C:C)+SUMIF(CAL!J:J,B4,CAL!D:D) -> 21 | K4: =SUMIF(CAL!B:D,B4,CAL!D:D)+SUMIF(CAL!J:L,B4,CAL!K:K) -> 13 | L4: =J4-K4 -> 8 | M4: =IF(E4=0,0,(J4/E4)) -> 1 | N4: =IF(E4=0,0,(K4/E4)) -> 0.61904762 | O4: =SUMIF(CAL!B:I,B4,CAL!I:I)+SUMIF(CAL!J:Q,B4,CAL!Q:Q) -> 12 | P4: =Q4+R4 -> 17 | Q4: 9 | R4: 8 | S4: D | T4: Rio de Janeiro | U4: RJ
A5: 4 | B5: nacionalam | C5: Nacional-AM | D5: =SUMIF(CAL!B:E,B5,CAL!E:E)+SUMIF(CAL!J:M,B5,CAL!M:M) -> 38 | E5: =COUNTIF(CAL!B:J,B5) -> 18 | F5: =SUMIF(CAL!B:F,B5,CAL!F:F)+SUMIF(CAL!J:N,B5,CAL!N:N) -> 11 | G5: =SUMIF(CAL!B:F,B5,CAL!G:G)+SUMIF(CAL!J:N,B5,CAL!O:O) -> 5 | H5: =SUMIF(CAL!B:F,B5,CAL!H:H)+SUMIF(CAL!J:N,B5,CAL!P:P) -> 2 | I5: =IF(E5=0,0,(D5/(E5*3))) -> 0.7037037 | J5: =SUMIF(CAL!B:C,B5,CAL!C:C)+SUMIF(CAL!J:J,B5,CAL!D:D) -> 30 | K5: =SUMIF(CAL!B:D,B5,CAL!D:D)+SUMIF(CAL!J:L,B5,CAL!K:K) -> 11 | L5: =J5-K5 -> 19 | M5: =IF(E5=0,0,(J5/E5)) -> 1.6666667 | N5: =IF(E5=0,0,(K5/E5)) -> 0.61111111 | O5: =SUMIF(CAL!B:I,B5,CAL!I:I)+SUMIF(CAL!J:Q,B5,CAL!Q:Q) -> 11 | P5: =Q5+R5 -> 9 | Q5: 7 | R5: 2 | S5: D | T5: Serra Branca | U5: PB
A6: 5 | B6: Manausam | C6: Manaus-AM | D6: =SUMIF(CAL!B:E,B6,CAL!E:E)+SUMIF(CAL!J:M,B6,CAL!M:M) -> 22 | E6: =COUNTIF(CAL!B:J,B6) -> 12 | F6: =SUMIF(CAL!B:F,B6,CAL!F:F)+SUMIF(CAL!J:N,B6,CAL!N:N) -> 6 | G6: =SUMIF(CAL!B:F,B6,CAL!G:G)+SUMIF(CAL!J:N,B6,CAL!O:O) -> 4 | H6: =SUMIF(CAL!B:F,B6,CAL!H:H)+SUMIF(CAL!J:N,B6,CAL!P:P) -> 2 | I6: =IF(E6=0,0,(D6/(E6*3))) -> 0.61111111 | J6: =SUMIF(CAL!B:C,B6,CAL!C:C)+SUMIF(CAL!J:J,B6,CAL!D:D) -> 13 | K6: =SUMIF(CAL!B:D,B6,CAL!D:D)+SUMIF(CAL!J:L,B6,CAL!K:K) -> 6 | L6: =J6-K6 -> 7 | M6: =IF(E6=0,0,(J6/E6)) -> 1.0833333 | N6: =IF(E6=0,0,(K6/E6)) -> 0.5 | O6: =SUMIF(CAL!B:I,B6,CAL!I:I)+SUMIF(CAL!J:Q,B6,CAL!Q:Q) -> 7 | P6: =Q6+R6 -> 8 | Q6: 4 | R6: 4 | S6: D | T6: Sertania | U6: PE
A7: 6 | B7: athleticmg | C7: Athletic-MG | D7: =SUMIF(CAL!B:E,B7,CAL!E:E)+SUMIF(CAL!J:M,B7,CAL!M:M) -> 19 | E7: =COUNTIF(CAL!B:J,B7) -> 14 | F7: =SUMIF(CAL!B:F,B7,CAL!F:F)+SUMIF(CAL!J:N,B7,CAL!N:N) -> 4 | G7: =SUMIF(CAL!B:F,B7,CAL!G:G)+SUMIF(CAL!J:N,B7,CAL!O:O) -> 7 | H7: =SUMIF(CAL!B:F,B7,CAL!H:H)+SUMIF(CAL!J:N,B7,CAL!P:P) -> 3 | I7: =IF(E7=0,0,(D7/(E7*3))) -> 0.45238095 | J7: =SUMIF(CAL!B:C,B7,CAL!C:C)+SUMIF(CAL!J:J,B7,CAL!D:D) -> 17 | K7: =SUMIF(CAL!B:D,B7,CAL!D:D)+SUMIF(CAL!J:L,B7,CAL!K:K) -> 18 | L7: =J7-K7 -> -1 | M7: =IF(E7=0,0,(J7/E7)) -> 1.2142857 | N7: =IF(E7=0,0,(K7/E7)) -> 1.2857143 | O7: =SUMIF(CAL!B:I,B7,CAL!I:I)+SUMIF(CAL!J:Q,B7,CAL!Q:Q) -> 2 | P7: =Q7+R7 -> 8 | Q7: 3 | R7: 5 | S7: D | T7: Aracaju | U7: SE
A8: 7 | B8: operariomt | C8: CEOV Operário-MT | D8: =SUMIF(CAL!B:E,B8,CAL!E:E)+SUMIF(CAL!J:M,B8,CAL!M:M) -> 21 | E8: =COUNTIF(CAL!B:J,B8) -> 14 | F8: =SUMIF(CAL!B:F,B8,CAL!F:F)+SUMIF(CAL!J:N,B8,CAL!N:N) -> 5 | G8: =SUMIF(CAL!B:F,B8,CAL!G:G)+SUMIF(CAL!J:N,B8,CAL!O:O) -> 6 | H8: =SUMIF(CAL!B:F,B8,CAL!H:H)+SUMIF(CAL!J:N,B8,CAL!P:P) -> 3 | I8: =IF(E8=0,0,(D8/(E8*3))) -> 0.5 | J8: =SUMIF(CAL!B:C,B8,CAL!C:C)+SUMIF(CAL!J:J,B8,CAL!D:D) -> 17 | K8: =SUMIF(CAL!B:D,B8,CAL!D:D)+SUMIF(CAL!J:L,B8,CAL!K:K) -> 16 | L8: =J8-K8 -> 1 | M8: =IF(E8=0,0,(J8/E8)) -> 1.2142857 | N8: =IF(E8=0,0,(K8/E8)) -> 1.1428571 | O8: =SUMIF(CAL!B:I,B8,CAL!I:I)+SUMIF(CAL!J:Q,B8,CAL!Q:Q) -> 4 | P8: =Q8+R8 -> 8 | Q8: 2 | R8: 6 | S8: C | T8: Manaus | U8: AM
A9: 8 | B9: palmeirassp | C9: Palmeiras-SP | D9: =SUMIF(CAL!B:E,B9,CAL!E:E)+SUMIF(CAL!J:M,B9,CAL!M:M) -> 54 | E9: =COUNTIF(CAL!B:J,B9) -> 23 | F9: =SUMIF(CAL!B:F,B9,CAL!F:F)+SUMIF(CAL!J:N,B9,CAL!N:N) -> 17 | G9: =SUMIF(CAL!B:F,B9,CAL!G:G)+SUMIF(CAL!J:N,B9,CAL!O:O) -> 3 | H9: =SUMIF(CAL!B:F,B9,CAL!H:H)+SUMIF(CAL!J:N,B9,CAL!P:P) -> 3 | I9: =IF(E9=0,0,(D9/(E9*3))) -> 0.7826087 | J9: =SUMIF(CAL!B:C,B9,CAL!C:C)+SUMIF(CAL!J:J,B9,CAL!D:D) -> 39 | K9: =SUMIF(CAL!B:D,B9,CAL!D:D)+SUMIF(CAL!J:L,B9,CAL!K:K) -> 20 | L9: =J9-K9 -> 19 | M9: =IF(E9=0,0,(J9/E9)) -> 1.6956522 | N9: =IF(E9=0,0,(K9/E9)) -> 0.86956522 | O9: =SUMIF(CAL!B:I,B9,CAL!I:I)+SUMIF(CAL!J:Q,B9,CAL!Q:Q) -> 8 | P9: =Q9+R9 -> 6 | Q9: 5 | R9: 1 | S9: D | T9: Aparecida de Goiânia | U9: GO
A10: 9 | B10: sportpe | C10: Sport-PE | D10: =SUMIF(CAL!B:E,B10,CAL!E:E)+SUMIF(CAL!J:M,B10,CAL!M:M) -> 40 | E10: =COUNTIF(CAL!B:J,B10) -> 20 | F10: =SUMIF(CAL!B:F,B10,CAL!F:F)+SUMIF(CAL!J:N,B10,CAL!N:N) -> 11 | G10: =SUMIF(CAL!B:F,B10,CAL!G:G)+SUMIF(CAL!J:N,B10,CAL!O:O) -> 7 | H10: =SUMIF(CAL!B:F,B10,CAL!H:H)+SUMIF(CAL!J:N,B10,CAL!P:P) -> 2 | I10: =IF(E10=0,0,(D10/(E10*3))) -> 0.66666667 | J10: =SUMIF(CAL!B:C,B10,CAL!C:C)+SUMIF(CAL!J:J,B10,CAL!D:D) -> 36 | K10: =SUMIF(CAL!B:D,B10,CAL!D:D)+SUMIF(CAL!J:L,B10,CAL!K:K) -> 20 | L10: =J10-K10 -> 16 | M10: =IF(E10=0,0,(J10/E10)) -> 1.8 | N10: =IF(E10=0,0,(K10/E10)) -> 1 | O10: =SUMIF(CAL!B:I,B10,CAL!I:I)+SUMIF(CAL!J:Q,B10,CAL!Q:Q) -> 9 | P10: =Q10+R10 -> 6 | Q10: 4 | R10: 2 | S10: D | T10: Boa Vista | U10: RR
A11: 10 | B11: csaal | C11: CSA-AL | D11: =SUMIF(CAL!B:E,B11,CAL!E:E)+SUMIF(CAL!J:M,B11,CAL!M:M) -> 35 | E11: =COUNTIF(CAL!B:J,B11) -> 17 | F11: =SUMIF(CAL!B:F,B11,CAL!F:F)+SUMIF(CAL!J:N,B11,CAL!N:N) -> 11 | G11: =SUMIF(CAL!B:F,B11,CAL!G:G)+SUMIF(CAL!J:N,B11,CAL!O:O) -> 2 | H11: =SUMIF(CAL!B:F,B11,CAL!H:H)+SUMIF(CAL!J:N,B11,CAL!P:P) -> 4 | I11: =IF(E11=0,0,(D11/(E11*3))) -> 0.68627451 | J11: =SUMIF(CAL!B:C,B11,CAL!C:C)+SUMIF(CAL!J:J,B11,CAL!D:D) -> 32 | K11: =SUMIF(CAL!B:D,B11,CAL!D:D)+SUMIF(CAL!J:L,B11,CAL!K:K) -> 11 | L11: =J11-K11 -> 21 | M11: =IF(E11=0,0,(J11/E11)) -> 1.8823529 | N11: =IF(E11=0,0,(K11/E11)) -> 0.64705882 | O11: =SUMIF(CAL!B:I,B11,CAL!I:I)+SUMIF(CAL!J:Q,B11,CAL!Q:Q) -> 10 | P11: =Q11+R11 -> 5 | Q11: 5 | R11: 0 | S11: D | T11: Sousa | U11: PB
A12: 11 | B12: sergipese | C12: Sergipe-SE | D12: =SUMIF(CAL!B:E,B12,CAL!E:E)+SUMIF(CAL!J:M,B12,CAL!M:M) -> 27 | E12: =COUNTIF(CAL!B:J,B12) -> 14 | F12: =SUMIF(CAL!B:F,B12,CAL!F:F)+SUMIF(CAL!J:N,B12,CAL!N:N) -> 7 | G12: =SUMIF(CAL!B:F,B12,CAL!G:G)+SUMIF(CAL!J:N,B12,CAL!O:O) -> 6 | H12: =SUMIF(CAL!B:F,B12,CAL!H:H)+SUMIF(CAL!J:N,B12,CAL!P:P) -> 1 | I12: =IF(E12=0,0,(D12/(E12*3))) -> 0.64285714 | J12: =SUMIF(CAL!B:C,B12,CAL!C:C)+SUMIF(CAL!J:J,B12,CAL!D:D) -> 18 | K12: =SUMIF(CAL!B:D,B12,CAL!D:D)+SUMIF(CAL!J:L,B12,CAL!K:K) -> 10 | L12: =J12-K12 -> 8 | M12: =IF(E12=0,0,(J12/E12)) -> 1.2857143 | N12: =IF(E12=0,0,(K12/E12)) -> 0.71428571 | O12: =SUMIF(CAL!B:I,B12,CAL!I:I)+SUMIF(CAL!J:Q,B12,CAL!Q:Q) -> 5 | P12: =Q12+R12 -> 5 | Q12: 1 | R12: 4 | S12: B | T12: Caxias do Sul | U12: RS
A13: 12 | B13: portovelhoro | C13: Porto Velho-RO | D13: =SUMIF(CAL!B:E,B13,CAL!E:E)+SUMIF(CAL!J:M,B13,CAL!M:M) -> 40 | E13: =COUNTIF(CAL!B:J,B13) -> 20 | F13: =SUMIF(CAL!B:F,B13,CAL!F:F)+SUMIF(CAL!J:N,B13,CAL!N:N) -> 12 | G13: =SUMIF(CAL!B:F,B13,CAL!G:G)+SUMIF(CAL!J:N,B13,CAL!O:O) -> 4 | H13: =SUMIF(CAL!B:F,B13,CAL!H:H)+SUMIF(CAL!J:N,B13,CAL!P:P) -> 4 | I13: =IF(E13=0,0,(D13/(E13*3))) -> 0.66666667 | J13: =SUMIF(CAL!B:C,B13,CAL!C:C)+SUMIF(CAL!J:J,B13,CAL!D:D) -> 38 | K13: =SUMIF(CAL!B:D,B13,CAL!D:D)+SUMIF(CAL!J:L,B13,CAL!K:K) -> 18 | L13: =J13-K13 -> 20 | M13: =IF(E13=0,0,(J13/E13)) -> 1.9 | N13: =IF(E13=0,0,(K13/E13)) -> 0.9 | O13: =SUMIF(CAL!B:I,B13,CAL!I:I)+SUMIF(CAL!J:Q,B13,CAL!Q:Q) -> 6 | P13: =Q13+R13 -> 4 | Q13: 4 | R13: 0 | S13: C | T13: João Pessoa | U13: PB
... A157: 156 | B157: vitoriaes | C157: Vitória-ES | D157: =SUMIF(CAL!B:E,B157,CAL!E:E)+SUMIF(CAL!J:M,B157,CAL!M:M) -> 30 | E157: =COUNTIF(CAL!B:J,B157) -> 15 | F157: =SUMIF(CAL!B:F,B157,CAL!F:F)+SUMIF(CAL!J:N,B157,CAL!N:N) -> 9 | G157: =SUMIF(CAL!B:F,B157,CAL!G:G)+SUMIF(CAL!J:N,B157,CAL!O:O) -> 3 | H157: =SUMIF(CAL!B:F,B157,CAL!H:H)+SUMIF(CAL!J:N,B157,CAL!P:P) -> 3 | I157: =IF(E157=0,0,(D157/(E157*3))) -> 0.66666667 | J157: =SUMIF(CAL!B:C,B157,CAL!C:C)+SUMIF(CAL!J:J,B157,CAL!D:D) -> 29 | K157: =SUMIF(CAL!B:D,B157,CAL!D:D)+SUMIF(CAL!J:L,B157,CAL!K:K) -> 13 | L157: =J157-K157 -> 16 | M157: =IF(E157=0,0,(J157/E157)) -> 1.9333333 | N157: =IF(E157=0,0,(K157/E157)) -> 0.86666667 | O157: =SUMIF(CAL!B:I,B157,CAL!I:I)+SUMIF(CAL!J:Q,B157,CAL!Q:Q) -> 7 | P157: =Q157+R157 -> 0 | Q157: 0 | R157: 0 | S157: D | T157: Tocantinópolis | U157: TO
A158: 157 | B158: adesgac | C158: ADESG-AC | D158: =SUMIF(CAL!B:E,B158,CAL!E:E)+SUMIF(CAL!J:M,B158,CAL!M:M) -> 5 | E158: =COUNTIF(CAL!B:J,B158) -> 7 | F158: =SUMIF(CAL!B:F,B158,CAL!F:F)+SUMIF(CAL!J:N,B158,CAL!N:N) -> 1 | G158: =SUMIF(CAL!B:F,B158,CAL!G:G)+SUMIF(CAL!J:N,B158,CAL!O:O) -> 2 | H158: =SUMIF(CAL!B:F,B158,CAL!H:H)+SUMIF(CAL!J:N,B158,CAL!P:P) -> 4 | I158: =IF(E158=0,0,(D158/(E158*3))) -> 0.23809524 | J158: =SUMIF(CAL!B:C,B158,CAL!C:C)+SUMIF(CAL!J:J,B158,CAL!D:D) -> 7 | K158: =SUMIF(CAL!B:D,B158,CAL!D:D)+SUMIF(CAL!J:L,B158,CAL!K:K) -> 12 | L158: =J158-K158 -> -5 | M158: =IF(E158=0,0,(J158/E158)) -> 1 | N158: =IF(E158=0,0,(K158/E158)) -> 1.7142857 | O158: =SUMIF(CAL!B:I,B158,CAL!I:I)+SUMIF(CAL!J:Q,B158,CAL!Q:Q) -> 1 | T158: Senador Guiomard | U158: AC
A159: 158 | B159: aguianegrams | C159: Águia Negra-MS | D159: =SUMIF(CAL!B:E,B159,CAL!E:E)+SUMIF(CAL!J:M,B159,CAL!M:M) -> 6 | E159: =COUNTIF(CAL!B:J,B159) -> 8 | F159: =SUMIF(CAL!B:F,B159,CAL!F:F)+SUMIF(CAL!J:N,B159,CAL!N:N) -> 1 | G159: =SUMIF(CAL!B:F,B159,CAL!G:G)+SUMIF(CAL!J:N,B159,CAL!O:O) -> 3 | H159: =SUMIF(CAL!B:F,B159,CAL!H:H)+SUMIF(CAL!J:N,B159,CAL!P:P) -> 4 | I159: =IF(E159=0,0,(D159/(E159*3))) -> 0.25 | J159: =SUMIF(CAL!B:C,B159,CAL!C:C)+SUMIF(CAL!J:J,B159,CAL!D:D) -> 8 | K159: =SUMIF(CAL!B:D,B159,CAL!D:D)+SUMIF(CAL!J:L,B159,CAL!K:K) -> 12 | L159: =J159-K159 -> -4 | M159: =IF(E159=0,0,(J159/E159)) -> 1 | N159: =IF(E159=0,0,(K159/E159)) -> 1.5 | O159: =SUMIF(CAL!B:I,B159,CAL!I:I)+SUMIF(CAL!J:Q,B159,CAL!Q:Q) -> 0 | T159: Rio Brilhante | U159: MS
A160: 159 | B160: amazoniapa | C160: Amazonia-PA | D160: =SUMIF(CAL!B:E,B160,CAL!E:E)+SUMIF(CAL!J:M,B160,CAL!M:M) -> 6 | E160: =COUNTIF(CAL!B:J,B160) -> 6 | F160: =SUMIF(CAL!B:F,B160,CAL!F:F)+SUMIF(CAL!J:N,B160,CAL!N:N) -> 1 | G160: =SUMIF(CAL!B:F,B160,CAL!G:G)+SUMIF(CAL!J:N,B160,CAL!O:O) -> 3 | H160: =SUMIF(CAL!B:F,B160,CAL!H:H)+SUMIF(CAL!J:N,B160,CAL!P:P) -> 2 | I160: =IF(E160=0,0,(D160/(E160*3))) -> 0.33333333 | J160: =SUMIF(CAL!B:C,B160,CAL!C:C)+SUMIF(CAL!J:J,B160,CAL!D:D) -> 7 | K160: =SUMIF(CAL!B:D,B160,CAL!D:D)+SUMIF(CAL!J:L,B160,CAL!K:K) -> 11 | L160: =J160-K160 -> -4 | M160: =IF(E160=0,0,(J160/E160)) -> 1.1666667 | N160: =IF(E160=0,0,(K160/E160)) -> 1.8333333 | O160: =SUMIF(CAL!B:I,B160,CAL!I:I)+SUMIF(CAL!J:Q,B160,CAL!Q:Q) -> 1 | T160: Santarem | U160: PA
A161: 160 | B161: americase | C161: América de Propriá-SE | D161: =SUMIF(CAL!B:E,B161,CAL!E:E)+SUMIF(CAL!J:M,B161,CAL!M:M) -> 18 | E161: =COUNTIF(CAL!B:J,B161) -> 14 | F161: =SUMIF(CAL!B:F,B161,CAL!F:F)+SUMIF(CAL!J:N,B161,CAL!N:N) -> 3 | G161: =SUMIF(CAL!B:F,B161,CAL!G:G)+SUMIF(CAL!J:N,B161,CAL!O:O) -> 9 | H161: =SUMIF(CAL!B:F,B161,CAL!H:H)+SUMIF(CAL!J:N,B161,CAL!P:P) -> 2 | I161: =IF(E161=0,0,(D161/(E161*3))) -> 0.42857143 | J161: =SUMIF(CAL!B:C,B161,CAL!C:C)+SUMIF(CAL!J:J,B161,CAL!D:D) -> 14 | K161: =SUMIF(CAL!B:D,B161,CAL!D:D)+SUMIF(CAL!J:L,B161,CAL!K:K) -> 12 | L161: =J161-K161 -> 2 | M161: =IF(E161=0,0,(J161/E161)) -> 1 | N161: =IF(E161=0,0,(K161/E161)) -> 0.85714286 | O161: =SUMIF(CAL!B:I,B161,CAL!I:I)+SUMIF(CAL!J:Q,B161,CAL!Q:Q) -> 6 | T161: Propria | U161: SE
A162: 161 | B162: anapolinago | C162: Anapolina-GO | D162: =SUMIF(CAL!B:E,B162,CAL!E:E)+SUMIF(CAL!J:M,B162,CAL!M:M) -> 18 | E162: =COUNTIF(CAL!B:J,B162) -> 12 | F162: =SUMIF(CAL!B:F,B162,CAL!F:F)+SUMIF(CAL!J:N,B162,CAL!N:N) -> 5 | G162: =SUMIF(CAL!B:F,B162,CAL!G:G)+SUMIF(CAL!J:N,B162,CAL!O:O) -> 3 | H162: =SUMIF(CAL!B:F,B162,CAL!H:H)+SUMIF(CAL!J:N,B162,CAL!P:P) -> 4 | I162: =IF(E162=0,0,(D162/(E162*3))) -> 0.5 | J162: =SUMIF(CAL!B:C,B162,CAL!C:C)+SUMIF(CAL!J:J,B162,CAL!D:D) -> 15 | K162: =SUMIF(CAL!B:D,B162,CAL!D:D)+SUMIF(CAL!J:L,B162,CAL!K:K) -> 16 | L162: =J162-K162 -> -1 | M162: =IF(E162=0,0,(J162/E162)) -> 1.25 | N162: =IF(E162=0,0,(K162/E162)) -> 1.3333333 | O162: =SUMIF(CAL!B:I,B162,CAL!I:I)+SUMIF(CAL!J:Q,B162,CAL!Q:Q) -> 3 | T162: Anapolis | U162: GO
A163: 162 | B163: andrauspr | C163: Andraus-PR | D163: =SUMIF(CAL!B:E,B163,CAL!E:E)+SUMIF(CAL!J:M,B163,CAL!M:M) -> 4 | E163: =COUNTIF(CAL!B:J,B163) -> 8 | F163: =SUMIF(CAL!B:F,B163,CAL!F:F)+SUMIF(CAL!J:N,B163,CAL!N:N) -> 1 | G163: =SUMIF(CAL!B:F,B163,CAL!G:G)+SUMIF(CAL!J:N,B163,CAL!O:O) -> 1 | H163: =SUMIF(CAL!B:F,B163,CAL!H:H)+SUMIF(CAL!J:N,B163,CAL!P:P) -> 6 | I163: =IF(E163=0,0,(D163/(E163*3))) -> 0.16666667 | J163: =SUMIF(CAL!B:C,B163,CAL!C:C)+SUMIF(CAL!J:J,B163,CAL!D:D) -> 7 | K163: =SUMIF(CAL!B:D,B163,CAL!D:D)+SUMIF(CAL!J:L,B163,CAL!K:K) -> 16 | L163: =J163-K163 -> -9 | M163: =IF(E163=0,0,(J163/E163)) -> 0.875 | N163: =IF(E163=0,0,(K163/E163)) -> 2 | O163: =SUMIF(CAL!B:I,B163,CAL!I:I)+SUMIF(CAL!J:Q,B163,CAL!Q:Q) -> 1 | T163: Campo Largo | U163: PR
A164: 163 | B164: aquidauanams | C164: Aquidauana-MS | D164: =SUMIF(CAL!B:E,B164,CAL!E:E)+SUMIF(CAL!J:M,B164,CAL!M:M) -> 7 | E164: =COUNTIF(CAL!B:J,B164) -> 8 | F164: =SUMIF(CAL!B:F,B164,CAL!F:F)+SUMIF(CAL!J:N,B164,CAL!N:N) -> 1 | G164: =SUMIF(CAL!B:F,B164,CAL!G:G)+SUMIF(CAL!J:N,B164,CAL!O:O) -> 4 | H164: =SUMIF(CAL!B:F,B164,CAL!H:H)+SUMIF(CAL!J:N,B164,CAL!P:P) -> 3 | I164: =IF(E164=0,0,(D164/(E164*3))) -> 0.29166667 | J164: =SUMIF(CAL!B:C,B164,CAL!C:C)+SUMIF(CAL!J:J,B164,CAL!D:D) -> 10 | K164: =SUMIF(CAL!B:D,B164,CAL!D:D)+SUMIF(CAL!J:L,B164,CAL!K:K) -> 13 | L164: =J164-K164 -> -3 | M164: =IF(E164=0,0,(J164/E164)) -> 1.25 | N164: =IF(E164=0,0,(K164/E164)) -> 1.625 | O164: =SUMIF(CAL!B:I,B164,CAL!I:I)+SUMIF(CAL!J:Q,B164,CAL!Q:Q) -> 0 | T164: Aquidauana | U164: MS
A165: 164 | B165: aracatubasp | C165: Araçatuba-SP | D165: =SUMIF(CAL!B:E,B165,CAL!E:E)+SUMIF(CAL!J:M,B165,CAL!M:M) -> 5 | E165: =COUNTIF(CAL!B:J,B165) -> 15 | F165: =SUMIF(CAL!B:F,B165,CAL!F:F)+SUMIF(CAL!J:N,B165,CAL!N:N) -> 1 | G165: =SUMIF(CAL!B:F,B165,CAL!G:G)+SUMIF(CAL!J:N,B165,CAL!O:O) -> 2 | H165: =SUMIF(CAL!B:F,B165,CAL!H:H)+SUMIF(CAL!J:N,B165,CAL!P:P) -> 12 | I165: =IF(E165=0,0,(D165/(E165*3))) -> 0.11111111 | J165: =SUMIF(CAL!B:C,B165,CAL!C:C)+SUMIF(CAL!J:J,B165,CAL!D:D) -> 6 | K165: =SUMIF(CAL!B:D,B165,CAL!D:D)+SUMIF(CAL!J:L,B165,CAL!K:K) -> 37 | L165: =J165-K165 -> -31 | M165: =IF(E165=0,0,(J165/E165)) -> 0.4 | N165: =IF(E165=0,0,(K165/E165)) -> 2.4666667 | O165: =SUMIF(CAL!B:I,B165,CAL!I:I)+SUMIF(CAL!J:Q,B165,CAL!Q:Q) -> 3 | T165: Araçatuba | U165: SP
A166: 165 | B166: araucariapr | C166: Araucária-PR | D166: =SUMIF(CAL!B:E,B166,CAL!E:E)+SUMIF(CAL!J:M,B166,CAL!M:M) -> 6 | E166: =COUNTIF(CAL!B:J,B166) -> 6 | F166: =SUMIF(CAL!B:F,B166,CAL!F:F)+SUMIF(CAL!J:N,B166,CAL!N:N) -> 1 | G166: =SUMIF(CAL!B:F,B166,CAL!G:G)+SUMIF(CAL!J:N,B166,CAL!O:O) -> 3 | H166: =SUMIF(CAL!B:F,B166,CAL!H:H)+SUMIF(CAL!J:N,B166,CAL!P:P) -> 2 | I166: =IF(E166=0,0,(D166/(E166*3))) -> 0.33333333 | J166: =SUMIF(CAL!B:C,B166,CAL!C:C)+SUMIF(CAL!J:J,B166,CAL!D:D) -> 11 | K166: =SUMIF(CAL!B:D,B166,CAL!D:D)+SUMIF(CAL!J:L,B166,CAL!K:K) -> 13 | L166: =J166-K166 -> -2 | M166: =IF(E166=0,0,(J166/E166)) -> 1.8333333 | N166: =IF(E166=0,0,(K166/E166)) -> 2.1666667 | O166: =SUMIF(CAL!B:I,B166,CAL!I:I)+SUMIF(CAL!J:Q,B166,CAL!Q:Q) -> 0 | T166: Araucária | U166: PR
A167: 166 | B167: arucdf | C167: ARUC-DF | D167: =SUMIF(CAL!B:E,B167,CAL!E:E)+SUMIF(CAL!J:M,B167,CAL!M:M) -> 3 | E167: =COUNTIF(CAL!B:J,B167) -> 9 | F167: =SUMIF(CAL!B:F,B167,CAL!F:F)+SUMIF(CAL!J:N,B167,CAL!N:N) -> 1 | G167: =SUMIF(CAL!B:F,B167,CAL!G:G)+SUMIF(CAL!J:N,B167,CAL!O:O) -> 0 | H167: =SUMIF(CAL!B:F,B167,CAL!H:H)+SUMIF(CAL!J:N,B167,CAL!P:P) -> 8 | I167: =IF(E167=0,0,(D167/(E167*3))) -> 0.11111111 | J167: =SUMIF(CAL!B:C,B167,CAL!C:C)+SUMIF(CAL!J:J,B167,CAL!D:D) -> 3 | K167: =SUMIF(CAL!B:D,B167,CAL!D:D)+SUMIF(CAL!J:L,B167,CAL!K:K) -> 20 | L167: =J167-K167 -> -17 | M167: =IF(E167=0,0,(J167/E167)) -> 0.33333333 | N167: =IF(E167=0,0,(K167/E167)) -> 2.2222222 | O167: =SUMIF(CAL!B:I,B167,CAL!I:I)+SUMIF(CAL!J:Q,B167,CAL!Q:Q) -> 1 | T167: Cruzeiro | U167: DF
A168: 167 | B168: atleticopb | C168: Atlético Cajazeiras-PB | D168: =SUMIF(CAL!B:E,B168,CAL!E:E)+SUMIF(CAL!J:M,B168,CAL!M:M) -> 10 | E168: =COUNTIF(CAL!B:J,B168) -> 9 | F168: =SUMIF(CAL!B:F,B168,CAL!F:F)+SUMIF(CAL!J:N,B168,CAL!N:N) -> 3 | G168: =SUMIF(CAL!B:F,B168,CAL!G:G)+SUMIF(CAL!J:N,B168,CAL!O:O) -> 1 | H168: =SUMIF(CAL!B:F,B168,CAL!H:H)+SUMIF(CAL!J:N,B168,CAL!P:P) -> 5 | I168: =IF(E168=0,0,(D168/(E168*3))) -> 0.37037037 | J168: =SUMIF(CAL!B:C,B168,CAL!C:C)+SUMIF(CAL!J:J,B168,CAL!D:D) -> 6 | K168: =SUMIF(CAL!B:D,B168,CAL!D:D)+SUMIF(CAL!J:L,B168,CAL!K:K) -> 11 | L168: =J168-K168 -> -5 | M168: =IF(E168=0,0,(J168/E168)) -> 0.66666667 | N168: =IF(E168=0,0,(K168/E168)) -> 1.2222222 | O168: =SUMIF(CAL!B:I,B168,CAL!I:I)+SUMIF(CAL!J:Q,B168,CAL!Q:Q) -> 2 | T168: Cajazeiras | U168: PB
A169: 168 | B169: atleticopi | C169: Atlético-PI | D169: =SUMIF(CAL!B:E,B169,CAL!E:E)+SUMIF(CAL!J:M,B169,CAL!M:M) -> 21 | E169: =COUNTIF(CAL!B:J,B169) -> 11 | F169: =SUMIF(CAL!B:F,B169,CAL!F:F)+SUMIF(CAL!J:N,B169,CAL!N:N) -> 6 | G169: =SUMIF(CAL!B:F,B169,CAL!G:G)+SUMIF(CAL!J:N,B169,CAL!O:O) -> 3 | H169: =SUMIF(CAL!B:F,B169,CAL!H:H)+SUMIF(CAL!J:N,B169,CAL!P:P) -> 2 | I169: =IF(E169=0,0,(D169/(E169*3))) -> 0.63636364 | J169: =SUMIF(CAL!B:C,B169,CAL!C:C)+SUMIF(CAL!J:J,B169,CAL!D:D) -> 17 | K169: =SUMIF(CAL!B:D,B169,CAL!D:D)+SUMIF(CAL!J:L,B169,CAL!K:K) -> 7 | L169: =J169-K169 -> 10 | M169: =IF(E169=0,0,(J169/E169)) -> 1.5454545 | N169: =IF(E169=0,0,(K169/E169)) -> 0.63636364 | O169: =SUMIF(CAL!B:I,B169,CAL!I:I)+SUMIF(CAL!J:Q,B169,CAL!Q:Q) -> 5 | T169: Teresina | U169: PI
... A196: 195 | B196: catanduvasp | C196: Catanduva-SP | D196: =SUMIF(CAL!B:E,B196,CAL!E:E)+SUMIF(CAL!J:M,B196,CAL!M:M) -> 21 | E196: =COUNTIF(CAL!B:J,B196) -> 15 | F196: =SUMIF(CAL!B:F,B196,CAL!F:F)+SUMIF(CAL!J:N,B196,CAL!N:N) -> 5 | G196: =SUMIF(CAL!B:F,B196,CAL!G:G)+SUMIF(CAL!J:N,B196,CAL!O:O) -> 6 | H196: =SUMIF(CAL!B:F,B196,CAL!H:H)+SUMIF(CAL!J:N,B196,CAL!P:P) -> 4 | I196: =IF(E196=0,0,(D196/(E196*3))) -> 0.46666667 | J196: =SUMIF(CAL!B:C,B196,CAL!C:C)+SUMIF(CAL!J:J,B196,CAL!D:D) -> 16 | K196: =SUMIF(CAL!B:D,B196,CAL!D:D)+SUMIF(CAL!J:L,B196,CAL!K:K) -> 15 | L196: =J196-K196 -> 1 | M196: =IF(E196=0,0,(J196/E196)) -> 1.0666667 | N196: =IF(E196=0,0,(K196/E196)) -> 1 | O196: =SUMIF(CAL!B:I,B196,CAL!I:I)+SUMIF(CAL!J:Q,B196,CAL!Q:Q) -> 7 | T196: Catanduva | U196: SP
A197: 196 | B197: caucaiace | C197: Caucaia-CE | D197: =SUMIF(CAL!B:E,B197,CAL!E:E)+SUMIF(CAL!J:M,B197,CAL!M:M) -> 7 | E197: =COUNTIF(CAL!B:J,B197) -> 4 | F197: =SUMIF(CAL!B:F,B197,CAL!F:F)+SUMIF(CAL!J:N,B197,CAL!N:N) -> 2 | G197: =SUMIF(CAL!B:F,B197,CAL!G:G)+SUMIF(CAL!J:N,B197,CAL!O:O) -> 1 | H197: =SUMIF(CAL!B:F,B197,CAL!H:H)+SUMIF(CAL!J:N,B197,CAL!P:P) -> 1 | I197: =IF(E197=0,0,(D197/(E197*3))) -> 0.58333333 | J197: =SUMIF(CAL!B:C,B197,CAL!C:C)+SUMIF(CAL!J:J,B197,CAL!D:D) -> 6 | K197: =SUMIF(CAL!B:D,B197,CAL!D:D)+SUMIF(CAL!J:L,B197,CAL!K:K) -> 6 | L197: =J197-K197 -> 0 | M197: =IF(E197=0,0,(J197/E197)) -> 1.5 | N197: =IF(E197=0,0,(K197/E197)) -> 1.5 | O197: =SUMIF(CAL!B:I,B197,CAL!I:I)+SUMIF(CAL!J:Q,B197,CAL!Q:Q) -> 1 | U197: CE
A198: 197 | B198: centrooestego | C198: Centro Oeste-GO | D198: =SUMIF(CAL!B:E,B198,CAL!E:E)+SUMIF(CAL!J:M,B198,CAL!M:M) -> 9 | E198: =COUNTIF(CAL!B:J,B198) -> 10 | F198: =SUMIF(CAL!B:F,B198,CAL!F:F)+SUMIF(CAL!J:N,B198,CAL!N:N) -> 2 | G198: =SUMIF(CAL!B:F,B198,CAL!G:G)+SUMIF(CAL!J:N,B198,CAL!O:O) -> 3 | H198: =SUMIF(CAL!B:F,B198,CAL!H:H)+SUMIF(CAL!J:N,B198,CAL!P:P) -> 5 | I198: =IF(E198=0,0,(D198/(E198*3))) -> 0.3 | J198: =SUMIF(CAL!B:C,B198,CAL!C:C)+SUMIF(CAL!J:J,B198,CAL!D:D) -> 8 | K198: =SUMIF(CAL!B:D,B198,CAL!D:D)+SUMIF(CAL!J:L,B198,CAL!K:K) -> 21 | L198: =J198-K198 -> -13 | M198: =IF(E198=0,0,(J198/E198)) -> 0.8 | N198: =IF(E198=0,0,(K198/E198)) -> 2.1 | O198: =SUMIF(CAL!B:I,B198,CAL!I:I)+SUMIF(CAL!J:Q,B198,CAL!Q:Q) -> 2 | T198: Neropolis | U198: GO
A199: 198 | B199: chapadamt | C199: Chapada-MT | D199: =SUMIF(CAL!B:E,B199,CAL!E:E)+SUMIF(CAL!J:M,B199,CAL!M:M) -> 11 | E199: =COUNTIF(CAL!B:J,B199) -> 9 | F199: =SUMIF(CAL!B:F,B199,CAL!F:F)+SUMIF(CAL!J:N,B199,CAL!N:N) -> 3 | G199: =SUMIF(CAL!B:F,B199,CAL!G:G)+SUMIF(CAL!J:N,B199,CAL!O:O) -> 2 | H199: =SUMIF(CAL!B:F,B199,CAL!H:H)+SUMIF(CAL!J:N,B199,CAL!P:P) -> 4 | I199: =IF(E199=0,0,(D199/(E199*3))) -> 0.40740741 | J199: =SUMIF(CAL!B:C,B199,CAL!C:C)+SUMIF(CAL!J:J,B199,CAL!D:D) -> 12 | K199: =SUMIF(CAL!B:D,B199,CAL!D:D)+SUMIF(CAL!J:L,B199,CAL!K:K) -> 13 | L199: =J199-K199 -> -1 | M199: =IF(E199=0,0,(J199/E199)) -> 1.3333333 | N199: =IF(E199=0,0,(K199/E199)) -> 1.4444444 | O199: =SUMIF(CAL!B:I,B199,CAL!I:I)+SUMIF(CAL!J:Q,B199,CAL!Q:Q) -> 2 | T199: Pocone | U199: MT
A200: 199 | B200: coloradosp | C200: Colorado-SP | D200: =SUMIF(CAL!B:E,B200,CAL!E:E)+SUMIF(CAL!J:M,B200,CAL!M:M) -> 10 | E200: =COUNTIF(CAL!B:J,B200) -> 15 | F200: =SUMIF(CAL!B:F,B200,CAL!F:F)+SUMIF(CAL!J:N,B200,CAL!N:N) -> 1 | G200: =SUMIF(CAL!B:F,B200,CAL!G:G)+SUMIF(CAL!J:N,B200,CAL!O:O) -> 7 | H200: =SUMIF(CAL!B:F,B200,CAL!H:H)+SUMIF(CAL!J:N,B200,CAL!P:P) -> 7 | I200: =IF(E200=0,0,(D200/(E200*3))) -> 0.22222222 | J200: =SUMIF(CAL!B:C,B200,CAL!C:C)+SUMIF(CAL!J:J,B200,CAL!D:D) -> 6 | K200: =SUMIF(CAL!B:D,B200,CAL!D:D)+SUMIF(CAL!J:L,B200,CAL!K:K) -> 20 | L200: =J200-K200 -> -14 | M200: =IF(E200=0,0,(J200/E200)) -> 0.4 | N200: =IF(E200=0,0,(K200/E200)) -> 1.3333333 | O200: =SUMIF(CAL!B:I,B200,CAL!I:I)+SUMIF(CAL!J:Q,B200,CAL!Q:Q) -> 5 | T200: Caieiras | U200: SP
A201: 200 | B201: comercialsp | C201: Comercial-SP | D201: =SUMIF(CAL!B:E,B201,CAL!E:E)+SUMIF(CAL!J:M,B201,CAL!M:M) -> 20 | E201: =COUNTIF(CAL!B:J,B201) -> 15 | F201: =SUMIF(CAL!B:F,B201,CAL!F:F)+SUMIF(CAL!J:N,B201,CAL!N:N) -> 6 | G201: =SUMIF(CAL!B:F,B201,CAL!G:G)+SUMIF(CAL!J:N,B201,CAL!O:O) -> 2 | H201: =SUMIF(CAL!B:F,B201,CAL!H:H)+SUMIF(CAL!J:N,B201,CAL!P:P) -> 7 | I201: =IF(E201=0,0,(D201/(E201*3))) -> 0.44444444 | J201: =SUMIF(CAL!B:C,B201,CAL!C:C)+SUMIF(CAL!J:J,B201,CAL!D:D) -> 17 | K201: =SUMIF(CAL!B:D,B201,CAL!D:D)+SUMIF(CAL!J:L,B201,CAL!K:K) -> 16 | L201: =J201-K201 -> 1 | M201: =IF(E201=0,0,(J201/E201)) -> 1.1333333 | N201: =IF(E201=0,0,(K201/E201)) -> 1.0666667 | O201: =SUMIF(CAL!B:I,B201,CAL!I:I)+SUMIF(CAL!J:Q,B201,CAL!Q:Q) -> 3 | T201: Ribeirao Preto | U201: SP
A202: 201 | B202: concordiasc | C202: Concórdia-SC | D202: =SUMIF(CAL!B:E,B202,CAL!E:E)+SUMIF(CAL!J:M,B202,CAL!M:M) -> 10 | E202: =COUNTIF(CAL!B:J,B202) -> 10 | F202: =SUMIF(CAL!B:F,B202,CAL!F:F)+SUMIF(CAL!J:N,B202,CAL!N:N) -> 2 | G202: =SUMIF(CAL!B:F,B202,CAL!G:G)+SUMIF(CAL!J:N,B202,CAL!O:O) -> 4 | H202: =SUMIF(CAL!B:F,B202,CAL!H:H)+SUMIF(CAL!J:N,B202,CAL!P:P) -> 4 | I202: =IF(E202=0,0,(D202/(E202*3))) -> 0.33333333 | J202: =SUMIF(CAL!B:C,B202,CAL!C:C)+SUMIF(CAL!J:J,B202,CAL!D:D) -> 8 | K202: =SUMIF(CAL!B:D,B202,CAL!D:D)+SUMIF(CAL!J:L,B202,CAL!K:K) -> 17 | L202: =J202-K202 -> -9 | M202: =IF(E202=0,0,(J202/E202)) -> 0.8 | N202: =IF(E202=0,0,(K202/E202)) -> 1.7 | O202: =SUMIF(CAL!B:I,B202,CAL!I:I)+SUMIF(CAL!J:Q,B202,CAL!Q:Q) -> 4 | T202: Concordia | U202: SC
A203: 202 | B203: confiancapb | C203: Confiança-PB | D203: =SUMIF(CAL!B:E,B203,CAL!E:E)+SUMIF(CAL!J:M,B203,CAL!M:M) -> 8 | E203: =COUNTIF(CAL!B:J,B203) -> 9 | F203: =SUMIF(CAL!B:F,B203,CAL!F:F)+SUMIF(CAL!J:N,B203,CAL!N:N) -> 2 | G203: =SUMIF(CAL!B:F,B203,CAL!G:G)+SUMIF(CAL!J:N,B203,CAL!O:O) -> 2 | H203: =SUMIF(CAL!B:F,B203,CAL!H:H)+SUMIF(CAL!J:N,B203,CAL!P:P) -> 5 | I203: =IF(E203=0,0,(D203/(E203*3))) -> 0.2962963 | J203: =SUMIF(CAL!B:C,B203,CAL!C:C)+SUMIF(CAL!J:J,B203,CAL!D:D) -> 12 | K203: =SUMIF(CAL!B:D,B203,CAL!D:D)+SUMIF(CAL!J:L,B203,CAL!K:K) -> 17 | L203: =J203-K203 -> -5 | M203: =IF(E203=0,0,(J203/E203)) -> 1.3333333 | N203: =IF(E203=0,0,(K203/E203)) -> 1.8888889 | O203: =SUMIF(CAL!B:I,B203,CAL!I:I)+SUMIF(CAL!J:Q,B203,CAL!Q:Q) -> 1 | T203: Sape | U203: PB
A204: 203 | B204: corisabbapi | C204: Corisabba-PI | D204: =SUMIF(CAL!B:E,B204,CAL!E:E)+SUMIF(CAL!J:M,B204,CAL!M:M) -> 5 | E204: =COUNTIF(CAL!B:J,B204) -> 7 | F204: =SUMIF(CAL!B:F,B204,CAL!F:F)+SUMIF(CAL!J:N,B204,CAL!N:N) -> 1 | G204: =SUMIF(CAL!B:F,B204,CAL!G:G)+SUMIF(CAL!J:N,B204,CAL!O:O) -> 2 | H204: =SUMIF(CAL!B:F,B204,CAL!H:H)+SUMIF(CAL!J:N,B204,CAL!P:P) -> 4 | I204: =IF(E204=0,0,(D204/(E204*3))) -> 0.23809524 | J204: =SUMIF(CAL!B:C,B204,CAL!C:C)+SUMIF(CAL!J:J,B204,CAL!D:D) -> 6 | K204: =SUMIF(CAL!B:D,B204,CAL!D:D)+SUMIF(CAL!J:L,B204,CAL!K:K) -> 13 | L204: =J204-K204 -> -7 | M204: =IF(E204=0,0,(J204/E204)) -> 0.85714286 | N204: =IF(E204=0,0,(K204/E204)) -> 1.8571429 | O204: =SUMIF(CAL!B:I,B204,CAL!I:I)+SUMIF(CAL!J:Q,B204,CAL!Q:Q) -> 1 | T204: Floriano | U204: PI
A205: 204 | B205: corumbaensems | C205: Corumbaense-MS | D205: =SUMIF(CAL!B:E,B205,CAL!E:E)+SUMIF(CAL!J:M,B205,CAL!M:M) -> 17 | E205: =COUNTIF(CAL!B:J,B205) -> 13 | F205: =SUMIF(CAL!B:F,B205,CAL!F:F)+SUMIF(CAL!J:N,B205,CAL!N:N) -> 4 | G205: =SUMIF(CAL!B:F,B205,CAL!G:G)+SUMIF(CAL!J:N,B205,CAL!O:O) -> 5 | H205: =SUMIF(CAL!B:F,B205,CAL!H:H)+SUMIF(CAL!J:N,B205,CAL!P:P) -> 4 | I205: =IF(E205=0,0,(D205/(E205*3))) -> 0.43589744 | J205: =SUMIF(CAL!B:C,B205,CAL!C:C)+SUMIF(CAL!J:J,B205,CAL!D:D) -> 14 | K205: =SUMIF(CAL!B:D,B205,CAL!D:D)+SUMIF(CAL!J:L,B205,CAL!K:K) -> 11 | L205: =J205-K205 -> 3 | M205: =IF(E205=0,0,(J205/E205)) -> 1.0769231 | N205: =IF(E205=0,0,(K205/E205)) -> 0.84615385 | O205: =SUMIF(CAL!B:I,B205,CAL!I:I)+SUMIF(CAL!J:Q,B205,CAL!Q:Q) -> 5 | T205: Corumba | U205: MS
A206: 205 | B206: coruripeal | C206: Coruripe-AL | D206: =SUMIF(CAL!B:E,B206,CAL!E:E)+SUMIF(CAL!J:M,B206,CAL!M:M) -> 12 | E206: =COUNTIF(CAL!B:J,B206) -> 11 | F206: =SUMIF(CAL!B:F,B206,CAL!F:F)+SUMIF(CAL!J:N,B206,CAL!N:N) -> 3 | G206: =SUMIF(CAL!B:F,B206,CAL!G:G)+SUMIF(CAL!J:N,B206,CAL!O:O) -> 3 | H206: =SUMIF(CAL!B:F,B206,CAL!H:H)+SUMIF(CAL!J:N,B206,CAL!P:P) -> 5 | I206: =IF(E206=0,0,(D206/(E206*3))) -> 0.36363636 | J206: =SUMIF(CAL!B:C,B206,CAL!C:C)+SUMIF(CAL!J:J,B206,CAL!D:D) -> 11 | K206: =SUMIF(CAL!B:D,B206,CAL!D:D)+SUMIF(CAL!J:L,B206,CAL!K:K) -> 18 | L206: =J206-K206 -> -7 | M206: =IF(E206=0,0,(J206/E206)) -> 1 | N206: =IF(E206=0,0,(K206/E206)) -> 1.6363636 | O206: =SUMIF(CAL!B:I,B206,CAL!I:I)+SUMIF(CAL!J:Q,B206,CAL!Q:Q) -> 1 | T206: Coruripe | U206: AL
A207: 206 | B207: costaricams | C207: Costa Rica-MS | D207: =SUMIF(CAL!B:E,B207,CAL!E:E)+SUMIF(CAL!J:M,B207,CAL!M:M) -> 8 | E207: =COUNTIF(CAL!B:J,B207) -> 9 | F207: =SUMIF(CAL!B:F,B207,CAL!F:F)+SUMIF(CAL!J:N,B207,CAL!N:N) -> 1 | G207: =SUMIF(CAL!B:F,B207,CAL!G:G)+SUMIF(CAL!J:N,B207,CAL!O:O) -> 5 | H207: =SUMIF(CAL!B:F,B207,CAL!H:H)+SUMIF(CAL!J:N,B207,CAL!P:P) -> 3 | I207: =IF(E207=0,0,(D207/(E207*3))) -> 0.2962963 | J207: =SUMIF(CAL!B:C,B207,CAL!C:C)+SUMIF(CAL!J:J,B207,CAL!D:D) -> 6 | K207: =SUMIF(CAL!B:D,B207,CAL!D:D)+SUMIF(CAL!J:L,B207,CAL!K:K) -> 10 | L207: =J207-K207 -> -4 | M207: =IF(E207=0,0,(J207/E207)) -> 0.66666667 | N207: =IF(E207=0,0,(K207/E207)) -> 1.1111111 | O207: =SUMIF(CAL!B:I,B207,CAL!I:I)+SUMIF(CAL!J:Q,B207,CAL!Q:Q) -> 2 | T207: Costa Rica | U207: MS
A208: 207 | B208: crateusce | C208: Crateús-CE | D208: =SUMIF(CAL!B:E,B208,CAL!E:E)+SUMIF(CAL!J:M,B208,CAL!M:M) -> 4 | E208: =COUNTIF(CAL!B:J,B208) -> 4 | F208: =SUMIF(CAL!B:F,B208,CAL!F:F)+SUMIF(CAL!J:N,B208,CAL!N:N) -> 1 | G208: =SUMIF(CAL!B:F,B208,CAL!G:G)+SUMIF(CAL!J:N,B208,CAL!O:O) -> 1 | H208: =SUMIF(CAL!B:F,B208,CAL!H:H)+SUMIF(CAL!J:N,B208,CAL!P:P) -> 2 | I208: =IF(E208=0,0,(D208/(E208*3))) -> 0.33333333 | J208: =SUMIF(CAL!B:C,B208,CAL!C:C)+SUMIF(CAL!J:J,B208,CAL!D:D) -> 4 | K208: =SUMIF(CAL!B:D,B208,CAL!D:D)+SUMIF(CAL!J:L,B208,CAL!K:K) -> 3 | L208: =J208-K208 -> 1 | M208: =IF(E208=0,0,(J208/E208)) -> 1 | N208: =IF(E208=0,0,(K208/E208)) -> 0.75 | O208: =SUMIF(CAL!B:I,B208,CAL!I:I)+SUMIF(CAL!J:Q,B208,CAL!Q:Q) -> 1 | T208: Crateús | U208: CE
A209: 208 | B209: cratoce | C209: Crato-CE | D209: =SUMIF(CAL!B:E,B209,CAL!E:E)+SUMIF(CAL!J:M,B209,CAL!M:M) -> 8 | E209: =COUNTIF(CAL!B:J,B209) -> 4 | F209: =SUMIF(CAL!B:F,B209,CAL!F:F)+SUMIF(CAL!J:N,B209,CAL!N:N) -> 2 | G209: =SUMIF(CAL!B:F,B209,CAL!G:G)+SUMIF(CAL!J:N,B209,CAL!O:O) -> 2 | H209: =SUMIF(CAL!B:F,B209,CAL!H:H)+SUMIF(CAL!J:N,B209,CAL!P:P) -> 0 | I209: =IF(E209=0,0,(D209/(E209*3))) -> 0.66666667 | J209: =SUMIF(CAL!B:C,B209,CAL!C:C)+SUMIF(CAL!J:J,B209,CAL!D:D) -> 4 | K209: =SUMIF(CAL!B:D,B209,CAL!D:D)+SUMIF(CAL!J:L,B209,CAL!K:K) -> 1 | L209: =J209-K209 -> 3 | M209: =IF(E209=0,0,(J209/E209)) -> 1 | N209: =IF(E209=0,0,(K209/E209)) -> 0.25 | O209: =SUMIF(CAL!B:I,B209,CAL!I:I)+SUMIF(CAL!J:Q,B209,CAL!Q:Q) -> 3 | T209: Crato | U209: CE
...

Sheet EST
A1: PAIS | B1: GOLS
A2: Argentina | B2: =SUMIF(ART!G:H,A2,ART!H:H) -> 63
A3: Colombia | B3: =SUMIF(ART!G:H,A3,ART!H:H) -> 63
A4: Uruguai | B4: =SUMIF(ART!G:H,A4,ART!H:H) -> 36
